Workbook
Name SegmentaciónDeDatos_CATEGORIA: #N/A
Name SegmentaciónDeDatos_STATUS: #N/A

Sheet Hoja1
A2: ELECTRONICA | B2: =A2&"-"&COUNTIF($A$2:A2,A2) -> ELECTRONICA-1 | D2: =E2&"-"&COUNTIF($E$2:E2,E2) -> EL-1 | E2: EL
A3: ROPA | B3: =A3&"-"&COUNTIF($A$2:A3,A3) -> ROPA-1 | D3: =E3&"-"&COUNTIF($E$2:E3,E3) -> RO-1 | E3: RO
A4: ELECTRONICA | B4: =A4&"-"&COUNTIF($A$2:A4,A4) -> ELECTRONICA-2 | D4: =E4&"-"&COUNTIF($E$2:E4,E4) -> EL-2 | E4: EL
D5: =E5&"-"&COUNTIF($E$2:E5,E5) -> -0
A6: =B6&"-"&COUNTIF($B$6:B6,B6) -> EL-1 | B6: EL | D6: =E6&"-"&COUNTIF($E$2:E6,E6) -> -0
A7: =B7&"-"&COUNTIF($B$6:B7,B7) -> RO-1 | B7: RO | D7: =E7&"-"&COUNTIF($E$2:E7,E7) -> -0
A8: =B8&"-"&COUNTIF($B$6:B8,B8) -> EL-2 | B8: EL | D8: =E8&"-"&COUNTIF($E$2:E8,E8) -> -0
D9: =E9&"-"&COUNTIF($E$2:E9,E9) -> -0
D10: =E10&"-"&COUNTIF($E$2:E10,E10) -> -0
D11: =E11&"-"&COUNTIF($E$2:E11,E11) -> -0
D12: =E12&"-"&COUNTIF($E$2:E12,E12) -> -0
D13: =E13&"-"&COUNTIF($E$2:E13,E13) -> -0
D14: =E14&"-"&COUNTIF($E$2:E14,E14) -> -0

Sheet DATOS
A1: N° | B1: NOMBRES | C1: DNI | D1: CLASE | E1: CARGO
A2: 1 | B2: NAVARRO LOZANO, ANGEL JAROL | C2: 75396402 | D2: OBRERO | E2: PEON | J2: ERNESTO ACUACHI LANCHIPA
A3: 2 | B3: JEREMIAS PALOMINO, NORBERTO LEONCIO | C3: 44184914 | D3: OBRERO | E3: PEON | J3: NAVARRO LOZANO, ANGEL JAROL
A4: 3 | B4: LOZANO MALDONADO, HERNAN | C4: 40839932 | D4: OBRERO | E4: PEON
A5: 4 | B5: PIÑA CHUJANDAMA, KEVIN | C5: 70833343 | D5: OBRERO | E5: PEON
A6: 5 | B6: MAYTAHUARI ACOSTA, SAMMER AXEL | C6: 48492558 | D6: OBRERO | E6: OPERARIO
A7: 6 | B7: CORDOVA ANGULO, JUAN | C7: 40889884 | D7: OBRERO | E7: PEON
A8: 7 | B8: ROJAS SANDOVAL, JAVIER ELOY | C8: 40861767 | D8: OBRERO | E8: OPERARIO/VOLQUETERO
A9: 8 | B9: CHINO PILCO SIMON | C9: 00487377 | D9: OBRERO | E9: PEON/CHOFER
A10: 9 | B10: ACUACHI LANCHIPA ERNESTO ALONSO | C10: 41056694 | D10: PERSONAL NO CLAVE | E10: LOGISTICO
A11: 10 | B11: ALEJO CHARCA, DENNYS MIRIAM | D11: PERSONAL CLAVE | E11: ING. CALIDAD
A12: 11 | B12: SILVA BORDA, ARLETTE NINOSKA | D12: PERSONAL NO CLAVE | E12: ASIS. ING.
A13: 12 | B13: ADUVIRE ARGUATA, MARIO ARTURO | D13: OBRERO | E13: MAESTRO OBRA
A14: 13 | B14: SALAZAR BAZAN, ROCÍO DALILA | D14: PERSONAL CLAVE | E14: RESIDENTE
A15: 14 | B15: CHACON ORTIZ, JOSE ANTONIO | C15: 00515241 | D15: OBRERO | E15: CARPINTERO
A16: 15 | B16: ORDOÑEZ CONDORI, GILBERTO | C16: 44723682 | D16: OBRERO
A17: 16 | B17: VILLEGAS ROGER
A18: 17 | B18: GUTARATE SABINO, ADRIEL ANTONY | C18: 78202475 | D18: OBRERO | E18: OPERARIO
A19: 18 | B19: QUISPE LIMACHE, ROGELIO | C19: 44758063 | D19: OBRERO | E19: OPERARIO
A20: 19 | B20: APASTEGUI GRANDEZ, LUIS ALFREDO | C20: 46906026 | D20: OBRERO | E20: PEON
A21: 20 | B21: LOZA, GUILLERMO | D21: PERSONAL CLAVE | E21: TOPOGRAFO
A22: 21 | B22: CACERES CALACHUA, YEYSON JORGE | D22: OBRERO | E22: OPERARIO
A23: 22 | B23: ACOSTA ROJAS, JOSEPH ALFONSO | C23: 70522697 | D23: PERSONAL CLAVE | E23: REPRESENTANTE
A24: 23 | B24: TUANAMA PILCO, CRHIS | C24: 74367601 | D24: OBRERO | E24: PEON
A25: 24 | B25: YEANCARLO
A26: 25 | B26: MAQUERA QUISPE, LEONIDAS EDWIN | C26: 41058582 | D26: OBRERO | E26: OPERARIO
A27: 26 | B27: MOGROVEJO FALCON, OSMAR ADOLFO | C27: 61415253 | D27: PERSONAL CLAVE | E27: ING. SEGURIDAD
A28: 27 | B28: GUTARATE SABINO, RONEL | D28: OBRERO | E28: PEON
A29: 28 | B29: TACANAHUI CALISAYA, NESTOR | D29: OBRERO | E29: PEON
A30: 29 | B30: ROSAS CHACHAQUE, WILSON JHONY | C30: 44365799 | D30: OBRERO | E30: OPERARIO
A31: 30 | B31: OTROS
A32: 31 | B32: ACOSTA ROJAS, ERICK
A33: 32 | B33: GAMARRA CONDORI, ANGEL | C33: 47099079 | D33: OBRERO | E33: OPERARIO
A34: 33 | B34: QUISPE MAQUERA, MARCO ANTONIO | C34: 74808890 | D34: OBRERO | E34: PEON
A35: 34 | B35: PUMAYALLI LICONA, ENOCH | C35: 45366294 | D35: OBRERO | E35: PEON
A36: 35 | B36: CURMAYARI MANUYAMA, VICTOR RAUL | C36: 00082335 | D36: OBRERO | E36: OPERARIO
A37: 36 | B37: OLIVA TARAPA, TOMAS
A38: 37 | B38: MACHUCA NAVARRO, OMAR
A39: 38 | B39: CURMAYARI GUZMAN, JOFFRE
A40: 39 | B40: ESCOBAR ARBILDO, GOLBER
...

Sheet PRODUCTOS
B1: GESTION DE INVENTARIO
B3: CONSORCIO FORTALEZA - FSA CONSTRUCTORA E.I.R.L
B5: LISTADO DE PRODUCTO
B6: 1 | C6: 2 | D6: 3 | E6: 4 | F6: 5 | G6: 6 | H6: 7 | I6: 8 | J6: 9 | K6: 10 | L6: 11 | M6: 12 | N6: 13 | O6: 14
B7: CODIGO | C7: PRODUCTO | D7: CATEGORIA | E7: CONCATENAR | F7: ALMACEN | G7: UNIDAD | H7: STATUS | I7: . | J7: STOCK MINIMO | K7: EXISTENCIA ACTUAL | L7: PROVIENE | M7: CONDICIÓN | N7: NRO REQUERIMIENTO | O7: AREA REQUERIMIENTO
B8: =E8&"-"&COUNTIF($E$8:E8,E8) -> IS-1 | C8: Pantalon jeans varon M/Jusbrend T/34 | D8: IMPLEMENTOS DE SEGURIDAD | E8: =IFERROR(VLOOKUP(D8,Hoja3!$A$2:$B$50,2,0),"") -> IS | F8: ALMACEN TICAPAMPA | G8: UNI | H8: =IF(Tabla1[[#This Row],[EXISTENCIA ACTUAL]]=0,"AGOTADO", IF(Tabla1[[#This Row],[EXISTENCIA ACTUAL]]<Tabla1[[#This Row],[STOCK MINIMO]],"MENOR AL MINIMO", "OK")) -> OK | I8: =IF(Tabla1[[#This Row],[EXISTENCIA ACTUAL]]=0,0, IF(Tabla1[[#This Row],[EXISTENCIA ACTUAL]]<Tabla1[[#This Row],[STOCK MINIMO]],1, 2)) -> 2 | J8: 2 | K8: =SUMIFS(Tabla2[CANTIDAD],Tabla2[PRODUCTO],Tabla1[[#This Row],[PRODUCTO]]) -> 4 | L8: COMPRA | M8: NUEVO | S8: 0 = Existencia actual AGOTADA
B9: =E9&"-"&COUNTIF($E$8:E9,E9) -> IS-2 | C9: Pantalon jeans varon M/Jusbrend T/32 | D9: IMPLEMENTOS DE SEGURIDAD | E9: =IFERROR(VLOOKUP(D9,Hoja3!$A$2:$B$50,2,0),"") -> IS | F9: ALMACEN TICAPAMPA | G9: UNI | H9: =IF(Tabla1[[#This Row],[EXISTENCIA ACTUAL]]=0,"AGOTADO", IF(Tabla1[[#This Row],[EXISTENCIA ACTUAL]]<Tabla1[[#This Row],[STOCK MINIMO]],"MENOR AL MINIMO", "OK")) -> OK | I9: =IF(Tabla1[[#This Row],[EXISTENCIA ACTUAL]]=0,0, IF(Tabla1[[#This Row],[EXISTENCIA ACTUAL]]<Tabla1[[#This Row],[STOCK MINIMO]],1, 2)) -> 2 | J9: 2 | K9: =SUMIFS(Tabla2[CANTIDAD],Tabla2[PRODUCTO],Tabla1[[#This Row],[PRODUCTO]]) -> 5 | L9: COMPRA | M9: NUEVO | S9: 1= Existencia actual < minima
B10: =E10&"-"&COUNTIF($E$8:E10,E10) -> IS-3 | C10: Pantalon jeans dama s/marca T/30 | D10: IMPLEMENTOS DE SEGURIDAD | E10: =IFERROR(VLOOKUP(D10,Hoja3!$A$2:$B$50,2,0),"") -> IS | F10: ALMACEN TICAPAMPA | G10: UNI | H10: =IF(Tabla1[[#This Row],[EXISTENCIA ACTUAL]]=0,"AGOTADO", IF(Tabla1[[#This Row],[EXISTENCIA ACTUAL]]<Tabla1[[#This Row],[STOCK MINIMO]],"MENOR AL MINIMO", "OK")) -> AGOTADO | I10: =IF(Tabla1[[#This Row],[EXISTENCIA ACTUAL]]=0,0, IF(Tabla1[[#This Row],[EXISTENCIA ACTUAL]]<Tabla1[[#This Row],[STOCK MINIMO]],1, 2)) -> 0 | J10: 2 | K10: =SUMIFS(Tabla2[CANTIDAD],Tabla2[PRODUCTO],Tabla1[[#This Row],[PRODUCTO]]) -> 0 | L10: COMPRA | M10: NUEVO | S10: 2= ninguna de las anteriores
B11: =E11&"-"&COUNTIF($E$8:E11,E11) -> IS-4 | C11: Pantalon jeans dama s/marca T/32 | D11: IMPLEMENTOS DE SEGURIDAD | E11: =IFERROR(VLOOKUP(D11,Hoja3!$A$2:$B$50,2,0),"") -> IS | F11: ALMACEN TICAPAMPA | G11: UNI | H11: =IF(Tabla1[[#This Row],[EXISTENCIA ACTUAL]]=0,"AGOTADO", IF(Tabla1[[#This Row],[EXISTENCIA ACTUAL]]<Tabla1[[#This Row],[STOCK MINIMO]],"MENOR AL MINIMO", "OK")) -> AGOTADO | I11: =IF(Tabla1[[#This Row],[EXISTENCIA ACTUAL]]=0,0, IF(Tabla1[[#This Row],[EXISTENCIA ACTUAL]]<Tabla1[[#This Row],[STOCK MINIMO]],1, 2)) -> 0 | J11: 2 | K11: =SUMIFS(Tabla2[CANTIDAD],Tabla2[PRODUCTO],Tabla1[[#This Row],[PRODUCTO]]) -> 0 | L11: COMPRA | M11: NUEVO
B12: =E12&"-"&COUNTIF($E$8:E12,E12) -> IS-5 | C12: Pantalon jeans dama s/maca T/34 | D12: IMPLEMENTOS DE SEGURIDAD | E12: =IFERROR(VLOOKUP(D12,Hoja3!$A$2:$B$50,2,0),"") -> IS | F12: ALMACEN TICAPAMPA | G12: UNI | H12: =IF(Tabla1[[#This Row],[EXISTENCIA ACTUAL]]=0,"AGOTADO", IF(Tabla1[[#This Row],[EXISTENCIA ACTUAL]]<Tabla1[[#This Row],[STOCK MINIMO]],"MENOR AL MINIMO", "OK")) -> AGOTADO | I12: =IF(Tabla1[[#This Row],[EXISTENCIA ACTUAL]]=0,0, IF(Tabla1[[#This Row],[EXISTENCIA ACTUAL]]<Tabla1[[#This Row],[STOCK MINIMO]],1, 2)) -> 0 | J12: 2 | K12: =SUMIFS(Tabla2[CANTIDAD],Tabla2[PRODUCTO],Tabla1[[#This Row],[PRODUCTO]]) -> 0 | L12: COMPRA | M12: NUEVO
B13: =E13&"-"&COUNTIF($E$8:E13,E13) -> IS-6 | C13: Chaleco Steel Power T/2XL | D13: IMPLEMENTOS DE SEGURIDAD | E13: =IFERROR(VLOOKUP(D13,Hoja3!$A$2:$B$50,2,0),"") -> IS | F13: ALMACEN TICAPAMPA | G13: UNI | H13: =IF(Tabla1[[#This Row],[EXISTENCIA ACTUAL]]=0,"AGOTADO", IF(Tabla1[[#This Row],[EXISTENCIA ACTUAL]]<Tabla1[[#This Row],[STOCK MINIMO]],"MENOR AL MINIMO", "OK")) -> AGOTADO | I13: =IF(Tabla1[[#This Row],[EXISTENCIA ACTUAL]]=0,0, IF(Tabla1[[#This Row],[EXISTENCIA ACTUAL]]<Tabla1[[#This Row],[STOCK MINIMO]],1, 2)) -> 0 | J13: 2 | K13: =SUMIFS(Tabla2[CANTIDAD],Tabla2[PRODUCTO],Tabla1[[#This Row],[PRODUCTO]]) -> 0 | L13: COMPRA | M13: NUEVO
B14: =E14&"-"&COUNTIF($E$8:E14,E14) -> IS-7 | C14: Chaleco Steel Power T/L | D14: IMPLEMENTOS DE SEGURIDAD | E14: =IFERROR(VLOOKUP(D14,Hoja3!$A$2:$B$50,2,0),"") -> IS | F14: ALMACEN TICAPAMPA | G14: UNI | H14: =IF(Tabla1[[#This Row],[EXISTENCIA ACTUAL]]=0,"AGOTADO", IF(Tabla1[[#This Row],[EXISTENCIA ACTUAL]]<Tabla1[[#This Row],[STOCK MINIMO]],"MENOR AL MINIMO", "OK")) -> AGOTADO | I14: =IF(Tabla1[[#This Row],[EXISTENCIA ACTUAL]]=0,0, IF(Tabla1[[#This Row],[EXISTENCIA ACTUAL]]<Tabla1[[#This Row],[STOCK MINIMO]],1, 2)) -> 0 | J14: 2 | K14: =SUMIFS(Tabla2[CANTIDAD],Tabla2[PRODUCTO],Tabla1[[#This Row],[PRODUCTO]]) -> 0 | L14: COMPRA | M14: NUEVO
B15: =E15&"-"&COUNTIF($E$8:E15,E15) -> IS-8 | C15: Chaleco Steel Power T/M | D15: IMPLEMENTOS DE SEGURIDAD | E15: =IFERROR(VLOOKUP(D15,Hoja3!$A$2:$B$50,2,0),"") -> IS | F15: ALMACEN TICAPAMPA | G15: UNI | H15: =IF(Tabla1[[#This Row],[EXISTENCIA ACTUAL]]=0,"AGOTADO", IF(Tabla1[[#This Row],[EXISTENCIA ACTUAL]]<Tabla1[[#This Row],[STOCK MINIMO]],"MENOR AL MINIMO", "OK")) -> AGOTADO | I15: =IF(Tabla1[[#This Row],[EXISTENCIA ACTUAL]]=0,0, IF(Tabla1[[#This Row],[EXISTENCIA ACTUAL]]<Tabla1[[#This Row],[STOCK MINIMO]],1, 2)) -> 0 | J15: 2 | K15: =SUMIFS(Tabla2[CANTIDAD],Tabla2[PRODUCTO],Tabla1[[#This Row],[PRODUCTO]]) -> 0 | L15: COMPRA | M15: NUEVO
B16: =E16&"-"&COUNTIF($E$8:E16,E16) -> IS-9 | C16: Camisa varon Fort Sport T/L | D16: IMPLEMENTOS DE SEGURIDAD | E16: =IFERROR(VLOOKUP(D16,Hoja3!$A$2:$B$50,2,0),"") -> IS | F16: ALMACEN TICAPAMPA | G16: UNI | H16: =IF(Tabla1[[#This Row],[EXISTENCIA ACTUAL]]=0,"AGOTADO", IF(Tabla1[[#This Row],[EXISTENCIA ACTUAL]]<Tabla1[[#This Row],[STOCK MINIMO]],"MENOR AL MINIMO", "OK")) -> AGOTADO | I16: =IF(Tabla1[[#This Row],[EXISTENCIA ACTUAL]]=0,0, IF(Tabla1[[#This Row],[EXISTENCIA ACTUAL]]<Tabla1[[#This Row],[STOCK MINIMO]],1, 2)) -> 0 | J16: 1 | K16: =SUMIFS(Tabla2[CANTIDAD],Tabla2[PRODUCTO],Tabla1[[#This Row],[PRODUCTO]]) -> 0 | L16: COMPRA | M16: NUEVO
B17: =E17&"-"&COUNTIF($E$8:E17,E17) -> IS-10 | C17: Camisa varon Fort Sport T/XL | D17: IMPLEMENTOS DE SEGURIDAD | E17: =IFERROR(VLOOKUP(D17,Hoja3!$A$2:$B$50,2,0),"") -> IS | F17: ALMACEN TICAPAMPA | G17: UNI | H17: =IF(Tabla1[[#This Row],[EXISTENCIA ACTUAL]]=0,"AGOTADO", IF(Tabla1[[#This Row],[EXISTENCIA ACTUAL]]<Tabla1[[#This Row],[STOCK MINIMO]],"MENOR AL MINIMO", "OK")) -> AGOTADO | I17: =IF(Tabla1[[#This Row],[EXISTENCIA ACTUAL]]=0,0, IF(Tabla1[[#This Row],[EXISTENCIA ACTUAL]]<Tabla1[[#This Row],[STOCK MINIMO]],1, 2)) -> 0 | J17: 1 | K17: =SUMIFS(Tabla2[CANTIDAD],Tabla2[PRODUCTO],Tabla1[[#This Row],[PRODUCTO]]) -> 0 | L17: COMPRA | M17: NUEVO
B18: =E18&"-"&COUNTIF($E$8:E18,E18) -> IS-11 | C18: Camisa dama Fort Sport T/M | D18: IMPLEMENTOS DE SEGURIDAD | E18: =IFERROR(VLOOKUP(D18,Hoja3!$A$2:$B$50,2,0),"") -> IS | F18: ALMACEN TICAPAMPA | G18: UNI | H18: =IF(Tabla1[[#This Row],[EXISTENCIA ACTUAL]]=0,"AGOTADO", IF(Tabla1[[#This Row],[EXISTENCIA ACTUAL]]<Tabla1[[#This Row],[STOCK MINIMO]],"MENOR AL MINIMO", "OK")) -> AGOTADO | I18: =IF(Tabla1[[#This Row],[EXISTENCIA ACTUAL]]=0,0, IF(Tabla1[[#This Row],[EXISTENCIA ACTUAL]]<Tabla1[[#This Row],[STOCK MINIMO]],1, 2)) -> 0 | J18: 1 | K18: =SUMIFS(Tabla2[CANTIDAD],Tabla2[PRODUCTO],Tabla1[[#This Row],[PRODUCTO]]) -> 0 | L18: COMPRA | M18: NUEVO
B19: =E19&"-"&COUNTIF($E$8:E19,E19) -> IS-12 | C19: Camisa dama Fort Sport T/L | D19: IMPLEMENTOS DE SEGURIDAD | E19: =IFERROR(VLOOKUP(D19,Hoja3!$A$2:$B$50,2,0),"") -> IS | F19: ALMACEN TICAPAMPA | G19: UNI | H19: =IF(Tabla1[[#This Row],[EXISTENCIA ACTUAL]]=0,"AGOTADO", IF(Tabla1[[#This Row],[EXISTENCIA ACTUAL]]<Tabla1[[#This Row],[STOCK MINIMO]],"MENOR AL MINIMO", "OK")) -> AGOTADO | I19: =IF(Tabla1[[#This Row],[EXISTENCIA ACTUAL]]=0,0, IF(Tabla1[[#This Row],[EXISTENCIA ACTUAL]]<Tabla1[[#This Row],[STOCK MINIMO]],1, 2)) -> 0 | J19: 1 | K19: =SUMIFS(Tabla2[CANTIDAD],Tabla2[PRODUCTO],Tabla1[[#This Row],[PRODUCTO]]) -> 0 | L19: COMPRA | M19: NUEVO
B20: =E20&"-"&COUNTIF($E$8:E20,E20) -> IS-13 | C20: Pantalon jeans varon m/Jusbrend T/36 | D20: IMPLEMENTOS DE SEGURIDAD | E20: =IFERROR(VLOOKUP(D20,Hoja3!$A$2:$B$50,2,0),"") -> IS | F20: ALMACEN TICAPAMPA | G20: UNI | H20: =IF(Tabla1[[#This Row],[EXISTENCIA ACTUAL]]=0,"AGOTADO", IF(Tabla1[[#This Row],[EXISTENCIA ACTUAL]]<Tabla1[[#This Row],[STOCK MINIMO]],"MENOR AL MINIMO", "OK")) -> OK | I20: =IF(Tabla1[[#This Row],[EXISTENCIA ACTUAL]]=0,0, IF(Tabla1[[#This Row],[EXISTENCIA ACTUAL]]<Tabla1[[#This Row],[STOCK MINIMO]],1, 2)) -> 2 | J20: 1 | K20: =SUMIFS(Tabla2[CANTIDAD],Tabla2[PRODUCTO],Tabla1[[#This Row],[PRODUCTO]]) -> 2 | L20: COMPRA | M20: NUEVO
B21: =E21&"-"&COUNTIF($E$8:E21,E21) -> IS-14 | C21: Cortaviento diferentes colores | D21: IMPLEMENTOS DE SEGURIDAD | E21: =IFERROR(VLOOKUP(D21,Hoja3!$A$2:$B$50,2,0),"") -> IS | F21: ALMACEN TICAPAMPA | G21: UNI | H21: =IF(Tabla1[[#This Row],[EXISTENCIA ACTUAL]]=0,"AGOTADO", IF(Tabla1[[#This Row],[EXISTENCIA ACTUAL]]<Tabla1[[#This Row],[STOCK MINIMO]],"MENOR AL MINIMO", "OK")) -> MENOR AL MINIMO | I21: =IF(Tabla1[[#This Row],[EXISTENCIA ACTUAL]]=0,0, IF(Tabla1[[#This Row],[EXISTENCIA ACTUAL]]<Tabla1[[#This Row],[STOCK MINIMO]],1, 2)) -> 1 | J21: 2 | K21: =SUMIFS(Tabla2[CANTIDAD],Tabla2[PRODUCTO],Tabla1[[#This Row],[PRODUCTO]]) -> 1 | L21: COMPRA | M21: NUEVO
B22: =E22&"-"&COUNTIF($E$8:E22,E22) -> IS-15 | C22: Zapato de seguridad Hunter T/40 | D22: IMPLEMENTOS DE SEGURIDAD | E22: =IFERROR(VLOOKUP(D22,Hoja3!$A$2:$B$50,2,0),"") -> IS | F22: ALMACEN TICAPAMPA | G22: PAR | H22: =IF(Tabla1[[#This Row],[EXISTENCIA ACTUAL]]=0,"AGOTADO", IF(Tabla1[[#This Row],[EXISTENCIA ACTUAL]]<Tabla1[[#This Row],[STOCK MINIMO]],"MENOR AL MINIMO", "OK")) -> AGOTADO | I22: =IF(Tabla1[[#This Row],[EXISTENCIA ACTUAL]]=0,0, IF(Tabla1[[#This Row],[EXISTENCIA ACTUAL]]<Tabla1[[#This Row],[STOCK MINIMO]],1, 2)) -> 0 | J22: 2 | K22: =SUMIFS(Tabla2[CANTIDAD],Tabla2[PRODUCTO],Tabla1[[#This Row],[PRODUCTO]]) -> 0 | L22: COMPRA | M22: NUEVO
... B128: =E128&"-"&COUNTIF($E$8:E128,E128) -> UE-55 | C128: Pizarra acrilica | D128: UTILES DE ESCRITORIO | E128: =IFERROR(VLOOKUP(D128,Hoja3!$A$2:$B$50,2,0),"") -> UE | F128: ALMACEN TICAPAMPA | G128: UNI | H128: =IF(Tabla1[[#This Row],[EXISTENCIA ACTUAL]]=0,"AGOTADO", IF(Tabla1[[#This Row],[EXISTENCIA ACTUAL]]<Tabla1[[#This Row],[STOCK MINIMO]],"MENOR AL MINIMO", "OK")) -> OK | I128: =IF(Tabla1[[#This Row],[EXISTENCIA ACTUAL]]=0,0, IF(Tabla1[[#This Row],[EXISTENCIA ACTUAL]]<Tabla1[[#This Row],[STOCK MINIMO]],1, 2)) -> 2 | J128: 1 | K128: =SUMIFS(Tabla2[CANTIDAD],Tabla2[PRODUCTO],Tabla1[[#This Row],[PRODUCTO]]) -> 1 | L128: COMPRA | M128: NUEVO
B129: =E129&"-"&COUNTIF($E$8:E129,E129) -> COM-1 | C129: Gasolina regular | D129: COMBUSTIBLE | E129: =IFERROR(VLOOKUP(D129,Hoja3!$A$2:$B$50,2,0),"") -> COM | F129: ALMACEN TICAPAMPA | G129: GLN | H129: =IF(Tabla1[[#This Row],[EXISTENCIA ACTUAL]]=0,"AGOTADO", IF(Tabla1[[#This Row],[EXISTENCIA ACTUAL]]<Tabla1[[#This Row],[STOCK MINIMO]],"MENOR AL MINIMO", "OK")) -> OK | I129: =IF(Tabla1[[#This Row],[EXISTENCIA ACTUAL]]=0,0, IF(Tabla1[[#This Row],[EXISTENCIA ACTUAL]]<Tabla1[[#This Row],[STOCK MINIMO]],1, 2)) -> 2 | J129: 1 | K129: =SUMIFS(Tabla2[CANTIDAD],Tabla2[PRODUCTO],Tabla1[[#This Row],[PRODUCTO]]) -> 5.623 | L129: COMPRA | M129: NUEVO | O129: CONSTRUCCION
B130: =E130&"-"&COUNTIF($E$8:E130,E130) -> IE-9 | C130: Grapas para pared | D130: INSTALACIONES ELECTRICAS | E130: =IFERROR(VLOOKUP(D130,Hoja3!$A$2:$B$50,2,0),"") -> IE | F130: ALMACEN TICAPAMPA | G130: BLS | H130: =IF(Tabla1[[#This Row],[EXISTENCIA ACTUAL]]=0,"AGOTADO", IF(Tabla1[[#This Row],[EXISTENCIA ACTUAL]]<Tabla1[[#This Row],[STOCK MINIMO]],"MENOR AL MINIMO", "OK")) -> AGOTADO | I130: =IF(Tabla1[[#This Row],[EXISTENCIA ACTUAL]]=0,0, IF(Tabla1[[#This Row],[EXISTENCIA ACTUAL]]<Tabla1[[#This Row],[STOCK MINIMO]],1, 2)) -> 0 | J130: 1 | K130: =SUMIFS(Tabla2[CANTIDAD],Tabla2[PRODUCTO],Tabla1[[#This Row],[PRODUCTO]]) -> 0 | L130: COMPRA | M130: NUEVO | O130: ELECTRICIDAD
B131: =E131&"-"&COUNTIF($E$8:E131,E131) -> HM-3 | C131: Disco de corte amoladora 71/16" kulkoni metal | D131: HERRAMIENTAS | E131: =IFERROR(VLOOKUP(D131,Hoja3!$A$2:$B$50,2,0),"") -> HM | F131: ALMACEN TICAPAMPA | G131: UNI | H131: =IF(Tabla1[[#This Row],[EXISTENCIA ACTUAL]]=0,"AGOTADO", IF(Tabla1[[#This Row],[EXISTENCIA ACTUAL]]<Tabla1[[#This Row],[STOCK MINIMO]],"MENOR AL MINIMO", "OK")) -> AGOTADO | I131: =IF(Tabla1[[#This Row],[EXISTENCIA ACTUAL]]=0,0, IF(Tabla1[[#This Row],[EXISTENCIA ACTUAL]]<Tabla1[[#This Row],[STOCK MINIMO]],1, 2)) -> 0 | J131: 5 | K131: =SUMIFS(Tabla2[CANTIDAD],Tabla2[PRODUCTO],Tabla1[[#This Row],[PRODUCTO]]) -> 0 | L131: COMPRA | M131: NUEVO
B132: =E132&"-"&COUNTIF($E$8:E132,E132) -> ISA-8 | C132: Llave de paso 1" | D132: INSTALACIONES SANITARIAS | E132: =IFERROR(VLOOKUP(D132,Hoja3!$A$2:$B$50,2,0),"") -> ISA | F132: ALMACEN TICAPAMPA | G132: UNI | H132: =IF(Tabla1[[#This Row],[EXISTENCIA ACTUAL]]=0,"AGOTADO", IF(Tabla1[[#This Row],[EXISTENCIA ACTUAL]]<Tabla1[[#This Row],[STOCK MINIMO]],"MENOR AL MINIMO", "OK")) -> OK | I132: =IF(Tabla1[[#This Row],[EXISTENCIA ACTUAL]]=0,0, IF(Tabla1[[#This Row],[EXISTENCIA ACTUAL]]<Tabla1[[#This Row],[STOCK MINIMO]],1, 2)) -> 2 | J132: 1 | K132: =SUMIFS(Tabla2[CANTIDAD],Tabla2[PRODUCTO],Tabla1[[#This Row],[PRODUCTO]]) -> 1 | L132: COMPRA | M132: NUEVO | O132: GASFITERIA
B133: =E133&"-"&COUNTIF($E$8:E133,E133) -> ISA-9 | C133: Pegamento Nicoll 1/16 | D133: INSTALACIONES SANITARIAS | E133: =IFERROR(VLOOKUP(D133,Hoja3!$A$2:$B$50,2,0),"") -> ISA | F133: ALMACEN TICAPAMPA | G133: UNI | H133: =IF(Tabla1[[#This Row],[EXISTENCIA ACTUAL]]=0,"AGOTADO", IF(Tabla1[[#This Row],[EXISTENCIA ACTUAL]]<Tabla1[[#This Row],[STOCK MINIMO]],"MENOR AL MINIMO", "OK")) -> AGOTADO | I133: =IF(Tabla1[[#This Row],[EXISTENCIA ACTUAL]]=0,0, IF(Tabla1[[#This Row],[EXISTENCIA ACTUAL]]<Tabla1[[#This Row],[STOCK MINIMO]],1, 2)) -> 0 | J133: 1 | K133: =SUMIFS(Tabla2[CANTIDAD],Tabla2[PRODUCTO],Tabla1[[#This Row],[PRODUCTO]]) -> 0 | L133: COMPRA | M133: NUEVO | O133: GASFITERIA
B134: =E134&"-"&COUNTIF($E$8:E291,E134) -> OTR-19 | C134: Bidones de agua 20 lt | D134: OTROS | E134: =IFERROR(VLOOKUP(D134,Hoja3!$A$2:$B$50,2,0),"") -> OTR | F134: ALMACEN TICAPAMPA | G134: UNI | H134: =IF(Tabla1[[#This Row],[EXISTENCIA ACTUAL]]=0,"AGOTADO", IF(Tabla1[[#This Row],[EXISTENCIA ACTUAL]]<Tabla1[[#This Row],[STOCK MINIMO]],"MENOR AL MINIMO", "OK")) -> MENOR AL MINIMO | I134: =IF(Tabla1[[#This Row],[EXISTENCIA ACTUAL]]=0,0, IF(Tabla1[[#This Row],[EXISTENCIA ACTUAL]]<Tabla1[[#This Row],[STOCK MINIMO]],1, 2)) -> 1 | J134: 3 | K134: =SUMIFS(Tabla2[CANTIDAD],Tabla2[PRODUCTO],Tabla1[[#This Row],[PRODUCTO]]) -> 1 | L134: ALMACEN CENTRAL
B135: =E135&"-"&COUNTIF($E$8:E135,E135) -> HM-4 | C135: Amoladora mano 9" Bosch, MD/3601HF40E0 2500W | D135: HERRAMIENTAS | E135: =IFERROR(VLOOKUP(D135,Hoja3!$A$2:$B$50,2,0),"") -> HM | F135: ALMACEN TICAPAMPA | G135: UNI | H135: =IF(Tabla1[[#This Row],[EXISTENCIA ACTUAL]]=0,"AGOTADO", IF(Tabla1[[#This Row],[EXISTENCIA ACTUAL]]<Tabla1[[#This Row],[STOCK MINIMO]],"MENOR AL MINIMO", "OK")) -> OK | I135: =IF(Tabla1[[#This Row],[EXISTENCIA ACTUAL]]=0,0, IF(Tabla1[[#This Row],[EXISTENCIA ACTUAL]]<Tabla1[[#This Row],[STOCK MINIMO]],1, 2)) -> 2 | J135: 1 | K135: =SUMIFS(Tabla2[CANTIDAD],Tabla2[PRODUCTO],Tabla1[[#This Row],[PRODUCTO]]) -> 1 | L135: COMPRA | M135: NUEVO
B136: =E136&"-"&COUNTIF($E$8:E136,E136) -> HM-5 | C136: Disco de corte amoladora 9" bosch | D136: HERRAMIENTAS | E136: =IFERROR(VLOOKUP(D136,Hoja3!$A$2:$B$50,2,0),"") -> HM | F136: ALMACEN TICAPAMPA | G136: UNI | H136: =IF(Tabla1[[#This Row],[EXISTENCIA ACTUAL]]=0,"AGOTADO", IF(Tabla1[[#This Row],[EXISTENCIA ACTUAL]]<Tabla1[[#This Row],[STOCK MINIMO]],"MENOR AL MINIMO", "OK")) -> MENOR AL MINIMO | I136: =IF(Tabla1[[#This Row],[EXISTENCIA ACTUAL]]=0,0, IF(Tabla1[[#This Row],[EXISTENCIA ACTUAL]]<Tabla1[[#This Row],[STOCK MINIMO]],1, 2)) -> 1 | J136: 5 | K136: =SUMIFS(Tabla2[CANTIDAD],Tabla2[PRODUCTO],Tabla1[[#This Row],[PRODUCTO]]) -> 1 | L136: COMPRA | M136: NUEVO
B137: =E137&"-"&COUNTIF($E$8:E137,E137) -> COM-2 | C137: Petroleo | D137: COMBUSTIBLE | E137: =IFERROR(VLOOKUP(D137,Hoja3!$A$2:$B$50,2,0),"") -> COM | F137: ALMACEN TICAPAMPA | G137: GLN | H137: =IF(Tabla1[[#This Row],[EXISTENCIA ACTUAL]]=0,"AGOTADO", IF(Tabla1[[#This Row],[EXISTENCIA ACTUAL]]<Tabla1[[#This Row],[STOCK MINIMO]],"MENOR AL MINIMO", "OK")) -> OK | I137: =IF(Tabla1[[#This Row],[EXISTENCIA ACTUAL]]=0,0, IF(Tabla1[[#This Row],[EXISTENCIA ACTUAL]]<Tabla1[[#This Row],[STOCK MINIMO]],1, 2)) -> 2 | J137: 450 | K137: =SUMIFS(Tabla2[CANTIDAD],Tabla2[PRODUCTO],Tabla1[[#This Row],[PRODUCTO]]) -> 1417 | L137: COMPRA | M137: NUEVO | O137: MAQUINARIA
B138: =E138&"-"&COUNTIF($E$8:E138,E138) -> IS-36 | C138: Poleras manga larga ploma | D138: IMPLEMENTOS DE SEGURIDAD | E138: =IFERROR(VLOOKUP(D138,Hoja3!$A$2:$B$50,2,0),"") -> IS | F138: ALMACEN TICAPAMPA | G138: UNI | H138: =IF(Tabla1[[#This Row],[EXISTENCIA ACTUAL]]=0,"AGOTADO", IF(Tabla1[[#This Row],[EXISTENCIA ACTUAL]]<Tabla1[[#This Row],[STOCK MINIMO]],"MENOR AL MINIMO", "OK")) -> MENOR AL MINIMO | I138: =IF(Tabla1[[#This Row],[EXISTENCIA ACTUAL]]=0,0, IF(Tabla1[[#This Row],[EXISTENCIA ACTUAL]]<Tabla1[[#This Row],[STOCK MINIMO]],1, 2)) -> 1 | J138: 5 | K138: =SUMIFS(Tabla2[CANTIDAD],Tabla2[PRODUCTO],Tabla1[[#This Row],[PRODUCTO]]) -> 4 | L138: COMPRA | M138: NUEVO
B139: =E139&"-"&COUNTIF($E$8:E139,E139) -> ISA-10 | C139: Reduccion tubo de 2 a 1" | D139: INSTALACIONES SANITARIAS | E139: =IFERROR(VLOOKUP(D139,Hoja3!$A$2:$B$50,2,0),"") -> ISA | F139: ALMACEN TICAPAMPA | G139: UNI | H139: =IF(Tabla1[[#This Row],[EXISTENCIA ACTUAL]]=0,"AGOTADO", IF(Tabla1[[#This Row],[EXISTENCIA ACTUAL]]<Tabla1[[#This Row],[STOCK MINIMO]],"MENOR AL MINIMO", "OK")) -> MENOR AL MINIMO | I139: =IF(Tabla1[[#This Row],[EXISTENCIA ACTUAL]]=0,0, IF(Tabla1[[#This Row],[EXISTENCIA ACTUAL]]<Tabla1[[#This Row],[STOCK MINIMO]],1, 2)) -> 1 | J139: 2 | K139: =SUMIFS(Tabla2[CANTIDAD],Tabla2[PRODUCTO],Tabla1[[#This Row],[PRODUCTO]]) -> 1 | L139: COMPRA | M139: NUEVO
B140: =E140&"-"&COUNTIF($E$8:E140,E140) -> HM-6 | C140: Tarraja de 1" | D140: HERRAMIENTAS | E140: =IFERROR(VLOOKUP(D140,Hoja3!$A$2:$B$50,2,0),"") -> HM | F140: ALMACEN TICAPAMPA | G140: UNI | H140: =IF(Tabla1[[#This Row],[EXISTENCIA ACTUAL]]=0,"AGOTADO", IF(Tabla1[[#This Row],[EXISTENCIA ACTUAL]]<Tabla1[[#This Row],[STOCK MINIMO]],"MENOR AL MINIMO", "OK")) -> OK | I140: =IF(Tabla1[[#This Row],[EXISTENCIA ACTUAL]]=0,0, IF(Tabla1[[#This Row],[EXISTENCIA ACTUAL]]<Tabla1[[#This Row],[STOCK MINIMO]],1, 2)) -> 2 | J140: 1 | K140: =SUMIFS(Tabla2[CANTIDAD],Tabla2[PRODUCTO],Tabla1[[#This Row],[PRODUCTO]]) -> 1 | L140: COMPRA | M140: NUEVO
B141: =E141&"-"&COUNTIF($E$8:E141,E141) -> OTR-5 | C141: Ocre | D141: OTROS | E141: =IFERROR(VLOOKUP(D141,Hoja3!$A$2:$B$50,2,0),"") -> OTR | F141: ALMACEN TICAPAMPA | G141: PQTE | H141: =IF(Tabla1[[#This Row],[EXISTENCIA ACTUAL]]=0,"AGOTADO", IF(Tabla1[[#This Row],[EXISTENCIA ACTUAL]]<Tabla1[[#This Row],[STOCK MINIMO]],"MENOR AL MINIMO", "OK")) -> OK | I141: =IF(Tabla1[[#This Row],[EXISTENCIA ACTUAL]]=0,0, IF(Tabla1[[#This Row],[EXISTENCIA ACTUAL]]<Tabla1[[#This Row],[STOCK MINIMO]],1, 2)) -> 2 | J141: 1 | K141: =SUMIFS(Tabla2[CANTIDAD],Tabla2[PRODUCTO],Tabla1[[#This Row],[PRODUCTO]]) -> 6 | L141: COMPRA
B142: =E142&"-"&COUNTIF($E$8:E142,E142) -> IE-10 | C142: Cable mellizo #12 por metros | D142: INSTALACIONES ELECTRICAS | E142: =IFERROR(VLOOKUP(D142,Hoja3!$A$2:$B$50,2,0),"") -> IE | F142: ALMACEN TICAPAMPA | G142: MT | H142: =IF(Tabla1[[#This Row],[EXISTENCIA ACTUAL]]=0,"AGOTADO", IF(Tabla1[[#This Row],[EXISTENCIA ACTUAL]]<Tabla1[[#This Row],[STOCK MINIMO]],"MENOR AL MINIMO", "OK")) -> OK | I142: =IF(Tabla1[[#This Row],[EXISTENCIA ACTUAL]]=0,0, IF(Tabla1[[#This Row],[EXISTENCIA ACTUAL]]<Tabla1[[#This Row],[STOCK MINIMO]],1, 2)) -> 2 | J142: 5 | K142: =SUMIFS(Tabla2[CANTIDAD],Tabla2[PRODUCTO],Tabla1[[#This Row],[PRODUCTO]]) -> 15 | L142: COMPRA
B143: =E143&"-"&COUNTIF($E$8:E143,E143) -> HM-7 | C143: Disco de corte madera para circular 6" | D143: HERRAMIENTAS | E143: =IFERROR(VLOOKUP(D143,Hoja3!$A$2:$B$50,2,0),"") -> HM | F143: ALMACEN TICAPAMPA | G143: UNI | H143: =IF(Tabla1[[#This Row],[EXISTENCIA ACTUAL]]=0,"AGOTADO", IF(Tabla1[[#This Row],[EXISTENCIA ACTUAL]]<Tabla1[[#This Row],[STOCK MINIMO]],"MENOR AL MINIMO", "OK")) -> OK | I143: =IF(Tabla1[[#This Row],[EXISTENCIA ACTUAL]]=0,0, IF(Tabla1[[#This Row],[EXISTENCIA ACTUAL]]<Tabla1[[#This Row],[STOCK MINIMO]],1, 2)) -> 2 | J143: 1 | K143: =SUMIFS(Tabla2[CANTIDAD],Tabla2[PRODUCTO],Tabla1[[#This Row],[PRODUCTO]]) -> 1 | L143: COMPRA
B144: =E144&"-"&COUNTIF($E$8:E144,E144) -> UE-56 | C144: hojas bond milleniun 75g | D144: UTILES DE ESCRITORIO | E144: =IFERROR(VLOOKUP(D144,Hoja3!$A$2:$B$50,2,0),"") -> UE | F144: ALMACEN TICAPAMPA | G144: PQTE | H144: =IF(Tabla1[[#This Row],[EXISTENCIA ACTUAL]]=0,"AGOTADO", IF(Tabla1[[#This Row],[EXISTENCIA ACTUAL]]<Tabla1[[#This Row],[STOCK MINIMO]],"MENOR AL MINIMO", "OK")) -> OK | I144: =IF(Tabla1[[#This Row],[EXISTENCIA ACTUAL]]=0,0, IF(Tabla1[[#This Row],[EXISTENCIA ACTUAL]]<Tabla1[[#This Row],[STOCK MINIMO]],1, 2)) -> 2 | J144: 2 | K144: =SUMIFS(Tabla2[CANTIDAD],Tabla2[PRODUCTO],Tabla1[[#This Row],[PRODUCTO]]) -> 22 | L144: COMPRA
B145: =E145&"-"&COUNTIF($E$8:E145,E145) -> HM-8 | C145: Manguera 1/2" | D145: HERRAMIENTAS | E145: =IFERROR(VLOOKUP(D145,Hoja3!$A$2:$B$50,2,0),"") -> HM | F145: ALMACEN TICAPAMPA | G145: MT | H145: =IF(Tabla1[[#This Row],[EXISTENCIA ACTUAL]]=0,"AGOTADO", IF(Tabla1[[#This Row],[EXISTENCIA ACTUAL]]<Tabla1[[#This Row],[STOCK MINIMO]],"MENOR AL MINIMO", "OK")) -> OK | I145: =IF(Tabla1[[#This Row],[EXISTENCIA ACTUAL]]=0,0, IF(Tabla1[[#This Row],[EXISTENCIA ACTUAL]]<Tabla1[[#This Row],[STOCK MINIMO]],1, 2)) -> 2 | J145: 10 | K145: =SUMIFS(Tabla2[CANTIDAD],Tabla2[PRODUCTO],Tabla1[[#This Row],[PRODUCTO]]) -> 100 | L145: COMPRA
B146: =E146&"-"&COUNTIF($E$8:E146,E146) -> HM-9 | C146: Manguera 1" | D146: HERRAMIENTAS | E146: =IFERROR(VLOOKUP(D146,Hoja3!$A$2:$B$50,2,0),"") -> HM | F146: ALMACEN TICAPAMPA | G146: MT | H146: =IF(Tabla1[[#This Row],[EXISTENCIA ACTUAL]]=0,"AGOTADO", IF(Tabla1[[#This Row],[EXISTENCIA ACTUAL]]<Tabla1[[#This Row],[STOCK MINIMO]],"MENOR AL MINIMO", "OK")) -> OK | I146: =IF(Tabla1[[#This Row],[EXISTENCIA ACTUAL]]=0,0, IF(Tabla1[[#This Row],[EXISTENCIA ACTUAL]]<Tabla1[[#This Row],[STOCK MINIMO]],1, 2)) -> 2 | J146: 5 | K146: =SUMIFS(Tabla2[CANTIDAD],Tabla2[PRODUCTO],Tabla1[[#This Row],[PRODUCTO]]) -> 50 | L146: COMPRA
B147: =E147&"-"&COUNTIF($E$8:E147,E147) -> HM-10 | C147: Manguera Nivel | D147: HERRAMIENTAS | E147: =IFERROR(VLOOKUP(D147,Hoja3!$A$2:$B$50,2,0),"") -> HM | F147: ALMACEN TICAPAMPA | G147: MT | H147: =IF(Tabla1[[#This Row],[EXISTENCIA ACTUAL]]=0,"AGOTADO", IF(Tabla1[[#This Row],[EXISTENCIA ACTUAL]]<Tabla1[[#This Row],[STOCK MINIMO]],"MENOR AL MINIMO", "OK")) -> OK | I147: =IF(Tabla1[[#This Row],[EXISTENCIA ACTUAL]]=0,0, IF(Tabla1[[#This Row],[EXISTENCIA ACTUAL]]<Tabla1[[#This Row],[STOCK MINIMO]],1, 2)) -> 2 | J147: 5 | K147: =SUMIFS(Tabla2[CANTIDAD],Tabla2[PRODUCTO],Tabla1[[#This Row],[PRODUCTO]]) -> 50 | L147: COMPRA
...

Sheet REGISTRO ENTRADAS Y SALIDAS
B1: GESTION DE INVENTARIO
B3: CONSORCIO FORTALEZA - FSA CONSTRUCTORA E.I.R.L
B5: LISTADO DE PRODUCTO
B6: 1 | C6: 2 | D6: 3 | E6: 4 | F6: 5 | G6: 6 | H6: 7 | I6: 8 | J6: 9 | K6: 10 | L6: 11 | M6: 12 | N6: 13 | O6: 14 | P6: 15 | Q6: 16 | R6: 17
B7: FECHA | C7: CODIGO | D7: PRODUCTO | E7: CATEGORIA | F7: ALMACEN | G7: UNIDAD | H7: EXISTENCIA ACTUAL | I7: CANTIDAD | J7: DESCRIPCION TRABAJO | K7: PROVIENE | L7: QUIEN ENTREGA | M7: QUIEN RECIBE | N7: PREC. UNITARIO | O7: PREC. VENTA | P7: DOCUMENTO INGRESO | Q7: DOCUMENTO SALIDA | R7: formula
B8: 45910 | C8: =IFERROR(_xlfn.XLOOKUP(Tabla2[[#This Row],[PRODUCTO]],Tabla1[PRODUCTO],Tabla1[CODIGO]),"") -> IS-1 | D8: Pantalon jeans varon M/Jusbrend T/34 | E8: =IFERROR(VLOOKUP(Tabla2[[#This Row],[CODIGO]],Tabla1[],3,0),"") -> IMPLEMENTOS DE SEGURIDAD | F8: =IFERROR(VLOOKUP(Tabla2[[#This Row],[CODIGO]],Tabla1[],5,0),"") -> ALMACEN TICAPAMPA | G8: =IFERROR(VLOOKUP(Tabla2[[#This Row],[CODIGO]],Tabla1[],6,0),"") -> UNI | H8: =IFERROR(VLOOKUP(Tabla2[[#This Row],[CODIGO]],Tabla1[],10,0),"") -> 4 | I8: 10 | J8: Ingreso a Inventario | K8: =IFERROR(VLOOKUP(Tabla2[[#This Row],[CODIGO]],Tabla1[],11,0),"") -> COMPRA | L8: ACOSTA ROJAS, JOSEPH ALFONSO | M8: ACUACHI LANCHIPA ERNESTO ALONSO | N8: 45 | O8: =Tabla2[[#This Row],[CANTIDAD]]*Tabla2[[#This Row],[PREC. UNITARIO]] -> 450 | P8: FAC F001-007926 | R8: =Tabla2[[#This Row],[QUIEN RECIBE]]&"-"&TEXT(Tabla2[[#This Row],[FECHA]],"dd/mm/yyyy") -> ACUACHI LANCHIPA ERNESTO ALONSO-10/09/2025
B9: 45910 | C9: =IFERROR(_xlfn.XLOOKUP(Tabla2[[#This Row],[PRODUCTO]],Tabla1[PRODUCTO],Tabla1[CODIGO]),"") -> IS-2 | D9: Pantalon jeans varon M/Jusbrend T/32 | E9: =IFERROR(VLOOKUP(Tabla2[[#This Row],[CODIGO]],Tabla1[],3,0),"") -> IMPLEMENTOS DE SEGURIDAD | F9: =IFERROR(VLOOKUP(Tabla2[[#This Row],[CODIGO]],Tabla1[],5,0),"") -> ALMACEN TICAPAMPA | G9: =IFERROR(VLOOKUP(Tabla2[[#This Row],[CODIGO]],Tabla1[],6,0),"") -> UNI | H9: =IFERROR(VLOOKUP(Tabla2[[#This Row],[CODIGO]],Tabla1[],10,0),"") -> 5 | I9: 10 | J9: Ingreso a Inventario | K9: =IFERROR(VLOOKUP(Tabla2[[#This Row],[CODIGO]],Tabla1[],11,0),"") -> COMPRA | L9: ACOSTA ROJAS, JOSEPH ALFONSO | M9: ACUACHI LANCHIPA ERNESTO ALONSO | N9: 45 | O9: =Tabla2[[#This Row],[CANTIDAD]]*Tabla2[[#This Row],[PREC. UNITARIO]] -> 450 | P9: FAC F001-007926 | R9: =Tabla2[[#This Row],[QUIEN RECIBE]]&"-"&TEXT(Tabla2[[#This Row],[FECHA]],"dd/mm/yyyy") -> ACUACHI LANCHIPA ERNESTO ALONSO-10/09/2025
B10: 45910 | C10: =IFERROR(_xlfn.XLOOKUP(Tabla2[[#This Row],[PRODUCTO]],Tabla1[PRODUCTO],Tabla1[CODIGO]),"") -> IS-3 | D10: Pantalon jeans dama s/marca T/30 | E10: =IFERROR(VLOOKUP(Tabla2[[#This Row],[CODIGO]],Tabla1[],3,0),"") -> IMPLEMENTOS DE SEGURIDAD | F10: =IFERROR(VLOOKUP(Tabla2[[#This Row],[CODIGO]],Tabla1[],5,0),"") -> ALMACEN TICAPAMPA | G10: =IFERROR(VLOOKUP(Tabla2[[#This Row],[CODIGO]],Tabla1[],6,0),"") -> UNI | H10: =IFERROR(VLOOKUP(Tabla2[[#This Row],[CODIGO]],Tabla1[],10,0),"") -> 0 | I10: 1 | J10: Ingreso a Inventario | K10: =IFERROR(VLOOKUP(Tabla2[[#This Row],[CODIGO]],Tabla1[],11,0),"") -> COMPRA | L10: ACOSTA ROJAS, JOSEPH ALFONSO | M10: ACUACHI LANCHIPA ERNESTO ALONSO | N10: 45 | O10: =Tabla2[[#This Row],[CANTIDAD]]*Tabla2[[#This Row],[PREC. UNITARIO]] -> 45 | P10: FAC F001-007926 | R10: =Tabla2[[#This Row],[QUIEN RECIBE]]&"-"&TEXT(Tabla2[[#This Row],[FECHA]],"dd/mm/yyyy") -> ACUACHI LANCHIPA ERNESTO ALONSO-10/09/2025
B11: 45910 | C11: =IFERROR(_xlfn.XLOOKUP(Tabla2[[#This Row],[PRODUCTO]],Tabla1[PRODUCTO],Tabla1[CODIGO]),"") -> IS-4 | D11: Pantalon jeans dama s/marca T/32 | E11: =IFERROR(VLOOKUP(Tabla2[[#This Row],[CODIGO]],Tabla1[],3,0),"") -> IMPLEMENTOS DE SEGURIDAD | F11: =IFERROR(VLOOKUP(Tabla2[[#This Row],[CODIGO]],Tabla1[],5,0),"") -> ALMACEN TICAPAMPA | G11: =IFERROR(VLOOKUP(Tabla2[[#This Row],[CODIGO]],Tabla1[],6,0),"") -> UNI | H11: =IFERROR(VLOOKUP(Tabla2[[#This Row],[CODIGO]],Tabla1[],10,0),"") -> 0 | I11: 1 | J11: Ingreso a Inventario | K11: =IFERROR(VLOOKUP(Tabla2[[#This Row],[CODIGO]],Tabla1[],11,0),"") -> COMPRA | L11: ACOSTA ROJAS, JOSEPH ALFONSO | M11: ACUACHI LANCHIPA ERNESTO ALONSO | N11: 45 | O11: =Tabla2[[#This Row],[CANTIDAD]]*Tabla2[[#This Row],[PREC. UNITARIO]] -> 45 | P11: FAC F001-007926 | R11: =Tabla2[[#This Row],[QUIEN RECIBE]]&"-"&TEXT(Tabla2[[#This Row],[FECHA]],"dd/mm/yyyy") -> ACUACHI LANCHIPA ERNESTO ALONSO-10/09/2025
B12: 45910 | C12: =IFERROR(_xlfn.XLOOKUP(Tabla2[[#This Row],[PRODUCTO]],Tabla1[PRODUCTO],Tabla1[CODIGO]),"") -> IS-5 | D12: Pantalon jeans dama s/maca T/34 | E12: =IFERROR(VLOOKUP(Tabla2[[#This Row],[CODIGO]],Tabla1[],3,0),"") -> IMPLEMENTOS DE SEGURIDAD | F12: =IFERROR(VLOOKUP(Tabla2[[#This Row],[CODIGO]],Tabla1[],5,0),"") -> ALMACEN TICAPAMPA | G12: =IFERROR(VLOOKUP(Tabla2[[#This Row],[CODIGO]],Tabla1[],6,0),"") -> UNI | H12: =IFERROR(VLOOKUP(Tabla2[[#This Row],[CODIGO]],Tabla1[],10,0),"") -> 0 | I12: 1 | J12: Ingreso a Inventario | K12: =IFERROR(VLOOKUP(Tabla2[[#This Row],[CODIGO]],Tabla1[],11,0),"") -> COMPRA | L12: ACOSTA ROJAS, JOSEPH ALFONSO | M12: ACUACHI LANCHIPA ERNESTO ALONSO | N12: 45 | O12: =Tabla2[[#This Row],[CANTIDAD]]*Tabla2[[#This Row],[PREC. UNITARIO]] -> 45 | P12: FAC F001-007926 | R12: =Tabla2[[#This Row],[QUIEN RECIBE]]&"-"&TEXT(Tabla2[[#This Row],[FECHA]],"dd/mm/yyyy") -> ACUACHI LANCHIPA ERNESTO ALONSO-10/09/2025
B13: 45910 | C13: =IFERROR(_xlfn.XLOOKUP(Tabla2[[#This Row],[PRODUCTO]],Tabla1[PRODUCTO],Tabla1[CODIGO]),"") -> IS-6 | D13: Chaleco Steel Power T/2XL | E13: =IFERROR(VLOOKUP(Tabla2[[#This Row],[CODIGO]],Tabla1[],3,0),"") -> IMPLEMENTOS DE SEGURIDAD | F13: =IFERROR(VLOOKUP(Tabla2[[#This Row],[CODIGO]],Tabla1[],5,0),"") -> ALMACEN TICAPAMPA | G13: =IFERROR(VLOOKUP(Tabla2[[#This Row],[CODIGO]],Tabla1[],6,0),"") -> UNI | H13: =IFERROR(VLOOKUP(Tabla2[[#This Row],[CODIGO]],Tabla1[],10,0),"") -> 0 | I13: 2 | J13: Ingreso a Inventario | K13: =IFERROR(VLOOKUP(Tabla2[[#This Row],[CODIGO]],Tabla1[],11,0),"") -> COMPRA | L13: ACOSTA ROJAS, JOSEPH ALFONSO | M13: ACUACHI LANCHIPA ERNESTO ALONSO | N13: 75 | O13: =Tabla2[[#This Row],[CANTIDAD]]*Tabla2[[#This Row],[PREC. UNITARIO]] -> 150 | P13: FAC F001-007926 | R13: =Tabla2[[#This Row],[QUIEN RECIBE]]&"-"&TEXT(Tabla2[[#This Row],[FECHA]],"dd/mm/yyyy") -> ACUACHI LANCHIPA ERNESTO ALONSO-10/09/2025
B14: 45910 | C14: =IFERROR(_xlfn.XLOOKUP(Tabla2[[#This Row],[PRODUCTO]],Tabla1[PRODUCTO],Tabla1[CODIGO]),"") -> IS-7 | D14: Chaleco Steel Power T/L | E14: =IFERROR(VLOOKUP(Tabla2[[#This Row],[CODIGO]],Tabla1[],3,0),"") -> IMPLEMENTOS DE SEGURIDAD | F14: =IFERROR(VLOOKUP(Tabla2[[#This Row],[CODIGO]],Tabla1[],5,0),"") -> ALMACEN TICAPAMPA | G14: =IFERROR(VLOOKUP(Tabla2[[#This Row],[CODIGO]],Tabla1[],6,0),"") -> UNI | H14: =IFERROR(VLOOKUP(Tabla2[[#This Row],[CODIGO]],Tabla1[],10,0),"") -> 0 | I14: 1 | J14: Ingreso a Inventario | K14: =IFERROR(VLOOKUP(Tabla2[[#This Row],[CODIGO]],Tabla1[],11,0),"") -> COMPRA | L14: ACOSTA ROJAS, JOSEPH ALFONSO | M14: ACUACHI LANCHIPA ERNESTO ALONSO | N14: 75 | O14: =Tabla2[[#This Row],[CANTIDAD]]*Tabla2[[#This Row],[PREC. UNITARIO]] -> 75 | P14: FAC F001-007926 | R14: =Tabla2[[#This Row],[QUIEN RECIBE]]&"-"&TEXT(Tabla2[[#This Row],[FECHA]],"dd/mm/yyyy") -> ACUACHI LANCHIPA ERNESTO ALONSO-10/09/2025
B15: 45910 | C15: =IFERROR(_xlfn.XLOOKUP(Tabla2[[#This Row],[PRODUCTO]],Tabla1[PRODUCTO],Tabla1[CODIGO]),"") -> IS-8 | D15: Chaleco Steel Power T/M | E15: =IFERROR(VLOOKUP(Tabla2[[#This Row],[CODIGO]],Tabla1[],3,0),"") -> IMPLEMENTOS DE SEGURIDAD | F15: =IFERROR(VLOOKUP(Tabla2[[#This Row],[CODIGO]],Tabla1[],5,0),"") -> ALMACEN TICAPAMPA | G15: =IFERROR(VLOOKUP(Tabla2[[#This Row],[CODIGO]],Tabla1[],6,0),"") -> UNI | H15: =IFERROR(VLOOKUP(Tabla2[[#This Row],[CODIGO]],Tabla1[],10,0),"") -> 0 | I15: 3 | J15: Ingreso a Inventario | K15: =IFERROR(VLOOKUP(Tabla2[[#This Row],[CODIGO]],Tabla1[],11,0),"") -> COMPRA | L15: ACOSTA ROJAS, JOSEPH ALFONSO | M15: ACUACHI LANCHIPA ERNESTO ALONSO | N15: 75 | O15: =Tabla2[[#This Row],[CANTIDAD]]*Tabla2[[#This Row],[PREC. UNITARIO]] -> 225 | P15: FAC F001-007926 | R15: =Tabla2[[#This Row],[QUIEN RECIBE]]&"-"&TEXT(Tabla2[[#This Row],[FECHA]],"dd/mm/yyyy") -> ACUACHI LANCHIPA ERNESTO ALONSO-10/09/2025
B16: 45910 | C16: =IFERROR(_xlfn.XLOOKUP(Tabla2[[#This Row],[PRODUCTO]],Tabla1[PRODUCTO],Tabla1[CODIGO]),"") -> IS-9 | D16: Camisa varon Fort Sport T/L | E16: =IFERROR(VLOOKUP(Tabla2[[#This Row],[CODIGO]],Tabla1[],3,0),"") -> IMPLEMENTOS DE SEGURIDAD | F16: =IFERROR(VLOOKUP(Tabla2[[#This Row],[CODIGO]],Tabla1[],5,0),"") -> ALMACEN TICAPAMPA | G16: =IFERROR(VLOOKUP(Tabla2[[#This Row],[CODIGO]],Tabla1[],6,0),"") -> UNI | H16: =IFERROR(VLOOKUP(Tabla2[[#This Row],[CODIGO]],Tabla1[],10,0),"") -> 0 | I16: 2 | J16: Ingreso a Inventario | K16: =IFERROR(VLOOKUP(Tabla2[[#This Row],[CODIGO]],Tabla1[],11,0),"") -> COMPRA | L16: ACOSTA ROJAS, JOSEPH ALFONSO | M16: ACUACHI LANCHIPA ERNESTO ALONSO | N16: 38 | O16: =Tabla2[[#This Row],[CANTIDAD]]*Tabla2[[#This Row],[PREC. UNITARIO]] -> 76 | R16: =Tabla2[[#This Row],[QUIEN RECIBE]]&"-"&TEXT(Tabla2[[#This Row],[FECHA]],"dd/mm/yyyy") -> ACUACHI LANCHIPA ERNESTO ALONSO-10/09/2025
B17: 45910 | C17: =IFERROR(_xlfn.XLOOKUP(Tabla2[[#This Row],[PRODUCTO]],Tabla1[PRODUCTO],Tabla1[CODIGO]),"") -> IS-10 | D17: Camisa varon Fort Sport T/XL | E17: =IFERROR(VLOOKUP(Tabla2[[#This Row],[CODIGO]],Tabla1[],3,0),"") -> IMPLEMENTOS DE SEGURIDAD | F17: =IFERROR(VLOOKUP(Tabla2[[#This Row],[CODIGO]],Tabla1[],5,0),"") -> ALMACEN TICAPAMPA | G17: =IFERROR(VLOOKUP(Tabla2[[#This Row],[CODIGO]],Tabla1[],6,0),"") -> UNI | H17: =IFERROR(VLOOKUP(Tabla2[[#This Row],[CODIGO]],Tabla1[],10,0),"") -> 0 | I17: 4 | J17: Ingreso a Inventario | K17: =IFERROR(VLOOKUP(Tabla2[[#This Row],[CODIGO]],Tabla1[],11,0),"") -> COMPRA | L17: ACOSTA ROJAS, JOSEPH ALFONSO | M17: ACUACHI LANCHIPA ERNESTO ALONSO | N17: 38 | O17: =Tabla2[[#This Row],[CANTIDAD]]*Tabla2[[#This Row],[PREC. UNITARIO]] -> 152 | R17: =Tabla2[[#This Row],[QUIEN RECIBE]]&"-"&TEXT(Tabla2[[#This Row],[FECHA]],"dd/mm/yyyy") -> ACUACHI LANCHIPA ERNESTO ALONSO-10/09/2025
B18: 45910 | C18: =IFERROR(_xlfn.XLOOKUP(Tabla2[[#This Row],[PRODUCTO]],Tabla1[PRODUCTO],Tabla1[CODIGO]),"") -> IS-11 | D18: Camisa dama Fort Sport T/M | E18: =IFERROR(VLOOKUP(Tabla2[[#This Row],[CODIGO]],Tabla1[],3,0),"") -> IMPLEMENTOS DE SEGURIDAD | F18: =IFERROR(VLOOKUP(Tabla2[[#This Row],[CODIGO]],Tabla1[],5,0),"") -> ALMACEN TICAPAMPA | G18: =IFERROR(VLOOKUP(Tabla2[[#This Row],[CODIGO]],Tabla1[],6,0),"") -> UNI | H18: =IFERROR(VLOOKUP(Tabla2[[#This Row],[CODIGO]],Tabla1[],10,0),"") -> 0 | I18: 5 | J18: Ingreso a Inventario | K18: =IFERROR(VLOOKUP(Tabla2[[#This Row],[CODIGO]],Tabla1[],11,0),"") -> COMPRA | L18: ACOSTA ROJAS, JOSEPH ALFONSO | M18: ACUACHI LANCHIPA ERNESTO ALONSO | N18: 38 | O18: =Tabla2[[#This Row],[CANTIDAD]]*Tabla2[[#This Row],[PREC. UNITARIO]] -> 190 | R18: =Tabla2[[#This Row],[QUIEN RECIBE]]&"-"&TEXT(Tabla2[[#This Row],[FECHA]],"dd/mm/yyyy") -> ACUACHI LANCHIPA ERNESTO ALONSO-10/09/2025
B19: 45910 | C19: =IFERROR(_xlfn.XLOOKUP(Tabla2[[#This Row],[PRODUCTO]],Tabla1[PRODUCTO],Tabla1[CODIGO]),"") -> IS-12 | D19: Camisa dama Fort Sport T/L | E19: =IFERROR(VLOOKUP(Tabla2[[#This Row],[CODIGO]],Tabla1[],3,0),"") -> IMPLEMENTOS DE SEGURIDAD | F19: =IFERROR(VLOOKUP(Tabla2[[#This Row],[CODIGO]],Tabla1[],5,0),"") -> ALMACEN TICAPAMPA | G19: =IFERROR(VLOOKUP(Tabla2[[#This Row],[CODIGO]],Tabla1[],6,0),"") -> UNI | H19: =IFERROR(VLOOKUP(Tabla2[[#This Row],[CODIGO]],Tabla1[],10,0),"") -> 0 | I19: 1 | J19: Ingreso a Inventario | K19: =IFERROR(VLOOKUP(Tabla2[[#This Row],[CODIGO]],Tabla1[],11,0),"") -> COMPRA | L19: ACOSTA ROJAS, JOSEPH ALFONSO | M19: ACUACHI LANCHIPA ERNESTO ALONSO | N19: 38 | O19: =Tabla2[[#This Row],[CANTIDAD]]*Tabla2[[#This Row],[PREC. UNITARIO]] -> 38 | R19: =Tabla2[[#This Row],[QUIEN RECIBE]]&"-"&TEXT(Tabla2[[#This Row],[FECHA]],"dd/mm/yyyy") -> ACUACHI LANCHIPA ERNESTO ALONSO-10/09/2025
B20: 45910 | C20: =IFERROR(_xlfn.XLOOKUP(Tabla2[[#This Row],[PRODUCTO]],Tabla1[PRODUCTO],Tabla1[CODIGO]),"") -> IS-13 | D20: Pantalon jeans varon m/Jusbrend T/36 | E20: =IFERROR(VLOOKUP(Tabla2[[#This Row],[CODIGO]],Tabla1[],3,0),"") -> IMPLEMENTOS DE SEGURIDAD | F20: =IFERROR(VLOOKUP(Tabla2[[#This Row],[CODIGO]],Tabla1[],5,0),"") -> ALMACEN TICAPAMPA | G20: =IFERROR(VLOOKUP(Tabla2[[#This Row],[CODIGO]],Tabla1[],6,0),"") -> UNI | H20: =IFERROR(VLOOKUP(Tabla2[[#This Row],[CODIGO]],Tabla1[],10,0),"") -> 2 | I20: 1 | J20: Ingreso a Inventario | K20: =IFERROR(VLOOKUP(Tabla2[[#This Row],[CODIGO]],Tabla1[],11,0),"") -> COMPRA | L20: ACOSTA ROJAS, JOSEPH ALFONSO | M20: ACUACHI LANCHIPA ERNESTO ALONSO | N20: 45 | O20: =Tabla2[[#This Row],[CANTIDAD]]*Tabla2[[#This Row],[PREC. UNITARIO]] -> 45 | P20: FAC F001-007926 | R20: =Tabla2[[#This Row],[QUIEN RECIBE]]&"-"&TEXT(Tabla2[[#This Row],[FECHA]],"dd/mm/yyyy") -> ACUACHI LANCHIPA ERNESTO ALONSO-10/09/2025
B21: 45910 | C21: =IFERROR(_xlfn.XLOOKUP(Tabla2[[#This Row],[PRODUCTO]],Tabla1[PRODUCTO],Tabla1[CODIGO]),"") -> IS-14 | D21: Cortaviento diferentes colores | E21: =IFERROR(VLOOKUP(Tabla2[[#This Row],[CODIGO]],Tabla1[],3,0),"") -> IMPLEMENTOS DE SEGURIDAD | F21: =IFERROR(VLOOKUP(Tabla2[[#This Row],[CODIGO]],Tabla1[],5,0),"") -> ALMACEN TICAPAMPA | G21: =IFERROR(VLOOKUP(Tabla2[[#This Row],[CODIGO]],Tabla1[],6,0),"") -> UNI | H21: =IFERROR(VLOOKUP(Tabla2[[#This Row],[CODIGO]],Tabla1[],10,0),"") -> 1 | I21: 30 | J21: Ingreso a Inventario | K21: =IFERROR(VLOOKUP(Tabla2[[#This Row],[CODIGO]],Tabla1[],11,0),"") -> COMPRA | L21: ACOSTA ROJAS, JOSEPH ALFONSO | M21: ACUACHI LANCHIPA ERNESTO ALONSO | N21: 4 | O21: =Tabla2[[#This Row],[CANTIDAD]]*Tabla2[[#This Row],[PREC. UNITARIO]] -> 120 | P21: FAC F001-007926 | R21: =Tabla2[[#This Row],[QUIEN RECIBE]]&"-"&TEXT(Tabla2[[#This Row],[FECHA]],"dd/mm/yyyy") -> ACUACHI LANCHIPA ERNESTO ALONSO-10/09/2025
B22: 45910 | C22: =IFERROR(_xlfn.XLOOKUP(Tabla2[[#This Row],[PRODUCTO]],Tabla1[PRODUCTO],Tabla1[CODIGO]),"") -> IS-15 | D22: Zapato de seguridad Hunter T/40 | E22: =IFERROR(VLOOKUP(Tabla2[[#This Row],[CODIGO]],Tabla1[],3,0),"") -> IMPLEMENTOS DE SEGURIDAD | F22: =IFERROR(VLOOKUP(Tabla2[[#This Row],[CODIGO]],Tabla1[],5,0),"") -> ALMACEN TICAPAMPA | G22: =IFERROR(VLOOKUP(Tabla2[[#This Row],[CODIGO]],Tabla1[],6,0),"") -> PAR | H22: =IFERROR(VLOOKUP(Tabla2[[#This Row],[CODIGO]],Tabla1[],10,0),"") -> 0 | I22: 10 | J22: Ingreso a Inventario | K22: =IFERROR(VLOOKUP(Tabla2[[#This Row],[CODIGO]],Tabla1[],11,0),"") -> COMPRA | L22: ACOSTA ROJAS, JOSEPH ALFONSO | M22: ACUACHI LANCHIPA ERNESTO ALONSO | N22: 63 | O22: =Tabla2[[#This Row],[CANTIDAD]]*Tabla2[[#This Row],[PREC. UNITARIO]] -> 630 | R22: =Tabla2[[#This Row],[QUIEN RECIBE]]&"-"&TEXT(Tabla2[[#This Row],[FECHA]],"dd/mm/yyyy") -> ACUACHI LANCHIPA ERNESTO ALONSO-10/09/2025
B23: 45910 | C23: =IFERROR(_xlfn.XLOOKUP(Tabla2[[#This Row],[PRODUCTO]],Tabla1[PRODUCTO],Tabla1[CODIGO]),"") -> IS-16 | D23: Zapato de seguridad Hunter T/41 | E23: =IFERROR(VLOOKUP(Tabla2[[#This Row],[CODIGO]],Tabla1[],3,0),"") -> IMPLEMENTOS DE SEGURIDAD | F23: =IFERROR(VLOOKUP(Tabla2[[#This Row],[CODIGO]],Tabla1[],5,0),"") -> ALMACEN TICAPAMPA | G23: =IFERROR(VLOOKUP(Tabla2[[#This Row],[CODIGO]],Tabla1[],6,0),"") -> PAR | H23: =IFERROR(VLOOKUP(Tabla2[[#This Row],[CODIGO]],Tabla1[],10,0),"") -> 1 | I23: 3 | J23: Ingreso a Inventario | K23: =IFERROR(VLOOKUP(Tabla2[[#This Row],[CODIGO]],Tabla1[],11,0),"") -> COMPRA | L23: ACOSTA ROJAS, JOSEPH ALFONSO | M23: ACUACHI LANCHIPA ERNESTO ALONSO | N23: 63 | O23: =Tabla2[[#This Row],[CANTIDAD]]*Tabla2[[#This Row],[PREC. UNITARIO]] -> 189 | R23: =Tabla2[[#This Row],[QUIEN RECIBE]]&"-"&TEXT(Tabla2[[#This Row],[FECHA]],"dd/mm/yyyy") -> ACUACHI LANCHIPA ERNESTO ALONSO-10/09/2025
B24: 45910 | C24: =IFERROR(_xlfn.XLOOKUP(Tabla2[[#This Row],[PRODUCTO]],Tabla1[PRODUCTO],Tabla1[CODIGO]),"") -> IS-17 | D24: Zapato de seguridad Hunter T/42 | E24: =IFERROR(VLOOKUP(Tabla2[[#This Row],[CODIGO]],Tabla1[],3,0),"") -> IMPLEMENTOS DE SEGURIDAD | F24: =IFERROR(VLOOKUP(Tabla2[[#This Row],[CODIGO]],Tabla1[],5,0),"") -> ALMACEN TICAPAMPA | G24: =IFERROR(VLOOKUP(Tabla2[[#This Row],[CODIGO]],Tabla1[],6,0),"") -> PAR | H24: =IFERROR(VLOOKUP(Tabla2[[#This Row],[CODIGO]],Tabla1[],10,0),"") -> 0 | I24: 7 | J24: Ingreso a Inventario | K24: =IFERROR(VLOOKUP(Tabla2[[#This Row],[CODIGO]],Tabla1[],11,0),"") -> COMPRA | L24: ACOSTA ROJAS, JOSEPH ALFONSO | M24: ACUACHI LANCHIPA ERNESTO ALONSO | N24: 63 | O24: =Tabla2[[#This Row],[CANTIDAD]]*Tabla2[[#This Row],[PREC. UNITARIO]] -> 441 | R24: =Tabla2[[#This Row],[QUIEN RECIBE]]&"-"&TEXT(Tabla2[[#This Row],[FECHA]],"dd/mm/yyyy") -> ACUACHI LANCHIPA ERNESTO ALONSO-10/09/2025
B25: 45910 | C25: =IFERROR(_xlfn.XLOOKUP(Tabla2[[#This Row],[PRODUCTO]],Tabla1[PRODUCTO],Tabla1[CODIGO]),"") -> IS-18 | D25: Casco de seguridad blanco 3M | E25: =IFERROR(VLOOKUP(Tabla2[[#This Row],[CODIGO]],Tabla1[],3,0),"") -> IMPLEMENTOS DE SEGURIDAD | F25: =IFERROR(VLOOKUP(Tabla2[[#This Row],[CODIGO]],Tabla1[],5,0),"") -> ALMACEN TICAPAMPA | G25: =IFERROR(VLOOKUP(Tabla2[[#This Row],[CODIGO]],Tabla1[],6,0),"") -> UNI | H25: =IFERROR(VLOOKUP(Tabla2[[#This Row],[CODIGO]],Tabla1[],10,0),"") -> 0 | I25: 6 | J25: Ingreso a Inventario | K25: =IFERROR(VLOOKUP(Tabla2[[#This Row],[CODIGO]],Tabla1[],11,0),"") -> COMPRA | L25: ACOSTA ROJAS, JOSEPH ALFONSO | M25: ACUACHI LANCHIPA ERNESTO ALONSO | N25: 45 | O25: =Tabla2[[#This Row],[CANTIDAD]]*Tabla2[[#This Row],[PREC. UNITARIO]] -> 270 | P25: FAC F001-007926 | R25: =Tabla2[[#This Row],[QUIEN RECIBE]]&"-"&TEXT(Tabla2[[#This Row],[FECHA]],"dd/mm/yyyy") -> ACUACHI LANCHIPA ERNESTO ALONSO-10/09/2025
B26: 45910 | C26: =IFERROR(_xlfn.XLOOKUP(Tabla2[[#This Row],[PRODUCTO]],Tabla1[PRODUCTO],Tabla1[CODIGO]),"") -> IS-19 | D26: Casco de seguridad plomo Asthers | E26: =IFERROR(VLOOKUP(Tabla2[[#This Row],[CODIGO]],Tabla1[],3,0),"") -> IMPLEMENTOS DE SEGURIDAD | F26: =IFERROR(VLOOKUP(Tabla2[[#This Row],[CODIGO]],Tabla1[],5,0),"") -> ALMACEN TICAPAMPA | G26: =IFERROR(VLOOKUP(Tabla2[[#This Row],[CODIGO]],Tabla1[],6,0),"") -> UNI | H26: =IFERROR(VLOOKUP(Tabla2[[#This Row],[CODIGO]],Tabla1[],10,0),"") -> 4 | I26: 4 | J26: Ingreso a Inventario | K26: =IFERROR(VLOOKUP(Tabla2[[#This Row],[CODIGO]],Tabla1[],11,0),"") -> COMPRA | L26: ACOSTA ROJAS, JOSEPH ALFONSO | M26: ACUACHI LANCHIPA ERNESTO ALONSO | N26: 6.5 | O26: =Tabla2[[#This Row],[CANTIDAD]]*Tabla2[[#This Row],[PREC. UNITARIO]] -> 26 | P26: FAC F001-007926 | R26: =Tabla2[[#This Row],[QUIEN RECIBE]]&"-"&TEXT(Tabla2[[#This Row],[FECHA]],"dd/mm/yyyy") -> ACUACHI LANCHIPA ERNESTO ALONSO-10/09/2025
B27: 45910 | C27: =IFERROR(_xlfn.XLOOKUP(Tabla2[[#This Row],[PRODUCTO]],Tabla1[PRODUCTO],Tabla1[CODIGO]),"") -> IS-20 | D27: Casco de seguridad azul Asthers | E27: =IFERROR(VLOOKUP(Tabla2[[#This Row],[CODIGO]],Tabla1[],3,0),"") -> IMPLEMENTOS DE SEGURIDAD | F27: =IFERROR(VLOOKUP(Tabla2[[#This Row],[CODIGO]],Tabla1[],5,0),"") -> ALMACEN TICAPAMPA | G27: =IFERROR(VLOOKUP(Tabla2[[#This Row],[CODIGO]],Tabla1[],6,0),"") -> UNI | H27: =IFERROR(VLOOKUP(Tabla2[[#This Row],[CODIGO]],Tabla1[],10,0),"") -> 5 | I27: 10 | J27: Ingreso a Inventario | K27: =IFERROR(VLOOKUP(Tabla2[[#This Row],[CODIGO]],Tabla1[],11,0),"") -> COMPRA | L27: ACOSTA ROJAS, JOSEPH ALFONSO | M27: ACUACHI LANCHIPA ERNESTO ALONSO | N27: 6.5 | O27: =Tabla2[[#This Row],[CANTIDAD]]*Tabla2[[#This Row],[PREC. UNITARIO]] -> 65 | P27: FAC F001-007926 | R27: =Tabla2[[#This Row],[QUIEN RECIBE]]&"-"&TEXT(Tabla2[[#This Row],[FECHA]],"dd/mm/yyyy") -> ACUACHI LANCHIPA ERNESTO ALONSO-10/09/2025
B28: 45910 | C28: =IFERROR(_xlfn.XLOOKUP(Tabla2[[#This Row],[PRODUCTO]],Tabla1[PRODUCTO],Tabla1[CODIGO]),"") -> IS-21 | D28: Casco de seguridad amarillo Asthers | E28: =IFERROR(VLOOKUP(Tabla2[[#This Row],[CODIGO]],Tabla1[],3,0),"") -> IMPLEMENTOS DE SEGURIDAD | F28: =IFERROR(VLOOKUP(Tabla2[[#This Row],[CODIGO]],Tabla1[],5,0),"") -> ALMACEN TICAPAMPA | G28: =IFERROR(VLOOKUP(Tabla2[[#This Row],[CODIGO]],Tabla1[],6,0),"") -> UNI | H28: =IFERROR(VLOOKUP(Tabla2[[#This Row],[CODIGO]],Tabla1[],10,0),"") -> 13 | I28: 20 | J28: Ingreso a Inventario | K28: =IFERROR(VLOOKUP(Tabla2[[#This Row],[CODIGO]],Tabla1[],11,0),"") -> COMPRA | L28: ACOSTA ROJAS, JOSEPH ALFONSO | M28: ACUACHI LANCHIPA ERNESTO ALONSO | N28: 6.5 | O28: =Tabla2[[#This Row],[CANTIDAD]]*Tabla2[[#This Row],[PREC. UNITARIO]] -> 130 | P28: FAC F001-007926 | R28: =Tabla2[[#This Row],[QUIEN RECIBE]]&"-"&TEXT(Tabla2[[#This Row],[FECHA]],"dd/mm/yyyy") -> ACUACHI LANCHIPA ERNESTO ALONSO-10/09/2025
B29: 45910 | C29: =IFERROR(_xlfn.XLOOKUP(Tabla2[[#This Row],[PRODUCTO]],Tabla1[PRODUCTO],Tabla1[CODIGO]),"") -> IS-34 | D29: Accesorio para el casco | E29: =IFERROR(VLOOKUP(Tabla2[[#This Row],[CODIGO]],Tabla1[],3,0),"") -> IMPLEMENTOS DE SEGURIDAD | F29: =IFERROR(VLOOKUP(Tabla2[[#This Row],[CODIGO]],Tabla1[],5,0),"") -> ALMACEN TICAPAMPA | G29: =IFERROR(VLOOKUP(Tabla2[[#This Row],[CODIGO]],Tabla1[],6,0),"") -> UNI | H29: =IFERROR(VLOOKUP(Tabla2[[#This Row],[CODIGO]],Tabla1[],10,0),"") -> 34 | I29: 34 | J29: Ingreso a Inventario | K29: =IFERROR(VLOOKUP(Tabla2[[#This Row],[CODIGO]],Tabla1[],11,0),"") -> COMPRA | L29: ACOSTA ROJAS, JOSEPH ALFONSO | M29: ACUACHI LANCHIPA ERNESTO ALONSO | N29: 0 | O29: =Tabla2[[#This Row],[CANTIDAD]]*Tabla2[[#This Row],[PREC. UNITARIO]] -> 0 | P29: FAC F001-007926 | R29: =Tabla2[[#This Row],[QUIEN RECIBE]]&"-"&TEXT(Tabla2[[#This Row],[FECHA]],"dd/mm/yyyy") -> ACUACHI LANCHIPA ERNESTO ALONSO-10/09/2025
B30: 45910 | C30: =IFERROR(_xlfn.XLOOKUP(Tabla2[[#This Row],[PRODUCTO]],Tabla1[PRODUCTO],Tabla1[CODIGO]),"") -> IS-22 | D30: Malla de seguridad 1m x 50yds Spro | E30: =IFERROR(VLOOKUP(Tabla2[[#This Row],[CODIGO]],Tabla1[],3,0),"") -> IMPLEMENTOS DE SEGURIDAD | F30: =IFERROR(VLOOKUP(Tabla2[[#This Row],[CODIGO]],Tabla1[],5,0),"") -> ALMACEN TICAPAMPA | G30: =IFERROR(VLOOKUP(Tabla2[[#This Row],[CODIGO]],Tabla1[],6,0),"") -> ROL | H30: =IFERROR(VLOOKUP(Tabla2[[#This Row],[CODIGO]],Tabla1[],10,0),"") -> 6 | I30: 6 | J30: Ingreso a Inventario | K30: =IFERROR(VLOOKUP(Tabla2[[#This Row],[CODIGO]],Tabla1[],11,0),"") -> COMPRA | L30: ACOSTA ROJAS, JOSEPH ALFONSO | M30: ACUACHI LANCHIPA ERNESTO ALONSO | N30: 27 | O30: =Tabla2[[#This Row],[CANTIDAD]]*Tabla2[[#This Row],[PREC. UNITARIO]] -> 162 | R30: =Tabla2[[#This Row],[QUIEN RECIBE]]&"-"&TEXT(Tabla2[[#This Row],[FECHA]],"dd/mm/yyyy") -> ACUACHI LANCHIPA ERNESTO ALONSO-10/09/2025
B31: 45910 | C31: =IFERROR(_xlfn.XLOOKUP(Tabla2[[#This Row],[PRODUCTO]],Tabla1[PRODUCTO],Tabla1[CODIGO]),"") -> HM-1 | D31: Pala redonda 71cm Tramontina | E31: =IFERROR(VLOOKUP(Tabla2[[#This Row],[CODIGO]],Tabla1[],3,0),"") -> HERRAMIENTAS | F31: =IFERROR(VLOOKUP(Tabla2[[#This Row],[CODIGO]],Tabla1[],5,0),"") -> ALMACEN TICAPAMPA | G31: =IFERROR(VLOOKUP(Tabla2[[#This Row],[CODIGO]],Tabla1[],6,0),"") -> UNI | H31: =IFERROR(VLOOKUP(Tabla2[[#This Row],[CODIGO]],Tabla1[],10,0),"") -> 15 | I31: 15 | J31: Ingreso a Inventario | K31: =IFERROR(VLOOKUP(Tabla2[[#This Row],[CODIGO]],Tabla1[],11,0),"") -> COMPRA | L31: ACOSTA ROJAS, JOSEPH ALFONSO | M31: ACUACHI LANCHIPA ERNESTO ALONSO | N31: 25 | O31: =Tabla2[[#This Row],[CANTIDAD]]*Tabla2[[#This Row],[PREC. UNITARIO]] -> 375 | R31: =Tabla2[[#This Row],[QUIEN RECIBE]]&"-"&TEXT(Tabla2[[#This Row],[FECHA]],"dd/mm/yyyy") -> ACUACHI LANCHIPA ERNESTO ALONSO-10/09/2025
B32: 45910 | C32: =IFERROR(_xlfn.XLOOKUP(Tabla2[[#This Row],[PRODUCTO]],Tabla1[PRODUCTO],Tabla1[CODIGO]),"") -> IS-23 | D32: Lentes de seguridad luna blanca Spro Startec | E32: =IFERROR(VLOOKUP(Tabla2[[#This Row],[CODIGO]],Tabla1[],3,0),"") -> IMPLEMENTOS DE SEGURIDAD | F32: =IFERROR(VLOOKUP(Tabla2[[#This Row],[CODIGO]],Tabla1[],5,0),"") -> ALMACEN TICAPAMPA | G32: =IFERROR(VLOOKUP(Tabla2[[#This Row],[CODIGO]],Tabla1[],6,0),"") -> UNI | H32: =IFERROR(VLOOKUP(Tabla2[[#This Row],[CODIGO]],Tabla1[],10,0),"") -> 34 | I32: 40 | J32: Ingreso a Inventario | K32: =IFERROR(VLOOKUP(Tabla2[[#This Row],[CODIGO]],Tabla1[],11,0),"") -> COMPRA | L32: ACOSTA ROJAS, JOSEPH ALFONSO | M32: ACUACHI LANCHIPA ERNESTO ALONSO | N32: 4 | O32: =Tabla2[[#This Row],[CANTIDAD]]*Tabla2[[#This Row],[PREC. UNITARIO]] -> 160 | P32: FAC F001-007926 | R32: =Tabla2[[#This Row],[QUIEN RECIBE]]&"-"&TEXT(Tabla2[[#This Row],[FECHA]],"dd/mm/yyyy") -> ACUACHI LANCHIPA ERNESTO ALONSO-10/09/2025
B33: 45910 | C33: =IFERROR(_xlfn.XLOOKUP(Tabla2[[#This Row],[PRODUCTO]],Tabla1[PRODUCTO],Tabla1[CODIGO]),"") -> IS-24 | D33: Mascarilla kn95 3M | E33: =IFERROR(VLOOKUP(Tabla2[[#This Row],[CODIGO]],Tabla1[],3,0),"") -> IMPLEMENTOS DE SEGURIDAD | F33: =IFERROR(VLOOKUP(Tabla2[[#This Row],[CODIGO]],Tabla1[],5,0),"") -> ALMACEN TICAPAMPA | G33: =IFERROR(VLOOKUP(Tabla2[[#This Row],[CODIGO]],Tabla1[],6,0),"") -> UNI | H33: =IFERROR(VLOOKUP(Tabla2[[#This Row],[CODIGO]],Tabla1[],10,0),"") -> 15 | I33: 15 | J33: Ingreso a Inventario | K33: =IFERROR(VLOOKUP(Tabla2[[#This Row],[CODIGO]],Tabla1[],11,0),"") -> COMPRA | L33: ACOSTA ROJAS, JOSEPH ALFONSO | M33: ACUACHI LANCHIPA ERNESTO ALONSO | N33: 10 | O33: =Tabla2[[#This Row],[CANTIDAD]]*Tabla2[[#This Row],[PREC. UNITARIO]] -> 150 | R33: =Tabla2[[#This Row],[QUIEN RECIBE]]&"-"&TEXT(Tabla2[[#This Row],[FECHA]],"dd/mm/yyyy") -> ACUACHI LANCHIPA ERNESTO ALONSO-10/09/2025
B34: 45910 | C34: =IFERROR(_xlfn.XLOOKUP(Tabla2[[#This Row],[PRODUCTO]],Tabla1[PRODUCTO],Tabla1[CODIGO]),"") -> IS-25 | D34: Cubre barbilla Tridente | E34: =IFERROR(VLOOKUP(Tabla2[[#This Row],[CODIGO]],Tabla1[],3,0),"") -> IMPLEMENTOS DE SEGURIDAD | F34: =IFERROR(VLOOKUP(Tabla2[[#This Row],[CODIGO]],Tabla1[],5,0),"") -> ALMACEN TICAPAMPA | G34: =IFERROR(VLOOKUP(Tabla2[[#This Row],[CODIGO]],Tabla1[],6,0),"") -> UNI | H34: =IFERROR(VLOOKUP(Tabla2[[#This Row],[CODIGO]],Tabla1[],10,0),"") -> 25 | I34: 30 | J34: Ingreso a Inventario | K34: =IFERROR(VLOOKUP(Tabla2[[#This Row],[CODIGO]],Tabla1[],11,0),"") -> COMPRA | L34: ACOSTA ROJAS, JOSEPH ALFONSO | M34: ACUACHI LANCHIPA ERNESTO ALONSO | N34: 2 | O34: =Tabla2[[#This Row],[CANTIDAD]]*Tabla2[[#This Row],[PREC. UNITARIO]] -> 60 | R34: =Tabla2[[#This Row],[QUIEN RECIBE]]&"-"&TEXT(Tabla2[[#This Row],[FECHA]],"dd/mm/yyyy") -> ACUACHI LANCHIPA ERNESTO ALONSO-10/09/2025
B35: 45910 | C35: =IFERROR(_xlfn.XLOOKUP(Tabla2[[#This Row],[PRODUCTO]],Tabla1[PRODUCTO],Tabla1[CODIGO]),"") -> IS-26 | D35: Guante de latex #25 Frotex T/9 | E35: =IFERROR(VLOOKUP(Tabla2[[#This Row],[CODIGO]],Tabla1[],3,0),"") -> IMPLEMENTOS DE SEGURIDAD | F35: =IFERROR(VLOOKUP(Tabla2[[#This Row],[CODIGO]],Tabla1[],5,0),"") -> ALMACEN TICAPAMPA | G35: =IFERROR(VLOOKUP(Tabla2[[#This Row],[CODIGO]],Tabla1[],6,0),"") -> UNI | H35: =IFERROR(VLOOKUP(Tabla2[[#This Row],[CODIGO]],Tabla1[],10,0),"") -> 16 | I35: 20 | J35: Ingreso a Inventario | K35: =IFERROR(VLOOKUP(Tabla2[[#This Row],[CODIGO]],Tabla1[],11,0),"") -> COMPRA | L35: ACOSTA ROJAS, JOSEPH ALFONSO | M35: ACUACHI LANCHIPA ERNESTO ALONSO | N35: 8 | O35: =Tabla2[[#This Row],[CANTIDAD]]*Tabla2[[#This Row],[PREC. UNITARIO]] -> 160 | R35: =Tabla2[[#This Row],[QUIEN RECIBE]]&"-"&TEXT(Tabla2[[#This Row],[FECHA]],"dd/mm/yyyy") -> ACUACHI LANCHIPA ERNESTO ALONSO-10/09/2025
B36: 45910 | C36: =IFERROR(_xlfn.XLOOKUP(Tabla2[[#This Row],[PRODUCTO]],Tabla1[PRODUCTO],Tabla1[CODIGO]),"") -> IS-27 | D36: Lentes de seguridad luna blanca Clute/Astros | E36: =IFERROR(VLOOKUP(Tabla2[[#This Row],[CODIGO]],Tabla1[],3,0),"") -> IMPLEMENTOS DE SEGURIDAD | F36: =IFERROR(VLOOKUP(Tabla2[[#This Row],[CODIGO]],Tabla1[],5,0),"") -> ALMACEN TICAPAMPA | G36: =IFERROR(VLOOKUP(Tabla2[[#This Row],[CODIGO]],Tabla1[],6,0),"") -> UNI | H36: =IFERROR(VLOOKUP(Tabla2[[#This Row],[CODIGO]],Tabla1[],10,0),"") -> 100 | I36: 100 | J36: Ingreso a Inventario | K36: =IFERROR(VLOOKUP(Tabla2[[#This Row],[CODIGO]],Tabla1[],11,0),"") -> COMPRA | L36: ACOSTA ROJAS, JOSEPH ALFONSO | M36: ACUACHI LANCHIPA ERNESTO ALONSO | N36: 4 | O36: =Tabla2[[#This Row],[CANTIDAD]]*Tabla2[[#This Row],[PREC. UNITARIO]] -> 400 | P36: FAC F001-007926 | R36: =Tabla2[[#This Row],[QUIEN RECIBE]]&"-"&TEXT(Tabla2[[#This Row],[FECHA]],"dd/mm/yyyy") -> ACUACHI LANCHIPA ERNESTO ALONSO-10/09/2025
B37: 45910 | C37: =IFERROR(_xlfn.XLOOKUP(Tabla2[[#This Row],[PRODUCTO]],Tabla1[PRODUCTO],Tabla1[CODIGO]),"") -> IS-28 | D37: Lentes de seguridad luna oscura Clute/Astros | E37: =IFERROR(VLOOKUP(Tabla2[[#This Row],[CODIGO]],Tabla1[],3,0),"") -> IMPLEMENTOS DE SEGURIDAD | F37: =IFERROR(VLOOKUP(Tabla2[[#This Row],[CODIGO]],Tabla1[],5,0),"") -> ALMACEN TICAPAMPA | G37: =IFERROR(VLOOKUP(Tabla2[[#This Row],[CODIGO]],Tabla1[],6,0),"") -> UNI | H37: =IFERROR(VLOOKUP(Tabla2[[#This Row],[CODIGO]],Tabla1[],10,0),"") -> 32 | I37: 60 | J37: Ingreso a Inventario | K37: =IFERROR(VLOOKUP(Tabla2[[#This Row],[CODIGO]],Tabla1[],11,0),"") -> COMPRA | L37: ACOSTA ROJAS, JOSEPH ALFONSO | M37: ACUACHI LANCHIPA ERNESTO ALONSO | N37: 4 | O37: =Tabla2[[#This Row],[CANTIDAD]]*Tabla2[[#This Row],[PREC. UNITARIO]] -> 240 | P37: FAC F001-007926 | R37: =Tabla2[[#This Row],[QUIEN RECIBE]]&"-"&TEXT(Tabla2[[#This Row],[FECHA]],"dd/mm/yyyy") -> ACUACHI LANCHIPA ERNESTO ALONSO-10/09/2025
B38: 45910 | C38: =IFERROR(_xlfn.XLOOKUP(Tabla2[[#This Row],[PRODUCTO]],Tabla1[PRODUCTO],Tabla1[CODIGO]),"") -> IS-29 | D38: Cinta de seguridad No Pasar | E38: =IFERROR(VLOOKUP(Tabla2[[#This Row],[CODIGO]],Tabla1[],3,0),"") -> IMPLEMENTOS DE SEGURIDAD | F38: =IFERROR(VLOOKUP(Tabla2[[#This Row],[CODIGO]],Tabla1[],5,0),"") -> ALMACEN TICAPAMPA | G38: =IFERROR(VLOOKUP(Tabla2[[#This Row],[CODIGO]],Tabla1[],6,0),"") -> ROL | H38: =IFERROR(VLOOKUP(Tabla2[[#This Row],[CODIGO]],Tabla1[],10,0),"") -> 6 | I38: 6 | J38: Ingreso a Inventario | K38: =IFERROR(VLOOKUP(Tabla2[[#This Row],[CODIGO]],Tabla1[],11,0),"") -> COMPRA | L38: ACOSTA ROJAS, JOSEPH ALFONSO | M38: ACUACHI LANCHIPA ERNESTO ALONSO | N38: 22 | O38: =Tabla2[[#This Row],[CANTIDAD]]*Tabla2[[#This Row],[PREC. UNITARIO]] -> 132 | R38: =Tabla2[[#This Row],[QUIEN RECIBE]]&"-"&TEXT(Tabla2[[#This Row],[FECHA]],"dd/mm/yyyy") -> ACUACHI LANCHIPA ERNESTO ALONSO-10/09/2025
B39: 45910 | C39: =IFERROR(_xlfn.XLOOKUP(Tabla2[[#This Row],[PRODUCTO]],Tabla1[PRODUCTO],Tabla1[CODIGO]),"") -> IS-30 | D39: Guantes de seguridad Winsafety T/8 | E39: =IFERROR(VLOOKUP(Tabla2[[#This Row],[CODIGO]],Tabla1[],3,0),"") -> IMPLEMENTOS DE SEGURIDAD | F39: =IFERROR(VLOOKUP(Tabla2[[#This Row],[CODIGO]],Tabla1[],5,0),"") -> ALMACEN TICAPAMPA | G39: =IFERROR(VLOOKUP(Tabla2[[#This Row],[CODIGO]],Tabla1[],6,0),"") -> UNI | H39: =IFERROR(VLOOKUP(Tabla2[[#This Row],[CODIGO]],Tabla1[],10,0),"") -> 99 | I39: 240 | J39: Ingreso a Inventario | K39: =IFERROR(VLOOKUP(Tabla2[[#This Row],[CODIGO]],Tabla1[],11,0),"") -> COMPRA | L39: ACOSTA ROJAS, JOSEPH ALFONSO | M39: ACUACHI LANCHIPA ERNESTO ALONSO | N39: 8 | O39: =Tabla2[[#This Row],[CANTIDAD]]*Tabla2[[#This Row],[PREC. UNITARIO]] -> 1920 | P39: FAC F001-007926 | R39: =Tabla2[[#This Row],[QUIEN RECIBE]]&"-"&TEXT(Tabla2[[#This Row],[FECHA]],"dd/mm/yyyy") -> ACUACHI LANCHIPA ERNESTO ALONSO-10/09/2025
B40: 45910 | C40: =IFERROR(_xlfn.XLOOKUP(Tabla2[[#This Row],[PRODUCTO]],Tabla1[PRODUCTO],Tabla1[CODIGO]),"") -> IS-31 | D40: Chaleco drill T/L | E40: =IFERROR(VLOOKUP(Tabla2[[#This Row],[CODIGO]],Tabla1[],3,0),"") -> IMPLEMENTOS DE SEGURIDAD | F40: =IFERROR(VLOOKUP(Tabla2[[#This Row],[CODIGO]],Tabla1[],5,0),"") -> ALMACEN TICAPAMPA | G40: =IFERROR(VLOOKUP(Tabla2[[#This Row],[CODIGO]],Tabla1[],6,0),"") -> UNI | H40: =IFERROR(VLOOKUP(Tabla2[[#This Row],[CODIGO]],Tabla1[],10,0),"") -> 0 | I40: 20 | J40: Ingreso a Inventario | K40: =IFERROR(VLOOKUP(Tabla2[[#This Row],[CODIGO]],Tabla1[],11,0),"") -> COMPRA | L40: ACOSTA ROJAS, JOSEPH ALFONSO | M40: ACUACHI LANCHIPA ERNESTO ALONSO | N40: 22 | O40: =Tabla2[[#This Row],[CANTIDAD]]*Tabla2[[#This Row],[PREC. UNITARIO]] -> 440 | P40: FAC F001-007926 | R40: =Tabla2[[#This Row],[QUIEN RECIBE]]&"-"&TEXT(Tabla2[[#This Row],[FECHA]],"dd/mm/yyyy") -> ACUACHI LANCHIPA ERNESTO ALONSO-10/09/2025
