Workbook
Name _Datos: 'ASISTENCIA 2 (2)'!$G1:$AK1
Name _Datos: 'ASISTENCIA NOVIEMBRE'!$G1:$AK1
Name _Datos: 'ASISTENCIA OCTUBRE'!$G1:$AK1
Name _Datos: 'TAREO HORAS EXTRAS'!$G1:$AK1
Name _Fechainicial: 'ASISTENCIA 2 (2)'!A$8
Name _Fechainicial: 'ASISTENCIA NOVIEMBRE'!A$8
Name _Fechainicial: 'ASISTENCIA OCTUBRE'!A$8
Name _Fechainicial: 'TAREO HORAS EXTRAS'!A$8
Name _FechaSiguiente: 'ASISTENCIA 2 (2)'!B$8
Name _FechaSiguiente: 'ASISTENCIA NOVIEMBRE'!B$8
Name _FechaSiguiente: 'ASISTENCIA OCTUBRE'!B$8
Name _FechaSiguiente: 'TAREO HORAS EXTRAS'!B$8
Name _HorasExtras: 'ASISTENCIA 2 (2)'!$AO$4
Name _HorasExtras: 'ASISTENCIA NOVIEMBRE'!$AO$4
Name _HorasExtras: 'ASISTENCIA OCTUBRE'!$AO$4
Name _HorasExtras: 'TAREO HORAS EXTRAS'!$AO$4
Name _PorEncimade: 'ASISTENCIA 2 (2)'!$AO$6
Name _PorEncimade: 'ASISTENCIA NOVIEMBRE'!$AO$6
Name _PorEncimade: 'ASISTENCIA OCTUBRE'!$AO$6
Name _PorEncimade: 'TAREO HORAS EXTRAS'!$AO$6
Name LMeses: TMESES[[MES ]]
Name LMeses: TMESES[[MES ]]
Name LMeses: TMESES[[MES ]]
Name LMeses: TMESES[[MES ]]
Name nFestivos: tFestivos4[[#All],[Festivos]]
Name nFestivos: tFestivos468[[#All],[Festivos]]
Name nFestivos: tFestivos46[[#All],[Festivos]]
Name nFestivos: tFestivos[[#All],[Festivos]]

Sheet DATOS GRALES
B1: NOMBRES | C1: DNI
A2: 1 | B2: NAVARRO LOZANO, ANGEL JAROL | C2: 75396402
A3: 2 | B3: JEREMIAS PALOMINO, NORBERTO LEONCIO | C3: 44184914
A4: 3 | B4: LOZANO MALDONADO, HERNAN | C4: 40839932
A5: 4 | B5: PIÑA CHUJANDAMA, KEVIN | C5: 70833343
A6: 5 | B6: MAYTAHUARI ACOSTA, SAMMER AXEL | C6: 48492558
A7: 6 | B7: CORDOVA ANGULO, JUAN | C7: 40889884
A8: 7 | B8: ROJAS SANDOVAL, JAVIER ELOY | C8: 40861767
A9: 8 | B9: CHINO PILCO SIMON | C9: 00487377
A10: 9
A11: 10
A12: 11
A13: 12
A14: 13
A15: 14
A16: 15
A17: 16
A18: 17
A19: 18
A20: 19
A21: 20
... A36: 35

Sheet DATOS GRALES 1
A1: N° | B1: NOMBRES | C1: DNI | D1: CLASE | E1: CARGO | F1: Columna1 | G1: NRO CUENTA BBVA | H1: CCI BBVA | I1: NRO CUENTA BCP | J1: CCI BCP | K1: NRO CUENTA INTERBANK | L1: CCI INTERBANK
A2: 1 | B2: NAVARRO LOZANO, ANGEL JAROL | C2: 75396402 | D2: OBRERO | E2: PEON | G2: 0011-0232-0201496863 | H2: 011-232-000201496863-66 | I2: 48099576706093 | J2: 002480199576706093-22
A3: 2 | B3: JEREMIAS PALOMINO, NORBERTO LEONCIO | C3: 44184914 | D3: OBRERO | E3: PEON | I3: 40594770093053 | J3: 00240519477009305391
A4: 3 | B4: LOZANO MALDONADO, HERNAN | C4: 40839932 | D4: OBRERO | E4: PEON | I4: 48008842398077 | J4: 00248010884239807724
A5: 4 | B5: PIÑA CHUJANDAMA, KEVIN | C5: 70833343 | D5: OBRERO | E5: PEON | I5: 54095302262034 | J5: 00254019530226203437
A6: 5 | B6: MAYTAHUARI ACOSTA, SAMMER AXEL | C6: 48492558 | D6: OBRERO | E6: OPERARIO | F6: CARPINTERO | I6: 54096578590053
A7: 6 | B7: CORDOVA ANGULO, JUAN | C7: 40889884 | D7: OBRERO | E7: PEON | I7: 54009616015070 | J7: 00254010961601507039
A8: 7 | B8: ROJAS SANDOVAL, JAVIER ELOY | C8: 40861767 | D8: OBRERO | E8: OPERARIO/VOLQUETERO | F8: VOLQUETERO | G8: 0011-0814-0282771654 | H8: 011-814-000282771654-15
A9: 8 | B9: CHINO PILCO SIMON | C9: 00487377 | D9: OBRERO | E9: PEON/CHOFER
A10: 9 | B10: ACUACHI LANCHIPA, ERNESTO ALONSO | C10: 41056694 | D10: PERSONAL NO CLAVE | E10: LOGISTICO | K10: 342-3123820927 | L10: 003-342-013123820927-37
A11: 10 | B11: ALEJO CHARCA, DENNYS MIRIAM | C11: 76470794 | D11: PERSONAL CLAVE | E11: ING. CALIDAD | I11: 54074340317053 | J11: 00254017434031705337
A12: 11 | B12: SILVA BORDA, ARLETTE NINOSKA | C12: 71234038 | D12: PERSONAL NO CLAVE | E12: ASIS. ING. | G12: 0011-0814-0277651071 | H12: 011-814-000277651071-17
A13: 12 | B13: ADUVIRE ARGUATA, MARIO ARTURO | C13: 00662471 | D13: OBRERO | E13: MAESTRO OBRA | G13: 0011-0232-0201494909 | H13: 011-232-000201494909-69
A14: 13 | B14: SALAZAR BAZAN, ROCÍO DALILA | C14: 26683098 | D14: PERSONAL CLAVE | E14: RESIDENTE | I14: 54039320324023 | J14: 00254013932032402337
A15: 14 | B15: CHACON ORTIZ, JOSE ANTONIO | C15: 00515241 | D15: OBRERO | E15: OPERARIO | F15: CARPINTERO | G15: 0011-0814-0282789561 | H15: 011-814-000282789561-12
A16: 15 | B16: ORDOÑEZ CONDORI, GILBERTO | C16: 44723682 | D16: OBRERO | E16: PEON | G16: 0011-0814-0282772960 | H16: 011-814-000282772960-15
A17: 16 | B17: GUTARATE SABINO, ADRIEL ANTONY | C17: 78202475 | D17: OBRERO | E17: OPERARIO | F17: fierro | G17: 0011-0814-0282782036 | H17: 011-814-000282782036-12
A18: 17 | B18: QUISPE LIMACHE, ROGELIO | C18: 44758063 | D18: OBRERO | E18: OPERARIO | F18: albañil | G18: 0011-0232-0201496596 | H18: 011-232-000201496596-62
A19: 18 | B19: APASTEGUI GRANDEZ, LUIS ALFREDO | C19: 46906026 | D19: OBRERO | E19: PEON | G19: 0011-0814-0282770674 | H19: 011-814-000282770674-14
A20: 19 | B20: LOZA YAPUCHURA, KENNY GUILLERMO | C20: 72188706 | D20: PERSONA CLAVE | E20: TOPOGRAFO | I20: 54003775270027 | J20: 00254010377527002739
A21: 20 | B21: VILLEGAS, ROGER | D21: OBRERO | E21: OPERARIO MAQU.
A22: 21 | B22: TUANAMA PILCO, CHRIS | C22: 74367601 | D22: OBRERO | E22: PEON | G22: 0011-0814-0281980403 | H22: 011-814-000281980403-16
A23: 22 | B23: CACERES CALACHUA, YEYSON JORGE | C23: 47109805 | D23: OBRERO | E23: OPERARIO | F23: fierro | I23: 42510879044040 | J23: 00242511087904404078
A24: 23 | B24: ACOSTA ROJAS, JOSEPH ALFONSO | C24: 70522697 | D24: PERSONAL CLAVE | E24: REPRESENTANTE
A25: 24 | B25: YEANCARLO | D25: PERSONAL CLAVE | E25: ASIS. ING.
A26: 25 | B26: ESCOBAR PALACIOS, LUIS IVAN | D26: PERSONAL CLAVE | E26: ESP. SEGURIDAD
A27: 26 | B27: MAQUERA QUISPE, LEONIDAS EDWIN | C27: 41018582 | D27: OBRERO | E27: OPERARIO | F27: CARPINTERO | G27: 0011-0814-0267066219 | H27: 011-814-000267066219-12
A28: 27 | B28: MOGROVEJO FALCON, OSMAR ADOLFO | C28: 61415253 | D28: PERSONAL CLAVE | E28: ESP. SEGURIDAD | I28: 21570446064035 | J28: 00221517044606403528
A29: 28 | B29: TACANAHUI CALISAYA, NESTOR | C29: 73536489 | D29: OBRERO | E29: PEÓN | I29: 54099248033061 | J29: 00254019924803306139
A30: 29 | B30: GUTARATE SABINO, RONEL ARTURO | C30: 76338169 | D30: OBRERO | E30: PEÓN | G30: 0011-0814-0283137347 | H30: 011-814-000283137347-13
A31: 30 | B31: ROSAS CHACHAJE, WILSON JHONY | C31: 44365799 | D31: OBRERO | E31: OPERARIO | F31: MAQUINISTA | I31: 54092485355073
A32: 31 | B32: GAMARRA CONDORI, ANGEL | C32: 47099079 | D32: OBRERO | E32: OPERARIO | F32: ALBAÑIL
A33: 32 | B33: QUISPE MAQUERA, MARCO ANTONIO | C33: 74808890 | D33: OBRERO | E33: PEON
A34: 33 | B34: PUMAYALLI LICONA, ENOCH | C34: 45366294 | D34: OBRERO | E34: PEON
A35: 34 | B35: CURMAYARI MANUYAMA, VICTOR RAUL | C35: 00082335 | D35: OBRERO | E35: OPERARIO
A36: 35 | B36: CURMAYARI GUZMAN, JOFFRE | C36: 47846597 | D36: OBRERO | E36: OPERARIO
A37: 36 | B37: OLIVA TARAPA, TOMAS | C37: 01764813 | D37: OBRERO | E37: PEON
A38: 37 | B38: MACHUCA NAVARRO, OMAR JIAN FRANCO | C38: 74208220 | D38: OBRERO | E38: PEON
A39: 38 | B39: ESCOBAR ARBILDO, GOLBER | C39: 45415827 | D39: OBRERO | E39: PEON
A40: 39 | B40: ESCOBAR ARBILDO, RUSBER | C40: 48841643 | D40: OBRERO | E40: PEON
...

Sheet Hoja2

Sheet Hoja1
A4: N° | B4: APELLIDOS Y NOMBRES | C4: DNI | D4: CARGO
A5: 1 | B5: SALAZAR BAZAN, ROCÍO DALILA | C5: =IF(_xlfn.XLOOKUP(Hoja1!B5,DATOS[NOMBRES],DATOS[DNI])="","",_xlfn.XLOOKUP(Hoja1!B5,DATOS[NOMBRES],DATOS[DNI])) -> 26683098 | D5: =IF(_xlfn.XLOOKUP(Tabla6[[#This Row],[APELLIDOS Y NOMBRES]],DATOS[NOMBRES],DATOS[CARGO])="","",_xlfn.XLOOKUP(Tabla6[[#This Row],[APELLIDOS Y NOMBRES]],DATOS[NOMBRES],DATOS[CARGO])) -> RESIDENTE
A6: 2 | B6: ALEJO CHARCA, DENNYS MIRIAM | C6: =IF(_xlfn.XLOOKUP(Hoja1!B6,DATOS[NOMBRES],DATOS[DNI])="","",_xlfn.XLOOKUP(Hoja1!B6,DATOS[NOMBRES],DATOS[DNI])) -> 76470794 | D6: =IF(_xlfn.XLOOKUP(Tabla6[[#This Row],[APELLIDOS Y NOMBRES]],DATOS[NOMBRES],DATOS[CARGO])="","",_xlfn.XLOOKUP(Tabla6[[#This Row],[APELLIDOS Y NOMBRES]],DATOS[NOMBRES],DATOS[CARGO])) -> ING. CALIDAD
A7: 3 | B7: SILVA BORDA, ARLETTE NINOSKA | C7: =IF(_xlfn.XLOOKUP(Hoja1!B7,DATOS[NOMBRES],DATOS[DNI])="","",_xlfn.XLOOKUP(Hoja1!B7,DATOS[NOMBRES],DATOS[DNI])) -> 71234038 | D7: =IF(_xlfn.XLOOKUP(Tabla6[[#This Row],[APELLIDOS Y NOMBRES]],DATOS[NOMBRES],DATOS[CARGO])="","",_xlfn.XLOOKUP(Tabla6[[#This Row],[APELLIDOS Y NOMBRES]],DATOS[NOMBRES],DATOS[CARGO])) -> ASIS. ING.
A8: 4 | B8: ACUACHI LANCHIPA, ERNESTO ALONSO | C8: =IF(_xlfn.XLOOKUP(Hoja1!B8,DATOS[NOMBRES],DATOS[DNI])="","",_xlfn.XLOOKUP(Hoja1!B8,DATOS[NOMBRES],DATOS[DNI])) -> 41056694 | D8: =IF(_xlfn.XLOOKUP(Tabla6[[#This Row],[APELLIDOS Y NOMBRES]],DATOS[NOMBRES],DATOS[CARGO])="","",_xlfn.XLOOKUP(Tabla6[[#This Row],[APELLIDOS Y NOMBRES]],DATOS[NOMBRES],DATOS[CARGO])) -> LOGISTICO
A9: 5 | B9: LOZA YAPUCHURA, KENNY GUILLERMO | C9: =IF(_xlfn.XLOOKUP(Hoja1!B9,DATOS[NOMBRES],DATOS[DNI])="","",_xlfn.XLOOKUP(Hoja1!B9,DATOS[NOMBRES],DATOS[DNI])) -> 72188706 | D9: =IF(_xlfn.XLOOKUP(Tabla6[[#This Row],[APELLIDOS Y NOMBRES]],DATOS[NOMBRES],DATOS[CARGO])="","",_xlfn.XLOOKUP(Tabla6[[#This Row],[APELLIDOS Y NOMBRES]],DATOS[NOMBRES],DATOS[CARGO])) -> TOPOGRAFO
A10: 6 | B10: ADUVIRE ARGUATA, MARIO ARTURO | C10: =IF(_xlfn.XLOOKUP(Hoja1!B10,DATOS[NOMBRES],DATOS[DNI])="","",_xlfn.XLOOKUP(Hoja1!B10,DATOS[NOMBRES],DATOS[DNI])) -> 00662471 | D10: =IF(_xlfn.XLOOKUP(Tabla6[[#This Row],[APELLIDOS Y NOMBRES]],DATOS[NOMBRES],DATOS[CARGO])="","",_xlfn.XLOOKUP(Tabla6[[#This Row],[APELLIDOS Y NOMBRES]],DATOS[NOMBRES],DATOS[CARGO])) -> MAESTRO OBRA
A11: 7 | B11: ACOSTA ROJAS, JOSEPH ALFONSO | C11: =IF(_xlfn.XLOOKUP(Hoja1!B11,DATOS[NOMBRES],DATOS[DNI])="","",_xlfn.XLOOKUP(Hoja1!B11,DATOS[NOMBRES],DATOS[DNI])) -> 70522697 | D11: =IF(_xlfn.XLOOKUP(Tabla6[[#This Row],[APELLIDOS Y NOMBRES]],DATOS[NOMBRES],DATOS[CARGO])="","",_xlfn.XLOOKUP(Tabla6[[#This Row],[APELLIDOS Y NOMBRES]],DATOS[NOMBRES],DATOS[CARGO])) -> REPRESENTANTE
A12: 8 | B12: YEANCARLO | C12: =IF(_xlfn.XLOOKUP(Hoja1!B12,DATOS[NOMBRES],DATOS[DNI])="","",_xlfn.XLOOKUP(Hoja1!B12,DATOS[NOMBRES],DATOS[DNI])) | D12: =IF(_xlfn.XLOOKUP(Tabla6[[#This Row],[APELLIDOS Y NOMBRES]],DATOS[NOMBRES],DATOS[CARGO])="","",_xlfn.XLOOKUP(Tabla6[[#This Row],[APELLIDOS Y NOMBRES]],DATOS[NOMBRES],DATOS[CARGO])) -> ASIS. ING.
A13: 9 | B13: ESCOBAR PALACIOS, LUIS IVAN | C13: =IF(_xlfn.XLOOKUP(Hoja1!B13,DATOS[NOMBRES],DATOS[DNI])="","",_xlfn.XLOOKUP(Hoja1!B13,DATOS[NOMBRES],DATOS[DNI])) | D13: =IF(_xlfn.XLOOKUP(Tabla6[[#This Row],[APELLIDOS Y NOMBRES]],DATOS[NOMBRES],DATOS[CARGO])="","",_xlfn.XLOOKUP(Tabla6[[#This Row],[APELLIDOS Y NOMBRES]],DATOS[NOMBRES],DATOS[CARGO])) -> ESP. SEGURIDAD
A14: 10 | C14: =IF(_xlfn.XLOOKUP(Hoja1!B14,DATOS[NOMBRES],DATOS[DNI])="","",_xlfn.XLOOKUP(Hoja1!B14,DATOS[NOMBRES],DATOS[DNI])) -> #N/A | D14: =IF(_xlfn.XLOOKUP(Tabla6[[#This Row],[APELLIDOS Y NOMBRES]],DATOS[NOMBRES],DATOS[CARGO])="","",_xlfn.XLOOKUP(Tabla6[[#This Row],[APELLIDOS Y NOMBRES]],DATOS[NOMBRES],DATOS[CARGO])) -> #N/A
B16: PERSONAL OBRERO
A17: 1 | B17: MAYTAHUARI ACOSTA, SAMMER AXEL | C17: =IF(_xlfn.XLOOKUP(Hoja1!B17,DATOS[NOMBRES],DATOS[DNI])="","",_xlfn.XLOOKUP(Hoja1!B17,DATOS[NOMBRES],DATOS[DNI])) -> 48492558 | D17: =IF(_xlfn.XLOOKUP(Tabla6[[#This Row],[APELLIDOS Y NOMBRES]],DATOS[NOMBRES],DATOS[CARGO])="","",_xlfn.XLOOKUP(Tabla6[[#This Row],[APELLIDOS Y NOMBRES]],DATOS[NOMBRES],DATOS[CARGO])) -> OPERARIO
A18: 2 | B18: CHACON ORTIZ, JOSE ANTONIO | C18: =IF(_xlfn.XLOOKUP(Hoja1!B18,DATOS[NOMBRES],DATOS[DNI])="","",_xlfn.XLOOKUP(Hoja1!B18,DATOS[NOMBRES],DATOS[DNI])) -> 00515241 | D18: =IF(_xlfn.XLOOKUP(Tabla6[[#This Row],[APELLIDOS Y NOMBRES]],DATOS[NOMBRES],DATOS[CARGO])="","",_xlfn.XLOOKUP(Tabla6[[#This Row],[APELLIDOS Y NOMBRES]],DATOS[NOMBRES],DATOS[CARGO])) -> OPERARIO
A19: 3 | B19: GUTARATE SABINO, ADRIEL ANTONY | C19: =IF(_xlfn.XLOOKUP(Hoja1!B19,DATOS[NOMBRES],DATOS[DNI])="","",_xlfn.XLOOKUP(Hoja1!B19,DATOS[NOMBRES],DATOS[DNI])) -> 78202475 | D19: =IF(_xlfn.XLOOKUP(Tabla6[[#This Row],[APELLIDOS Y NOMBRES]],DATOS[NOMBRES],DATOS[CARGO])="","",_xlfn.XLOOKUP(Tabla6[[#This Row],[APELLIDOS Y NOMBRES]],DATOS[NOMBRES],DATOS[CARGO])) -> OPERARIO
A20: 4 | B20: QUISPE LIMACHE, ROGELIO | C20: =IF(_xlfn.XLOOKUP(Hoja1!B20,DATOS[NOMBRES],DATOS[DNI])="","",_xlfn.XLOOKUP(Hoja1!B20,DATOS[NOMBRES],DATOS[DNI])) -> 44758063 | D20: =IF(_xlfn.XLOOKUP(Tabla6[[#This Row],[APELLIDOS Y NOMBRES]],DATOS[NOMBRES],DATOS[CARGO])="","",_xlfn.XLOOKUP(Tabla6[[#This Row],[APELLIDOS Y NOMBRES]],DATOS[NOMBRES],DATOS[CARGO])) -> OPERARIO
A21: 5 | B21: CACERES CALACHUA, YEYSON JORGE | C21: =IF(_xlfn.XLOOKUP(Hoja1!B21,DATOS[NOMBRES],DATOS[DNI])="","",_xlfn.XLOOKUP(Hoja1!B21,DATOS[NOMBRES],DATOS[DNI])) -> 47109805 | D21: =IF(_xlfn.XLOOKUP(Tabla6[[#This Row],[APELLIDOS Y NOMBRES]],DATOS[NOMBRES],DATOS[CARGO])="","",_xlfn.XLOOKUP(Tabla6[[#This Row],[APELLIDOS Y NOMBRES]],DATOS[NOMBRES],DATOS[CARGO])) -> OPERARIO
A22: 6 | B22: ROJAS SANDOVAL, JAVIER ELOY | C22: =IF(_xlfn.XLOOKUP(Hoja1!B22,DATOS[NOMBRES],DATOS[DNI])="","",_xlfn.XLOOKUP(Hoja1!B22,DATOS[NOMBRES],DATOS[DNI])) -> 40861767 | D22: =IF(_xlfn.XLOOKUP(Tabla6[[#This Row],[APELLIDOS Y NOMBRES]],DATOS[NOMBRES],DATOS[CARGO])="","",_xlfn.XLOOKUP(Tabla6[[#This Row],[APELLIDOS Y NOMBRES]],DATOS[NOMBRES],DATOS[CARGO])) -> OPERARIO/VOLQUETERO
A23: 7 | B23: NAVARRO LOZANO, ANGEL JAROL | C23: =IF(_xlfn.XLOOKUP(Hoja1!B23,DATOS[NOMBRES],DATOS[DNI])="","",_xlfn.XLOOKUP(Hoja1!B23,DATOS[NOMBRES],DATOS[DNI])) -> 75396402 | D23: =IF(_xlfn.XLOOKUP(Tabla6[[#This Row],[APELLIDOS Y NOMBRES]],DATOS[NOMBRES],DATOS[CARGO])="","",_xlfn.XLOOKUP(Tabla6[[#This Row],[APELLIDOS Y NOMBRES]],DATOS[NOMBRES],DATOS[CARGO])) -> PEON
A24: 8 | B24: JEREMIAS PALOMINO, NORBERTO LEONCIO | C24: =IF(_xlfn.XLOOKUP(Hoja1!B24,DATOS[NOMBRES],DATOS[DNI])="","",_xlfn.XLOOKUP(Hoja1!B24,DATOS[NOMBRES],DATOS[DNI])) -> 44184914 | D24: =IF(_xlfn.XLOOKUP(Tabla6[[#This Row],[APELLIDOS Y NOMBRES]],DATOS[NOMBRES],DATOS[CARGO])="","",_xlfn.XLOOKUP(Tabla6[[#This Row],[APELLIDOS Y NOMBRES]],DATOS[NOMBRES],DATOS[CARGO])) -> PEON
A25: 9 | B25: LOZANO MALDONADO, HERNAN | C25: =IF(_xlfn.XLOOKUP(Hoja1!B25,DATOS[NOMBRES],DATOS[DNI])="","",_xlfn.XLOOKUP(Hoja1!B25,DATOS[NOMBRES],DATOS[DNI])) -> 40839932 | D25: =IF(_xlfn.XLOOKUP(Tabla6[[#This Row],[APELLIDOS Y NOMBRES]],DATOS[NOMBRES],DATOS[CARGO])="","",_xlfn.XLOOKUP(Tabla6[[#This Row],[APELLIDOS Y NOMBRES]],DATOS[NOMBRES],DATOS[CARGO])) -> PEON
A26: 10 | B26: PIÑA CHUJANDAMA, KEVIN | C26: =IF(_xlfn.XLOOKUP(Hoja1!B26,DATOS[NOMBRES],DATOS[DNI])="","",_xlfn.XLOOKUP(Hoja1!B26,DATOS[NOMBRES],DATOS[DNI])) -> 70833343 | D26: =IF(_xlfn.XLOOKUP(Tabla6[[#This Row],[APELLIDOS Y NOMBRES]],DATOS[NOMBRES],DATOS[CARGO])="","",_xlfn.XLOOKUP(Tabla6[[#This Row],[APELLIDOS Y NOMBRES]],DATOS[NOMBRES],DATOS[CARGO])) -> PEON
A27: 11 | B27: CORDOVA ANGULO, JUAN | C27: =IF(_xlfn.XLOOKUP(Hoja1!B27,DATOS[NOMBRES],DATOS[DNI])="","",_xlfn.XLOOKUP(Hoja1!B27,DATOS[NOMBRES],DATOS[DNI])) -> 40889884 | D27: =IF(_xlfn.XLOOKUP(Tabla6[[#This Row],[APELLIDOS Y NOMBRES]],DATOS[NOMBRES],DATOS[CARGO])="","",_xlfn.XLOOKUP(Tabla6[[#This Row],[APELLIDOS Y NOMBRES]],DATOS[NOMBRES],DATOS[CARGO])) -> PEON
A28: 12 | B28: ORDOÑEZ CONDORI, GILBERTO | C28: =IF(_xlfn.XLOOKUP(Hoja1!B28,DATOS[NOMBRES],DATOS[DNI])="","",_xlfn.XLOOKUP(Hoja1!B28,DATOS[NOMBRES],DATOS[DNI])) -> 44723682 | D28: =IF(_xlfn.XLOOKUP(Tabla6[[#This Row],[APELLIDOS Y NOMBRES]],DATOS[NOMBRES],DATOS[CARGO])="","",_xlfn.XLOOKUP(Tabla6[[#This Row],[APELLIDOS Y NOMBRES]],DATOS[NOMBRES],DATOS[CARGO])) -> PEON
... A31: 15 | B31: VILLEGAS, ROGER | C31: =IF(_xlfn.XLOOKUP(Hoja1!B31,DATOS[NOMBRES],DATOS[DNI])="","",_xlfn.XLOOKUP(Hoja1!B31,DATOS[NOMBRES],DATOS[DNI])) | D31: =IF(_xlfn.XLOOKUP(Tabla6[[#This Row],[APELLIDOS Y NOMBRES]],DATOS[NOMBRES],DATOS[CARGO])="","",_xlfn.XLOOKUP(Tabla6[[#This Row],[APELLIDOS Y NOMBRES]],DATOS[NOMBRES],DATOS[CARGO])) -> OPERARIO MAQU.
A32: 16 | C32: =IF(_xlfn.XLOOKUP(Hoja1!B32,DATOS[NOMBRES],DATOS[DNI])="","",_xlfn.XLOOKUP(Hoja1!B32,DATOS[NOMBRES],DATOS[DNI])) -> #N/A | D32: =IF(_xlfn.XLOOKUP(Tabla6[[#This Row],[APELLIDOS Y NOMBRES]],DATOS[NOMBRES],DATOS[CARGO])="","",_xlfn.XLOOKUP(Tabla6[[#This Row],[APELLIDOS Y NOMBRES]],DATOS[NOMBRES],DATOS[CARGO])) -> #N/A
A33: 17 | C33: =IF(_xlfn.XLOOKUP(Hoja1!B33,DATOS[NOMBRES],DATOS[DNI])="","",_xlfn.XLOOKUP(Hoja1!B33,DATOS[NOMBRES],DATOS[DNI])) -> #N/A | D33: =IF(_xlfn.XLOOKUP(Tabla6[[#This Row],[APELLIDOS Y NOMBRES]],DATOS[NOMBRES],DATOS[CARGO])="","",_xlfn.XLOOKUP(Tabla6[[#This Row],[APELLIDOS Y NOMBRES]],DATOS[NOMBRES],DATOS[CARGO])) -> #N/A
A34: 18 | C34: =IF(_xlfn.XLOOKUP(Hoja1!B34,DATOS[NOMBRES],DATOS[DNI])="","",_xlfn.XLOOKUP(Hoja1!B34,DATOS[NOMBRES],DATOS[DNI])) -> #N/A | D34: =IF(_xlfn.XLOOKUP(Tabla6[[#This Row],[APELLIDOS Y NOMBRES]],DATOS[NOMBRES],DATOS[CARGO])="","",_xlfn.XLOOKUP(Tabla6[[#This Row],[APELLIDOS Y NOMBRES]],DATOS[NOMBRES],DATOS[CARGO])) -> #N/A
A35: 19 | C35: =IF(_xlfn.XLOOKUP(Hoja1!B35,DATOS[NOMBRES],DATOS[DNI])="","",_xlfn.XLOOKUP(Hoja1!B35,DATOS[NOMBRES],DATOS[DNI])) -> #N/A | D35: =IF(_xlfn.XLOOKUP(Tabla6[[#This Row],[APELLIDOS Y NOMBRES]],DATOS[NOMBRES],DATOS[CARGO])="","",_xlfn.XLOOKUP(Tabla6[[#This Row],[APELLIDOS Y NOMBRES]],DATOS[NOMBRES],DATOS[CARGO])) -> #N/A
A36: 20 | C36: =IF(_xlfn.XLOOKUP(Hoja1!B36,DATOS[NOMBRES],DATOS[DNI])="","",_xlfn.XLOOKUP(Hoja1!B36,DATOS[NOMBRES],DATOS[DNI])) -> #N/A | D36: =IF(_xlfn.XLOOKUP(Tabla6[[#This Row],[APELLIDOS Y NOMBRES]],DATOS[NOMBRES],DATOS[CARGO])="","",_xlfn.XLOOKUP(Tabla6[[#This Row],[APELLIDOS Y NOMBRES]],DATOS[NOMBRES],DATOS[CARGO])) -> #N/A
A37: 21 | C37: =IF(_xlfn.XLOOKUP(Hoja1!B37,DATOS[NOMBRES],DATOS[DNI])="","",_xlfn.XLOOKUP(Hoja1!B37,DATOS[NOMBRES],DATOS[DNI])) -> #N/A | D37: =IF(_xlfn.XLOOKUP(Tabla6[[#This Row],[APELLIDOS Y NOMBRES]],DATOS[NOMBRES],DATOS[CARGO])="","",_xlfn.XLOOKUP(Tabla6[[#This Row],[APELLIDOS Y NOMBRES]],DATOS[NOMBRES],DATOS[CARGO])) -> #N/A
A38: 22 | C38: =IF(_xlfn.XLOOKUP(Hoja1!B38,DATOS[NOMBRES],DATOS[DNI])="","",_xlfn.XLOOKUP(Hoja1!B38,DATOS[NOMBRES],DATOS[DNI])) -> #N/A | D38: =IF(_xlfn.XLOOKUP(Tabla6[[#This Row],[APELLIDOS Y NOMBRES]],DATOS[NOMBRES],DATOS[CARGO])="","",_xlfn.XLOOKUP(Tabla6[[#This Row],[APELLIDOS Y NOMBRES]],DATOS[NOMBRES],DATOS[CARGO])) -> #N/A
A39: 23 | C39: =IF(_xlfn.XLOOKUP(Hoja1!B39,DATOS[NOMBRES],DATOS[DNI])="","",_xlfn.XLOOKUP(Hoja1!B39,DATOS[NOMBRES],DATOS[DNI])) -> #N/A | D39: =IF(_xlfn.XLOOKUP(Tabla6[[#This Row],[APELLIDOS Y NOMBRES]],DATOS[NOMBRES],DATOS[CARGO])="","",_xlfn.XLOOKUP(Tabla6[[#This Row],[APELLIDOS Y NOMBRES]],DATOS[NOMBRES],DATOS[CARGO])) -> #N/A
A40: 24 | C40: =IF(_xlfn.XLOOKUP(Hoja1!B40,DATOS[NOMBRES],DATOS[DNI])="","",_xlfn.XLOOKUP(Hoja1!B40,DATOS[NOMBRES],DATOS[DNI])) -> #N/A | D40: =IF(_xlfn.XLOOKUP(Tabla6[[#This Row],[APELLIDOS Y NOMBRES]],DATOS[NOMBRES],DATOS[CARGO])="","",_xlfn.XLOOKUP(Tabla6[[#This Row],[APELLIDOS Y NOMBRES]],DATOS[NOMBRES],DATOS[CARGO])) -> #N/A
A41: 25 | C41: =IF(_xlfn.XLOOKUP(Hoja1!B41,DATOS[NOMBRES],DATOS[DNI])="","",_xlfn.XLOOKUP(Hoja1!B41,DATOS[NOMBRES],DATOS[DNI])) -> #N/A | D41: =IF(_xlfn.XLOOKUP(Tabla6[[#This Row],[APELLIDOS Y NOMBRES]],DATOS[NOMBRES],DATOS[CARGO])="","",_xlfn.XLOOKUP(Tabla6[[#This Row],[APELLIDOS Y NOMBRES]],DATOS[NOMBRES],DATOS[CARGO])) -> #N/A
A42: 26 | C42: =IF(_xlfn.XLOOKUP(Hoja1!B42,DATOS[NOMBRES],DATOS[DNI])="","",_xlfn.XLOOKUP(Hoja1!B42,DATOS[NOMBRES],DATOS[DNI])) -> #N/A | D42: =IF(_xlfn.XLOOKUP(Tabla6[[#This Row],[APELLIDOS Y NOMBRES]],DATOS[NOMBRES],DATOS[CARGO])="","",_xlfn.XLOOKUP(Tabla6[[#This Row],[APELLIDOS Y NOMBRES]],DATOS[NOMBRES],DATOS[CARGO])) -> #N/A
A43: 27 | C43: =IF(_xlfn.XLOOKUP(Hoja1!B43,DATOS[NOMBRES],DATOS[DNI])="","",_xlfn.XLOOKUP(Hoja1!B43,DATOS[NOMBRES],DATOS[DNI])) -> #N/A | D43: =IF(_xlfn.XLOOKUP(Tabla6[[#This Row],[APELLIDOS Y NOMBRES]],DATOS[NOMBRES],DATOS[CARGO])="","",_xlfn.XLOOKUP(Tabla6[[#This Row],[APELLIDOS Y NOMBRES]],DATOS[NOMBRES],DATOS[CARGO])) -> #N/A
... A46: 30 | C46: =IF(_xlfn.XLOOKUP(Hoja1!B46,DATOS[NOMBRES],DATOS[DNI])="","",_xlfn.XLOOKUP(Hoja1!B46,DATOS[NOMBRES],DATOS[DNI])) -> #N/A | D46: =IF(_xlfn.XLOOKUP(Tabla6[[#This Row],[APELLIDOS Y NOMBRES]],DATOS[NOMBRES],DATOS[CARGO])="","",_xlfn.XLOOKUP(Tabla6[[#This Row],[APELLIDOS Y NOMBRES]],DATOS[NOMBRES],DATOS[CARGO])) -> #N/A

Sheet CONTROL ASISTENCIA
C1: REGISTRO DE CONTROL DE ASISTENCIA
C2: CONSORCIO FORTALEZA E.I.R.L
C3: RUC 20612747271
A4: N° | B4: TRABAJADORES | C4: DNI N° | D4: INGRESO | F4: SALIDA | H4: SOBRE TIEMPO | J4: TOTAL | K4: FIRMA | L4: OBSERVACIONES
B5: APELLIDOS Y NOMBRES | D5: Dia | E5: Hora y Min. | F5: Dia | G5: Hora y Min. | H5: De | I5: A | J5: GENERAL
H6: Hora y Min. | I6: Hora y Min.
A7: 1 | B7: NAVARRO LOZANO, ANGEL JAROL | C7: =IFERROR(VLOOKUP(B7,'DATOS GRALES 1'!$B$2:$C$52,2,0)," ") -> 75396402 | D7: 45909 | F7: 45909
A8: 2 | B8: JEREMIAS PALOMINO, NORBERTO LEONCIO | C8: =IFERROR(VLOOKUP(B8,'DATOS GRALES 1'!$B$2:$C$52,2,0)," ") -> 44184914 | D8: 45909 | F8: 45909
A9: =+A8+1 -> 3 | B9: LOZANO MALDONADO, HERNAN | C9: =IFERROR(VLOOKUP(B9,'DATOS GRALES 1'!$B$2:$C$52,2,0)," ") -> 40839932 | D9: 45909 | F9: 45909
A10: =+A9+1 -> 4 | B10: PIÑA CHUJANDAMA, KEVIN | C10: =IFERROR(VLOOKUP(B10,'DATOS GRALES 1'!$B$2:$C$52,2,0)," ") -> 70833343 | D10: 45909 | F10: 45909
A11: =+A10+1 -> 5 | B11: MAYTAHUARI ACOSTA, SAMMER AXEL | C11: =IFERROR(VLOOKUP(B11,'DATOS GRALES 1'!$B$2:$C$52,2,0)," ") -> 48492558 | D11: 45909 | F11: 45909
A12: =+A11+1 -> 6 | B12: CORDOVA ANGULO, JUAN | C12: =IFERROR(VLOOKUP(B12,'DATOS GRALES 1'!$B$2:$C$52,2,0)," ") -> 40889884 | D12: 45909 | F12: 45909
A13: =+A12+1 -> 7 | B13: ROJAS SANDOVAL, JAVIER ELOY | C13: =IFERROR(VLOOKUP(B13,'DATOS GRALES 1'!$B$2:$C$52,2,0)," ") -> 40861767 | D13: 45909 | F13: 45909
A14: =+A13+1 -> 8 | B14: CHINO PILCO SIMON | C14: =IFERROR(VLOOKUP(B14,'DATOS GRALES 1'!$B$2:$C$52,2,0)," ") -> 00487377 | D14: 45909 | F14: 45909
A15: =+A14+1 -> 9 | B15: NAVARRO LOZANO, ANGEL JAROL | C15: =IFERROR(VLOOKUP(B15,'DATOS GRALES 1'!$B$2:$C$52,2,0)," ") -> 75396402 | D15: 45910 | F15: 45910
A16: =+A15+1 -> 10 | B16: JEREMIAS PALOMINO, NORBERTO LEONCIO | C16: =IFERROR(VLOOKUP(B16,'DATOS GRALES 1'!$B$2:$C$52,2,0)," ") -> 44184914 | D16: 45910 | F16: 45910
A17: =+A16+1 -> 11 | B17: LOZANO MALDONADO, HERNAN | C17: =IFERROR(VLOOKUP(B17,'DATOS GRALES 1'!$B$2:$C$52,2,0)," ") -> 40839932 | D17: 45910 | F17: 45910
A18: =+A17+1 -> 12 | B18: PIÑA CHUJANDAMA, KEVIN | C18: =IFERROR(VLOOKUP(B18,'DATOS GRALES 1'!$B$2:$C$52,2,0)," ") -> 70833343 | D18: 45910 | F18: 45910
A19: =+A18+1 -> 13 | B19: MAYTAHUARI ACOSTA, SAMMER AXEL | C19: =IFERROR(VLOOKUP(B19,'DATOS GRALES 1'!$B$2:$C$52,2,0)," ") -> 48492558 | D19: 45910 | F19: 45910
A20: =+A19+1 -> 14 | B20: CORDOVA ANGULO, JUAN | C20: =IFERROR(VLOOKUP(B20,'DATOS GRALES 1'!$B$2:$C$52,2,0)," ") -> 40889884 | D20: 45910 | F20: 45910
A21: 15 | B21: ROJAS SANDOVAL, JAVIER ELOY | C21: =IFERROR(VLOOKUP(B21,'DATOS GRALES 1'!$B$2:$C$52,2,0)," ") -> 40861767 | D21: 45910 | F21: 45910
A22: =+A21+1 -> 16 | B22: CHINO PILCO SIMON | C22: =IFERROR(VLOOKUP(B22,'DATOS GRALES 1'!$B$2:$C$52,2,0)," ") -> 00487377 | D22: 45910 | F22: 45910
A23: 17 | B23: NAVARRO LOZANO, ANGEL JAROL | C23: =IFERROR(VLOOKUP(B23,'DATOS GRALES 1'!$B$2:$C$52,2,0)," ") -> 75396402 | D23: 45911 | F23: 45911
A24: 18 | B24: JEREMIAS PALOMINO, NORBERTO LEONCIO | C24: =IFERROR(VLOOKUP(B24,'DATOS GRALES 1'!$B$2:$C$52,2,0)," ") -> 44184914 | D24: 45911 | F24: 45911
A25: 19 | B25: LOZANO MALDONADO, HERNAN | C25: =IFERROR(VLOOKUP(B25,'DATOS GRALES 1'!$B$2:$C$52,2,0)," ") -> 40839932 | D25: 45911 | F25: 45911
A26: 20 | B26: PIÑA CHUJANDAMA, KEVIN | C26: =IFERROR(VLOOKUP(B26,'DATOS GRALES 1'!$B$2:$C$52,2,0)," ") -> 70833343 | D26: 45911 | F26: 45911
A27: 21 | B27: MAYTAHUARI ACOSTA, SAMMER AXEL | C27: =IFERROR(VLOOKUP(B27,'DATOS GRALES 1'!$B$2:$C$52,2,0)," ") -> 48492558 | D27: 45911 | F27: 45911
A28: 22 | B28: CORDOVA ANGULO, JUAN | C28: =IFERROR(VLOOKUP(B28,'DATOS GRALES 1'!$B$2:$C$52,2,0)," ") -> 40889884 | D28: 45911 | F28: 45911
A29: 23 | B29: ROJAS SANDOVAL, JAVIER ELOY | C29: =IFERROR(VLOOKUP(B29,'DATOS GRALES 1'!$B$2:$C$52,2,0)," ") -> 40861767 | D29: 45911 | F29: 45911
A30: =+A29+1 -> 24 | B30: NAVARRO LOZANO, ANGEL JAROL | C30: =IFERROR(VLOOKUP(B30,'DATOS GRALES 1'!$B$2:$C$52,2,0)," ") -> 75396402 | D30: 45912 | F30: 45912
A31: =+A30+1 -> 25 | B31: JEREMIAS PALOMINO, NORBERTO LEONCIO | C31: =IFERROR(VLOOKUP(B31,'DATOS GRALES 1'!$B$2:$C$52,2,0)," ") -> 44184914 | D31: 45912 | F31: 45912
A32: =+A31+1 -> 26 | B32: LOZANO MALDONADO, HERNAN | C32: =IFERROR(VLOOKUP(B32,'DATOS GRALES 1'!$B$2:$C$52,2,0)," ") -> 40839932 | D32: 45912 | F32: 45912
A33: 27 | B33: PIÑA CHUJANDAMA, KEVIN | C33: =IFERROR(VLOOKUP(B33,'DATOS GRALES 1'!$B$2:$C$52,2,0)," ") -> 70833343 | D33: 45912 | F33: 45912
A34: 28 | B34: MAYTAHUARI ACOSTA, SAMMER AXEL | C34: =IFERROR(VLOOKUP(B34,'DATOS GRALES 1'!$B$2:$C$52,2,0)," ") -> 48492558 | D34: 45912 | F34: 45912
A35: 29 | B35: CORDOVA ANGULO, JUAN | C35: =IFERROR(VLOOKUP(B35,'DATOS GRALES 1'!$B$2:$C$52,2,0)," ") -> 40889884 | D35: 45912 | F35: 45912
A36: 30 | B36: ROJAS SANDOVAL, JAVIER ELOY | C36: =IFERROR(VLOOKUP(B36,'DATOS GRALES 1'!$B$2:$C$52,2,0)," ") -> 40861767 | D36: 45912 | F36: 45912
A37: =+A36+1 -> 31 | B37: NAVARRO LOZANO, ANGEL JAROL | C37: =IFERROR(VLOOKUP(B37,'DATOS GRALES 1'!$B$2:$C$52,2,0)," ") -> 75396402 | D37: 45913 | F37: 45913
A38: =+A37+1 -> 32 | B38: JEREMIAS PALOMINO, NORBERTO LEONCIO | C38: =IFERROR(VLOOKUP(B38,'DATOS GRALES 1'!$B$2:$C$52,2,0)," ") -> 44184914 | D38: 45913 | F38: 45913
A39: =+A38+1 -> 33 | B39: LOZANO MALDONADO, HERNAN | C39: =IFERROR(VLOOKUP(B39,'DATOS GRALES 1'!$B$2:$C$52,2,0)," ") -> 40839932 | D39: 45913 | F39: 45913
A40: 34 | B40: PIÑA CHUJANDAMA, KEVIN | C40: =IFERROR(VLOOKUP(B40,'DATOS GRALES 1'!$B$2:$C$52,2,0)," ") -> 70833343 | D40: 45913 | F40: 45913
...

Sheet FORMATO
C1: REGISTRO DE CONTROL DE ASISTENCIA
C2: CONSORCIO FORTALEZA E.I.R.L | O2: FECHA | P2: 45968
C3: RUC 20612747271
A4: N° | B4: TRABAJADORES | C4: DNI N° | D4: INGRESO | F4: SALIDA | H4: SOBRE TIEMPO | J4: TOTAL | K4: FIRMA | L4: OBSERVACIONES
B5: APELLIDOS Y NOMBRES | D5: Dia | E5: Hora y Min. | F5: Dia | G5: Hora y Min. | H5: De | I5: A | J5: GENERAL
H6: Hora y Min. | I6: Hora y Min.
A7: {=_xlfn.SEQUENCE(COUNTA(B:B))} -> 1 | B7: NAVARRO LOZANO, ANGEL JAROL | C7: =IFERROR(IF(_xlfn.XLOOKUP(B7,DATOS[NOMBRES],DATOS[DNI])=0,"",_xlfn.XLOOKUP(B7,DATOS[NOMBRES],DATOS[DNI])),"") -> 75396402 | D7: =IF(B7="","",$P$2) -> 45968 | F7: =IF(B7="","",$P$2) -> 45968
A8: 2 | B8: JEREMIAS PALOMINO, NORBERTO LEONCIO | C8: =IFERROR(IF(_xlfn.XLOOKUP(B8,DATOS[NOMBRES],DATOS[DNI])=0,"",_xlfn.XLOOKUP(B8,DATOS[NOMBRES],DATOS[DNI])),"") -> 44184914 | D8: =IF(B8="","",$P$2) -> 45968 | F8: =IF(B8="","",$P$2) -> 45968
A9: 3 | B9: LOZANO MALDONADO, HERNAN | C9: =IFERROR(IF(_xlfn.XLOOKUP(B9,DATOS[NOMBRES],DATOS[DNI])=0,"",_xlfn.XLOOKUP(B9,DATOS[NOMBRES],DATOS[DNI])),"") -> 40839932 | D9: =IF(B9="","",$P$2) -> 45968 | F9: =IF(B9="","",$P$2) -> 45968
A10: 4 | B10: PIÑA CHUJANDAMA, KEVIN | C10: =IFERROR(IF(_xlfn.XLOOKUP(B10,DATOS[NOMBRES],DATOS[DNI])=0,"",_xlfn.XLOOKUP(B10,DATOS[NOMBRES],DATOS[DNI])),"") -> 70833343 | D10: =IF(B10="","",$P$2) -> 45968 | F10: =IF(B10="","",$P$2) -> 45968
A11: 5 | B11: MAYTAHUARI ACOSTA, SAMMER AXEL | C11: =IFERROR(IF(_xlfn.XLOOKUP(B11,DATOS[NOMBRES],DATOS[DNI])=0,"",_xlfn.XLOOKUP(B11,DATOS[NOMBRES],DATOS[DNI])),"") -> 48492558 | D11: =IF(B11="","",$P$2) -> 45968 | F11: =IF(B11="","",$P$2) -> 45968
A12: 6 | B12: CORDOVA ANGULO, JUAN | C12: =IFERROR(IF(_xlfn.XLOOKUP(B12,DATOS[NOMBRES],DATOS[DNI])=0,"",_xlfn.XLOOKUP(B12,DATOS[NOMBRES],DATOS[DNI])),"") -> 40889884 | D12: =IF(B12="","",$P$2) -> 45968 | F12: =IF(B12="","",$P$2) -> 45968
A13: 7 | B13: CHACON ORTIZ, JOSE ANTONIO | C13: =IFERROR(IF(_xlfn.XLOOKUP(B13,DATOS[NOMBRES],DATOS[DNI])=0,"",_xlfn.XLOOKUP(B13,DATOS[NOMBRES],DATOS[DNI])),"") -> 00515241 | D13: =IF(B13="","",$P$2) -> 45968 | F13: =IF(B13="","",$P$2) -> 45968
A14: 8 | B14: ORDOÑEZ CONDORI, GILBERTO | C14: =IFERROR(IF(_xlfn.XLOOKUP(B14,DATOS[NOMBRES],DATOS[DNI])=0,"",_xlfn.XLOOKUP(B14,DATOS[NOMBRES],DATOS[DNI])),"") -> 44723682 | D14: =IF(B14="","",$P$2) -> 45968 | F14: =IF(B14="","",$P$2) -> 45968
A15: 9 | B15: GUTARATE SABINO, ADRIEL ANTONY | C15: =IFERROR(IF(_xlfn.XLOOKUP(B15,DATOS[NOMBRES],DATOS[DNI])=0,"",_xlfn.XLOOKUP(B15,DATOS[NOMBRES],DATOS[DNI])),"") -> 78202475 | D15: =IF(B15="","",$P$2) -> 45968 | F15: =IF(B15="","",$P$2) -> 45968
A16: 10 | B16: CACERES CALACHUA, YEYSON JORGE | C16: =IFERROR(IF(_xlfn.XLOOKUP(B16,DATOS[NOMBRES],DATOS[DNI])=0,"",_xlfn.XLOOKUP(B16,DATOS[NOMBRES],DATOS[DNI])),"") -> 47109805 | D16: =IF(B16="","",$P$2) -> 45968 | F16: =IF(B16="","",$P$2) -> 45968
A17: 11 | B17: MAQUERA QUISPE, LEONIDAS EDWIN | C17: =IFERROR(IF(_xlfn.XLOOKUP(B17,DATOS[NOMBRES],DATOS[DNI])=0,"",_xlfn.XLOOKUP(B17,DATOS[NOMBRES],DATOS[DNI])),"") -> 41018582 | D17: =IF(B17="","",$P$2) -> 45968 | F17: =IF(B17="","",$P$2) -> 45968
A18: 12 | B18: TACANAHUI CALISAYA, NESTOR | C18: =IFERROR(IF(_xlfn.XLOOKUP(B18,DATOS[NOMBRES],DATOS[DNI])=0,"",_xlfn.XLOOKUP(B18,DATOS[NOMBRES],DATOS[DNI])),"") -> 73536489 | D18: =IF(B18="","",$P$2) -> 45968 | F18: =IF(B18="","",$P$2) -> 45968
A19: 13 | B19: ROSAS CHACHAJE, WILSON JHONY | C19: =IFERROR(IF(_xlfn.XLOOKUP(B19,DATOS[NOMBRES],DATOS[DNI])=0,"",_xlfn.XLOOKUP(B19,DATOS[NOMBRES],DATOS[DNI])),"") -> 44365799 | D19: =IF(B19="","",$P$2) -> 45968 | F19: =IF(B19="","",$P$2) -> 45968
... A33: 27 | B33: CARMELO MONTEJO, OSCAR CESAR | C33: =IFERROR(IF(_xlfn.XLOOKUP(B33,DATOS[NOMBRES],DATOS[DNI])=0,"",_xlfn.XLOOKUP(B33,DATOS[NOMBRES],DATOS[DNI])),"") -> 73009722 | D33: =IF(B33="","",$P$2) -> 45968 | F33: =IF(B33="","",$P$2) -> 45968
A34: 28 | C34: =IFERROR(IF(_xlfn.XLOOKUP(B34,DATOS[NOMBRES],DATOS[DNI])=0,"",_xlfn.XLOOKUP(B34,DATOS[NOMBRES],DATOS[DNI])),"") | D34: =IF(B34="","",$P$2) | F34: =IF(B34="","",$P$2)
A35: 29 | C35: =IFERROR(IF(_xlfn.XLOOKUP(B35,DATOS[NOMBRES],DATOS[DNI])=0,"",_xlfn.XLOOKUP(B35,DATOS[NOMBRES],DATOS[DNI])),"") | D35: =IF(B35="","",$P$2) | F35: =IF(B35="","",$P$2)
C36: =IFERROR(IF(_xlfn.XLOOKUP(B36,DATOS[NOMBRES],DATOS[DNI])=0,"",_xlfn.XLOOKUP(B36,DATOS[NOMBRES],DATOS[DNI])),"") | D36: =IF(B36="","",$P$2) | F36: =IF(B36="","",$P$2)
C37: =IFERROR(IF(_xlfn.XLOOKUP(B37,DATOS[NOMBRES],DATOS[DNI])=0,"",_xlfn.XLOOKUP(B37,DATOS[NOMBRES],DATOS[DNI])),"") | D37: =IF(B37="","",$P$2) | F37: =IF(B37="","",$P$2)
C38: =IFERROR(IF(_xlfn.XLOOKUP(B38,DATOS[NOMBRES],DATOS[DNI])=0,"",_xlfn.XLOOKUP(B38,DATOS[NOMBRES],DATOS[DNI])),"") | D38: =IF(B38="","",$P$2) | F38: =IF(B38="","",$P$2)

Sheet TAREO HORAS EXTRAS
C1: Registro y Control de Horas Trabajadas
C4: Escoja Mes: | E4: Setiembre | H4: ← Item Lista Desplegable | N4: Empresa: | Q4: FSA Constructora | V4: El Periodo Comprende | AD4: Mes: | AG4: Año: | AM4: Horas Extras: | AO4: SI
N5: Obra: | Q5: Ticapampa | V5: ="Desde: "&TEXT(DATE(E6,MONTH(E4&1),1),"mmm-dd-yy")&" Hasta "&TEXT(EOMONTH(DATE(E6,MONTH(E4&1),1),0),"mmm-dd-yy") -> Desde: Set-01-25 Hasta Set-30-25 | AD5: =E4 -> Setiembre | AG5: =E6 -> 2025
C6: Escoja Año: | E6: 2025 | H6: ← Introduzca manualmente | N6: Encargado: | Q6: Ernesto Acuachi | AM6: Por Encima de: | AO6: 8
G8: =DATE(E6,MONTH(E4&1),1) -> 45901 | H8: =G8+1 -> 45902 | I8: =H8+1 -> 45903 | J8: =I8+1 -> 45904 | K8: =J8+1 -> 45905 | L8: =K8+1 -> 45906 | M8: =L8+1 -> 45907 | N8: =M8+1 -> 45908 | O8: =N8+1 -> 45909 | ... AK8: =AJ8+1 -> 45931
AQ9: Festivos
AQ10: 45658
AQ11: 45866
AQ12: 45867
C13: Apellido y Nombres | E13: Cargo | G13: =PROPER(LEFT(TEXT(G8,"dddd"),3)) -> Lun | H13: =PROPER(LEFT(TEXT(H8,"dddd"),3)) -> Mar | I13: =PROPER(LEFT(TEXT(I8,"dddd"),3)) -> Mié | J13: =PROPER(LEFT(TEXT(J8,"dddd"),3)) -> Jue | K13: =PROPER(LEFT(TEXT(K8,"dddd"),3)) -> Vie | L13: =PROPER(LEFT(TEXT(L8,"dddd"),3)) -> Sáb | M13: =PROPER(LEFT(TEXT(M8,"dddd"),3)) -> Dom | N13: =PROPER(LEFT(TEXT(N8,"dddd"),3)) -> Lun | ... AK13: =PROPER(LEFT(TEXT(AK8,"dddd"),3)) -> Mié | AM13: Horas Normales | AO13: Horas Extras | AQ13: 45962
AQ14: 46016
AM15: {=_xlfn.SWITCH(_HorasExtras, "Si",SUMPRODUCT(IF(_Datos<=_PorEncimade,_Datos,_PorEncimade),(WEEKDAY($G$8:$AK$8,2)<=6)*1,NOT(ISNUMBER(MATCH($G$8:$AK$8,nFestivos,0)))*1), "No",SUMPRODUCT(_Datos,(WEEKDAY($G$8:$AK$8,2)<=5)*1,NOT(ISNUMBER(MATCH($G$8:$AK$8,nFestivos,0)))*1))} -> 0 | AO15: {=_xlfn.SWITCH(_HorasExtras, "Si",SUMPRODUCT(IF(_Datos>_PorEncimade,_Datos-_PorEncimade,0),(WEEKDAY($G$8:$AK$8,2)<=6)*1,NOT(ISNUMBER(MATCH($G$8:$AK$8,nFestivos,0)))*1), "No",0)} -> 0 | AQ15: 46022
AM16: {=_xlfn.SWITCH(_HorasExtras, "Si",SUMPRODUCT(IF(_Datos<=_PorEncimade,_Datos,_PorEncimade),(WEEKDAY($G$8:$AK$8,2)<=5)*1,NOT(ISNUMBER(MATCH($G$8:$AK$8,nFestivos,0)))*1), "No",SUMPRODUCT(_Datos,(WEEKDAY($G$8:$AK$8,2)<=5)*1,NOT(ISNUMBER(MATCH($G$8:$AK$8,nFestivos,0)))*1))} -> 0 | AO16: {=_xlfn.SWITCH(_HorasExtras, "Si",SUMPRODUCT(IF(_Datos>_PorEncimade,_Datos-_PorEncimade,0),(WEEKDAY($G$8:$AK$8,2)<=6)*1,NOT(ISNUMBER(MATCH($G$8:$AK$8,nFestivos,0)))*1), "No",0)} -> 0
AM17: {=_xlfn.SWITCH(_HorasExtras, "Si",SUMPRODUCT(IF(_Datos<=_PorEncimade,_Datos,_PorEncimade),(WEEKDAY($G$8:$AK$8,2)<=5)*1,NOT(ISNUMBER(MATCH($G$8:$AK$8,nFestivos,0)))*1), "No",SUMPRODUCT(_Datos,(WEEKDAY($G$8:$AK$8,2)<=5)*1,NOT(ISNUMBER(MATCH($G$8:$AK$8,nFestivos,0)))*1))} -> 0 | AO17: {=_xlfn.SWITCH(_HorasExtras, "Si",SUMPRODUCT(IF(_Datos>_PorEncimade,_Datos-_PorEncimade,0),(WEEKDAY($G$8:$AK$8,2)<=6)*1,NOT(ISNUMBER(MATCH($G$8:$AK$8,nFestivos,0)))*1), "No",0)} -> 0
AM18: {=_xlfn.SWITCH(_HorasExtras, "Si",SUMPRODUCT(IF(_Datos<=_PorEncimade,_Datos,_PorEncimade),(WEEKDAY($G$8:$AK$8,2)<=5)*1,NOT(ISNUMBER(MATCH($G$8:$AK$8,nFestivos,0)))*1), "No",SUMPRODUCT(_Datos,(WEEKDAY($G$8:$AK$8,2)<=5)*1,NOT(ISNUMBER(MATCH($G$8:$AK$8,nFestivos,0)))*1))} -> 0 | AO18: {=_xlfn.SWITCH(_HorasExtras, "Si",SUMPRODUCT(IF(_Datos>_PorEncimade,_Datos-_PorEncimade,0),(WEEKDAY($G$8:$AK$8,2)<=6)*1,NOT(ISNUMBER(MATCH($G$8:$AK$8,nFestivos,0)))*1), "No",0)} -> 0
AM19: {=_xlfn.SWITCH(_HorasExtras, "Si",SUMPRODUCT(IF(_Datos<=_PorEncimade,_Datos,_PorEncimade),(WEEKDAY($G$8:$AK$8,2)<=5)*1,NOT(ISNUMBER(MATCH($G$8:$AK$8,nFestivos,0)))*1), "No",SUMPRODUCT(_Datos,(WEEKDAY($G$8:$AK$8,2)<=5)*1,NOT(ISNUMBER(MATCH($G$8:$AK$8,nFestivos,0)))*1))} -> 0 | AO19: {=_xlfn.SWITCH(_HorasExtras, "Si",SUMPRODUCT(IF(_Datos>_PorEncimade,_Datos-_PorEncimade,0),(WEEKDAY($G$8:$AK$8,2)<=6)*1,NOT(ISNUMBER(MATCH($G$8:$AK$8,nFestivos,0)))*1), "No",0)} -> 0
AM20: {=_xlfn.SWITCH(_HorasExtras, "Si",SUMPRODUCT(IF(_Datos<=_PorEncimade,_Datos,_PorEncimade),(WEEKDAY($G$8:$AK$8,2)<=5)*1,NOT(ISNUMBER(MATCH($G$8:$AK$8,nFestivos,0)))*1), "No",SUMPRODUCT(_Datos,(WEEKDAY($G$8:$AK$8,2)<=5)*1,NOT(ISNUMBER(MATCH($G$8:$AK$8,nFestivos,0)))*1))} -> 0 | AO20: {=_xlfn.SWITCH(_HorasExtras, "Si",SUMPRODUCT(IF(_Datos>_PorEncimade,_Datos-_PorEncimade,0),(WEEKDAY($G$8:$AK$8,2)<=6)*1,NOT(ISNUMBER(MATCH($G$8:$AK$8,nFestivos,0)))*1), "No",0)} -> 0
AM21: {=_xlfn.SWITCH(_HorasExtras, "Si",SUMPRODUCT(IF(_Datos<=_PorEncimade,_Datos,_PorEncimade),(WEEKDAY($G$8:$AK$8,2)<=5)*1,NOT(ISNUMBER(MATCH($G$8:$AK$8,nFestivos,0)))*1), "No",SUMPRODUCT(_Datos,(WEEKDAY($G$8:$AK$8,2)<=5)*1,NOT(ISNUMBER(MATCH($G$8:$AK$8,nFestivos,0)))*1))} -> 0 | AO21: {=_xlfn.SWITCH(_HorasExtras, "Si",SUMPRODUCT(IF(_Datos>_PorEncimade,_Datos-_PorEncimade,0),(WEEKDAY($G$8:$AK$8,2)<=6)*1,NOT(ISNUMBER(MATCH($G$8:$AK$8,nFestivos,0)))*1), "No",0)} -> 0
AM22: {=_xlfn.SWITCH(_HorasExtras, "Si",SUMPRODUCT(IF(_Datos<=_PorEncimade,_Datos,_PorEncimade),(WEEKDAY($G$8:$AK$8,2)<=5)*1,NOT(ISNUMBER(MATCH($G$8:$AK$8,nFestivos,0)))*1), "No",SUMPRODUCT(_Datos,(WEEKDAY($G$8:$AK$8,2)<=5)*1,NOT(ISNUMBER(MATCH($G$8:$AK$8,nFestivos,0)))*1))} -> 0 | AO22: {=_xlfn.SWITCH(_HorasExtras, "Si",SUMPRODUCT(IF(_Datos>_PorEncimade,_Datos-_PorEncimade,0),(WEEKDAY($G$8:$AK$8,2)<=6)*1,NOT(ISNUMBER(MATCH($G$8:$AK$8,nFestivos,0)))*1), "No",0)} -> 0
AM23: {=_xlfn.SWITCH(_HorasExtras, "Si",SUMPRODUCT(IF(_Datos<=_PorEncimade,_Datos,_PorEncimade),(WEEKDAY($G$8:$AK$8,2)<=5)*1,NOT(ISNUMBER(MATCH($G$8:$AK$8,nFestivos,0)))*1), "No",SUMPRODUCT(_Datos,(WEEKDAY($G$8:$AK$8,2)<=5)*1,NOT(ISNUMBER(MATCH($G$8:$AK$8,nFestivos,0)))*1))} -> 0 | AO23: {=_xlfn.SWITCH(_HorasExtras, "Si",SUMPRODUCT(IF(_Datos>_PorEncimade,_Datos-_PorEncimade,0),(WEEKDAY($G$8:$AK$8,2)<=6)*1,NOT(ISNUMBER(MATCH($G$8:$AK$8,nFestivos,0)))*1), "No",0)} -> 0
AM24: {=_xlfn.SWITCH(_HorasExtras, "Si",SUMPRODUCT(IF(_Datos<=_PorEncimade,_Datos,_PorEncimade),(WEEKDAY($G$8:$AK$8,2)<=5)*1,NOT(ISNUMBER(MATCH($G$8:$AK$8,nFestivos,0)))*1), "No",SUMPRODUCT(_Datos,(WEEKDAY($G$8:$AK$8,2)<=5)*1,NOT(ISNUMBER(MATCH($G$8:$AK$8,nFestivos,0)))*1))} -> 0 | AO24: {=_xlfn.SWITCH(_HorasExtras, "Si",SUMPRODUCT(IF(_Datos>_PorEncimade,_Datos-_PorEncimade,0),(WEEKDAY($G$8:$AK$8,2)<=6)*1,NOT(ISNUMBER(MATCH($G$8:$AK$8,nFestivos,0)))*1), "No",0)} -> 0
AM25: {=_xlfn.SWITCH(_HorasExtras, "Si",SUMPRODUCT(IF(_Datos<=_PorEncimade,_Datos,_PorEncimade),(WEEKDAY($G$8:$AK$8,2)<=5)*1,NOT(ISNUMBER(MATCH($G$8:$AK$8,nFestivos,0)))*1), "No",SUMPRODUCT(_Datos,(WEEKDAY($G$8:$AK$8,2)<=5)*1,NOT(ISNUMBER(MATCH($G$8:$AK$8,nFestivos,0)))*1))} -> 0 | AO25: {=_xlfn.SWITCH(_HorasExtras, "Si",SUMPRODUCT(IF(_Datos>_PorEncimade,_Datos-_PorEncimade,0),(WEEKDAY($G$8:$AK$8,2)<=6)*1,NOT(ISNUMBER(MATCH($G$8:$AK$8,nFestivos,0)))*1), "No",0)} -> 0
AM26: {=_xlfn.SWITCH(_HorasExtras, "Si",SUMPRODUCT(IF(_Datos<=_PorEncimade,_Datos,_PorEncimade),(WEEKDAY($G$8:$AK$8,2)<=5)*1,NOT(ISNUMBER(MATCH($G$8:$AK$8,nFestivos,0)))*1), "No",SUMPRODUCT(_Datos,(WEEKDAY($G$8:$AK$8,2)<=5)*1,NOT(ISNUMBER(MATCH($G$8:$AK$8,nFestivos,0)))*1))} -> 0 | AO26: {=_xlfn.SWITCH(_HorasExtras, "Si",SUMPRODUCT(IF(_Datos>_PorEncimade,_Datos-_PorEncimade,0),(WEEKDAY($G$8:$AK$8,2)<=6)*1,NOT(ISNUMBER(MATCH($G$8:$AK$8,nFestivos,0)))*1), "No",0)} -> 0
AM27: {=_xlfn.SWITCH(_HorasExtras, "Si",SUMPRODUCT(IF(_Datos<=_PorEncimade,_Datos,_PorEncimade),(WEEKDAY($G$8:$AK$8,2)<=5)*1,NOT(ISNUMBER(MATCH($G$8:$AK$8,nFestivos,0)))*1), "No",SUMPRODUCT(_Datos,(WEEKDAY($G$8:$AK$8,2)<=5)*1,NOT(ISNUMBER(MATCH($G$8:$AK$8,nFestivos,0)))*1))} -> 0 | AO27: {=_xlfn.SWITCH(_HorasExtras, "Si",SUMPRODUCT(IF(_Datos>_PorEncimade,_Datos-_PorEncimade,0),(WEEKDAY($G$8:$AK$8,2)<=6)*1,NOT(ISNUMBER(MATCH($G$8:$AK$8,nFestivos,0)))*1), "No",0)} -> 0
... AM51: {=_xlfn.SWITCH(_HorasExtras, "Si",SUMPRODUCT(IF(_Datos<=_PorEncimade,_Datos,_PorEncimade),(WEEKDAY($G$8:$AK$8,2)<=5)*1,NOT(ISNUMBER(MATCH($G$8:$AK$8,nFestivos,0)))*1), "No",SUMPRODUCT(_Datos,(WEEKDAY($G$8:$AK$8,2)<=5)*1,NOT(ISNUMBER(MATCH($G$8:$AK$8,nFestivos,0)))*1))} -> 0 | AO51: {=_xlfn.SWITCH(_HorasExtras, "Si",SUMPRODUCT(IF(_Datos>_PorEncimade,_Datos-_PorEncimade,0),(WEEKDAY($G$8:$AK$8,2)<=6)*1,NOT(ISNUMBER(MATCH($G$8:$AK$8,nFestivos,0)))*1), "No",0)} -> 0

Sheet formulas
A3: 1 | B3: {=WEEKDAY(_Fechainicial,2)>WEEKDAY(_FechaSiguiente,2)} -> #NAME? | C3: colocar una linea de lunes a domingo en formato condicional
A4: 2 | B4: {=MONTH(_Fechainicial)<>MONTH($E$4&1)} -> #NAME? | C4: apaga los dias que no se utlizan de acuerdo al mes
A5: 3 | B5: {=MONTH(_Fechainicial)=MONTH($E$4&1)} -> #NAME? | C5: para colocar un color de relleno hasta donde este los dias activos
B6: {=OR(WEEKDAY(_Fechainicial,2)>=7,ISNUMBER(MATCH(_Fechainicial,nFestivo,0)),MONTH(_Fechainicial)<>MONTH($E$4&1))} -> #NAME? | C6: colocar una trama en los dias festivos y domingos
B7: =CAMBIAR(_HorasExtras; | N7: para hallar horas normales = 8horas
B8: Si;SUMAPRODUCTO(SI(_Datos<=_PorEncimade;_Datos;_PorEncimade);(DIASEM($G$8:$AK$8;2)<=5)*1;NO(ESNUMERO(COINCIDIR($G$8:$AK$8;nFestivos;0)))*1);
B9: No;SUMAPRODUCTO(_Datos;(DIASEM($G$8:$AK$8;2)<=5)*1;NO(ESNUMERO(COINCIDIR($G$8:$AK$8;nFestivos;0)))*1))
B10: {=_HorasExtras="NO"} -> #NAME? | C10: para que las horas extras en formato condiciona tenga otro color
B12: {=AND(_HorasExtras="SI",OR(_Datos>_PorEncimade))} -> #NAME? | C12: para el color al costado de los empleados

Sheet ASISTENCIA KRAMER1
A5: Año | B5: 2025
A6: Mes | B6: ABRIL
C8: =IF($B$6="","",1) -> 1 | D8: =IF(IF(C8="","",SUM(C8+1))>VLOOKUP('ASISTENCIA KRAMER1'!$B$6,TMESES[],2,FALSE),"",SUM('ASISTENCIA KRAMER1'!C8+1)) -> 2 | E8: =IF(IF(D8="","",SUM(D8+1))>VLOOKUP('ASISTENCIA KRAMER1'!$B$6,TMESES[],2,FALSE),"",SUM('ASISTENCIA KRAMER1'!D8+1)) -> 3 | F8: =IF(IF(E8="","",SUM(E8+1))>VLOOKUP('ASISTENCIA KRAMER1'!$B$6,TMESES[],2,FALSE),"",SUM('ASISTENCIA KRAMER1'!E8+1)) -> 4 | G8: =IF(IF(F8="","",SUM(F8+1))>VLOOKUP('ASISTENCIA KRAMER1'!$B$6,TMESES[],2,FALSE),"",SUM('ASISTENCIA KRAMER1'!F8+1)) -> 5 | H8: =IF(IF(G8="","",SUM(G8+1))>VLOOKUP('ASISTENCIA KRAMER1'!$B$6,TMESES[],2,FALSE),"",SUM('ASISTENCIA KRAMER1'!G8+1)) -> 6 | I8: =IF(IF(H8="","",SUM(H8+1))>VLOOKUP('ASISTENCIA KRAMER1'!$B$6,TMESES[],2,FALSE),"",SUM('ASISTENCIA KRAMER1'!H8+1)) -> 7 | J8: =IF(IF(I8="","",SUM(I8+1))>VLOOKUP('ASISTENCIA KRAMER1'!$B$6,TMESES[],2,FALSE),"",SUM('ASISTENCIA KRAMER1'!I8+1)) -> 8 | K8: =IF(IF(J8="","",SUM(J8+1))>VLOOKUP('ASISTENCIA KRAMER1'!$B$6,TMESES[],2,FALSE),"",SUM('ASISTENCIA KRAMER1'!J8+1)) -> 9 | ... AG8: =IF(IF(AF8="","",SUM(AF8+1))>VLOOKUP('ASISTENCIA KRAMER1'!$B$6,TMESES[],2,FALSE),"",SUM('ASISTENCIA KRAMER1'!AF8+1))
C9: =TEXT(DATE($B$5,MONTH($B$6&1),C8),"ddd") -> mar | D9: =TEXT(DATE($B$5,MONTH($B$6&1),D8),"ddd") -> mié | E9: =TEXT(DATE($B$5,MONTH($B$6&1),E8),"ddd") -> jue | F9: =TEXT(DATE($B$5,MONTH($B$6&1),F8),"ddd") -> vie | G9: =TEXT(DATE($B$5,MONTH($B$6&1),G8),"ddd") -> sáb | H9: =TEXT(DATE($B$5,MONTH($B$6&1),H8),"ddd") -> dom | I9: =TEXT(DATE($B$5,MONTH($B$6&1),I8),"ddd") -> lun | J9: =TEXT(DATE($B$5,MONTH($B$6&1),J8),"ddd") -> mar | ... AF9: =TEXT(DATE($B$5,MONTH($B$6&1),AF8),"ddd") -> mié
A10: N° | B10: APELLIDOS Y NOMBRES

Sheet MESES
A1: MES | B1: HASTA
A2: ENERO | B2: 31
A3: FEBRERO | B3: 28
A4: MARZO | B4: 31
A5: ABRIL | B5: 30
A6: MAYO | B6: 31
A7: JUNIO | B7: 30
A8: JULIO | B8: 31
A9: AGOSTO | B9: 31
A10: SETIEMBRE | B10: 30
A11: OCTUBRE | B11: 31
A12: NOVIEMBRE | B12: 30
A13: DICIEMBRE | B13: 31

Sheet ASISTENCIA 2 (2)
C1: Registro y Control de Asistencia
C4: Escoja Mes: | E4: Setiembre | H4: ← Item Lista Desplegable | N4: Empresa: | Q4: FSA Constructora | V4: El Periodo Comprende | AD4: Mes: | AG4: Año: | AM4: Horas Extras: | AO4: NO
N5: Obra: | Q5: Ticapampa | V5: ="Desde: "&TEXT(DATE(E6,MONTH(E4&1),1),"mmm-dd-yy")&" Hasta "&TEXT(EOMONTH(DATE(E6,MONTH(E4&1),1),0),"mmm-dd-yy") -> Desde: Set-01-25 Hasta Set-30-25 | AD5: =E4 -> Setiembre | AG5: =E6 -> 2025
C6: Escoja Año: | E6: 2025 | H6: ← Introduzca manualmente | N6: Encargado: | Q6: Ernesto Acuachi | AM6: Por Encima de: | AO6: 8
G8: =DATE(E6,MONTH(E4&1),1) -> 45901 | H8: =G8+1 -> 45902 | I8: =H8+1 -> 45903 | J8: =I8+1 -> 45904 | K8: =J8+1 -> 45905 | L8: =K8+1 -> 45906 | M8: =L8+1 -> 45907 | N8: =M8+1 -> 45908 | O8: =N8+1 -> 45909 | ... AK8: =AJ8+1 -> 45931
AT9: Festivos
AT10: 45658
AT11: 45866
AT12: 45867
C13: Apellido y Nombres | E13: Cargo | G13: =PROPER(LEFT(TEXT(G8,"dddd"),3)) -> Lun | H13: =PROPER(LEFT(TEXT(H8,"dddd"),3)) -> Mar | I13: =PROPER(LEFT(TEXT(I8,"dddd"),3)) -> Mié | J13: =PROPER(LEFT(TEXT(J8,"dddd"),3)) -> Jue | K13: =PROPER(LEFT(TEXT(K8,"dddd"),3)) -> Vie | L13: =PROPER(LEFT(TEXT(L8,"dddd"),3)) -> Sáb | M13: =PROPER(LEFT(TEXT(M8,"dddd"),3)) -> Dom | N13: =PROPER(LEFT(TEXT(N8,"dddd"),3)) -> Lun | ... AK13: =PROPER(LEFT(TEXT(AK8,"dddd"),3)) -> Mié | AM13: ASISTIO(SI) | AO13: FALTA(NO) | AQ13: MEDIO DIA(MED) | AS13: TOTAL | AT13: 45962
AT14: 46016
C15: SALAZAR BAZAN, ROCÍO DALILA | E15: =IFERROR(VLOOKUP(C15,'DATOS GRALES 1'!$B$2:$E$52,4,0),"") -> RESIDENTE | N15: SI | O15: SI | P15: SI | Q15: SI | R15: SI | S15: SI | U15: SI | V15: SI | W15: SI | X15: SI | Y15: SI | Z15: SI | AB15: NO | AC15: SI | AD15: si | AE15: SI | AF15: SI | AG15: SI | AI15: SI | AJ15: SI | AM15: =IF(COUNTIF(G15:AK15,"SI")=0,"",COUNTIF(G15:AK15,"SI")) -> 19 | AO15: =IF(COUNTIF(G15:AK15,"NO")=0,"",COUNTIF(G15:AK15,"NO")) -> 1 | AQ15: =IF(COUNTIF(G15:AK15,"MED")=0,"",COUNTIF(G15:AK15,"MED")) | AS15: =IF(SUM(AM15:AQ15)=0,"",SUM(AM15:AQ15)) -> 20 | AT15: 46022
C16: ALEJO CHARCA, DENNYS MIRIAM | E16: =IFERROR(VLOOKUP(C16,'DATOS GRALES 1'!$B$2:$E$52,4,0),"") -> ING. CALIDAD | O16: SI | P16: SI | Q16: SI | R16: SI | S16: SI | U16: SI | V16: SI | W16: SI | X16: SI | Y16: SI | Z16: SI | AB16: SI | AC16: SI | AD16: si | AE16: SI | AF16: SI | AG16: SI | AI16: SI | AJ16: SI | AM16: =IF(COUNTIF(G16:AK16,"SI")=0,"",COUNTIF(G16:AK16,"SI")) -> 19 | AO16: =IF(COUNTIF(G16:AK16,"NO")=0,"",COUNTIF(G16:AK16,"NO")) | AQ16: =IF(COUNTIF(G16:AK16,"MED")=0,"",COUNTIF(G16:AK16,"MED")) | AS16: =IF(SUM(AM16:AQ16)=0,"",SUM(AM16:AQ16)) -> 19
C17: SILVA BORDA, ARLETTE NINOSKA | E17: =IFERROR(VLOOKUP(C17,'DATOS GRALES 1'!$B$2:$E$52,4,0),"") -> ASIS. ING. | P17: SI | Q17: SI | R17: SI | S17: SI | U17: SI | V17: SI | W17: SI | X17: SI | Y17: SI | Z17: SI | AB17: SI | AC17: SI | AD17: si | AE17: SI | AF17: SI | AG17: SI | AI17: SI | AJ17: SI | AM17: =IF(COUNTIF(G17:AK17,"SI")=0,"",COUNTIF(G17:AK17,"SI")) -> 18 | AO17: =IF(COUNTIF(G17:AK17,"NO")=0,"",COUNTIF(G17:AK17,"NO")) | AQ17: =IF(COUNTIF(G17:AK17,"MED")=0,"",COUNTIF(G17:AK17,"MED")) | AS17: =IF(SUM(AM17:AQ17)=0,"",SUM(AM17:AQ17)) -> 18
C18: ACUACHI LANCHIPA, ERNESTO ALONSO | E18: =IFERROR(VLOOKUP(C18,'DATOS GRALES 1'!$B$2:$E$52,4,0),"") -> LOGISTICO | N18: SI | O18: SI | P18: SI | Q18: SI | R18: SI | S18: SI | U18: SI | V18: SI | W18: SI | X18: SI | Y18: SI | Z18: SI | AB18: SI | AC18: SI | AD18: SI | AE18: MED | AF18: SI | AG18: SI | AI18: SI | AJ18: SI | AM18: =IF(COUNTIF(G18:AK18,"SI")=0,"",COUNTIF(G18:AK18,"SI")) -> 19 | AO18: =IF(COUNTIF(G18:AK18,"NO")=0,"",COUNTIF(G18:AK18,"NO")) | AQ18: =IF(COUNTIF(G18:AK18,"MED")=0,"",COUNTIF(G18:AK18,"MED")) -> 1 | AS18: =IF(SUM(AM18:AQ18)=0,"",SUM(AM18:AQ18)) -> 20
C19: ADUVIRE ARGUATA, MARIO ARTURO | E19: =IFERROR(VLOOKUP(C19,'DATOS GRALES 1'!$B$2:$E$52,4,0),"") -> MAESTRO OBRA | N19: SI | O19: SI | P19: SI | Q19: SI | R19: SI | S19: SI | U19: SI | V19: SI | W19: SI | X19: SI | Y19: SI | Z19: SI | AB19: SI | AC19: SI | AD19: si | AE19: SI | AF19: SI | AG19: SI | AI19: SI | AJ19: SI | AM19: =IF(COUNTIF(G19:AK19,"SI")=0,"",COUNTIF(G19:AK19,"SI")) -> 20 | AO19: =IF(COUNTIF(G19:AK19,"NO")=0,"",COUNTIF(G19:AK19,"NO")) | AQ19: =IF(COUNTIF(G19:AK19,"MED")=0,"",COUNTIF(G19:AK19,"MED")) | AS19: =IF(SUM(AM19:AQ19)=0,"",SUM(AM19:AQ19)) -> 20
C20: LOZA YAPUCHURA, KENNY GUILLERMO | E20: =IFERROR(VLOOKUP(C20,'DATOS GRALES 1'!$B$2:$E$52,4,0),"") -> TOPOGRAFO | AB20: SI | AC20: SI | AD20: si | AE20: SI | AF20: SI | AG20: SI | AI20: SI | AJ20: SI | AM20: =IF(COUNTIF(G20:AK20,"SI")=0,"",COUNTIF(G20:AK20,"SI")) -> 8 | AO20: =IF(COUNTIF(G20:AK20,"NO")=0,"",COUNTIF(G20:AK20,"NO")) | AQ20: =IF(COUNTIF(G20:AK20,"MED")=0,"",COUNTIF(G20:AK20,"MED")) | AS20: =IF(SUM(AM20:AQ20)=0,"",SUM(AM20:AQ20)) -> 8
C21: MOGROVEJO FALCON, OSMAR ADOLFO | E21: =IFERROR(VLOOKUP(C21,'DATOS GRALES 1'!$B$2:$E$52,4,0),"") -> ESP. SEGURIDAD | AI21: SI | AJ21: SI | AM21: =IF(COUNTIF(G21:AK21,"SI")=0,"",COUNTIF(G21:AK21,"SI")) -> 2 | AO21: =IF(COUNTIF(G21:AK21,"NO")=0,"",COUNTIF(G21:AK21,"NO")) | AQ21: =IF(COUNTIF(G21:AK21,"MED")=0,"",COUNTIF(G21:AK21,"MED")) | AS21: =IF(SUM(AM21:AQ21)=0,"",SUM(AM21:AQ21)) -> 2
E22: =IFERROR(VLOOKUP(C22,'DATOS GRALES 1'!$B$2:$E$52,4,0),"") | AM22: =IF(COUNTIF(G22:AK22,"SI")=0,"",COUNTIF(G22:AK22,"SI")) | AO22: =IF(COUNTIF(G22:AK22,"NO")=0,"",COUNTIF(G22:AK22,"NO")) | AQ22: =IF(COUNTIF(G22:AK22,"MED")=0,"",COUNTIF(G22:AK22,"MED")) | AS22: =IF(SUM(AM22:AQ22)=0,"",SUM(AM22:AQ22))
C23: OBREROS | G23: OBREROS
C24: NAVARRO LOZANO, ANGEL JAROL | E24: =IFERROR(VLOOKUP(C24,'DATOS GRALES 1'!B2:E52,4,0),"") -> PEON | O24: SI | P24: SI | Q24: SI | R24: SI | S24: SI | U24: SI | V24: SI | W24: SI | X24: SI | Y24: SI | Z24: SI | AB24: SI | AC24: SI | AD24: SI | AE24: SI | AF24: SI | AG24: SI | AI24: SI | AJ24: SI | AM24: =IF(COUNTIF(G24:AK24,"SI")=0,"",COUNTIF(G24:AK24,"SI")) -> 19 | AO24: =IF(COUNTIF(G24:AK24,"NO")=0,"",COUNTIF(G24:AK24,"NO")) | AQ24: =IF(COUNTIF(G24:AK24,"MED")=0,"",COUNTIF(G24:AK24,"MED")) | AS24: =IF(SUM(AM24:AQ24)=0,"",SUM(AM24:AQ24)) -> 19
C25: JEREMIAS PALOMINO, NORBERTO LEONCIO | E25: =IFERROR(VLOOKUP(C25,'DATOS GRALES 1'!B3:E44,4,0),"") -> PEON | O25: SI | P25: SI | Q25: SI | R25: SI | S25: SI | U25: SI | V25: SI | W25: SI | X25: SI | Y25: NO | Z25: NO | AB25: SI | AC25: SI | AD25: SI | AE25: SI | AF25: SI | AG25: SI | AI25: SI | AJ25: SI | AM25: =IF(COUNTIF(G25:AK25,"SI")=0,"",COUNTIF(G25:AK25,"SI")) -> 17 | AO25: =IF(COUNTIF(G25:AK25,"NO")=0,"",COUNTIF(G25:AK25,"NO")) -> 2 | AQ25: =IF(COUNTIF(G25:AK25,"MED")=0,"",COUNTIF(G25:AK25,"MED")) | AS25: =IF(SUM(AM25:AQ25)=0,"",SUM(AM25:AQ25)) -> 19 | AU25: 29/09/2025 llego 8:00 am
C26: LOZANO MALDONADO, HERNAN | E26: =IFERROR(VLOOKUP(C26,'DATOS GRALES 1'!B4:E45,4,0),"") -> PEON | O26: SI | P26: SI | Q26: SI | R26: SI | S26: SI | U26: SI | V26: SI | W26: SI | X26: SI | Y26: SI | Z26: SI | AB26: SI | AC26: SI | AD26: SI | AE26: SI | AF26: SI | AG26: SI | AI26: SI | AJ26: SI | AM26: =IF(COUNTIF(G26:AK26,"SI")=0,"",COUNTIF(G26:AK26,"SI")) -> 19 | AO26: =IF(COUNTIF(G26:AK26,"NO")=0,"",COUNTIF(G26:AK26,"NO")) | AQ26: =IF(COUNTIF(G26:AK26,"MED")=0,"",COUNTIF(G26:AK26,"MED")) | AS26: =IF(SUM(AM26:AQ26)=0,"",SUM(AM26:AQ26)) -> 19
C27: PIÑA CHUJANDAMA, KEVIN | E27: =IFERROR(VLOOKUP(C27,'DATOS GRALES 1'!B5:E53,4,0),"") -> PEON | O27: SI | P27: SI. | Q27: SI | R27: SI | S27: SI | U27: SI | V27: SI | W27: SI | X27: SI | Y27: SI | Z27: SI | AB27: SI | AC27: SI | AD27: SI | AE27: SI | AF27: SI | AG27: SI | AI27: SI | AJ27: SI | AM27: =IF(COUNTIF(G27:AK27,"SI")=0,"",COUNTIF(G27:AK27,"SI")) -> 18 | AO27: =IF(COUNTIF(G27:AK27,"NO")=0,"",COUNTIF(G27:AK27,"NO")) | AQ27: =IF(COUNTIF(G27:AK27,"MED")=0,"",COUNTIF(G27:AK27,"MED")) | AS27: =IF(SUM(AM27:AQ27)=0,"",SUM(AM27:AQ27)) -> 18
C28: MAYTAHUARI ACOSTA, SAMMER AXEL | E28: =IFERROR(VLOOKUP(C28,'DATOS GRALES 1'!B6:E54,4,0),"") -> OPERARIO | O28: SI | P28: SI | Q28: SI | R28: SI | S28: SI | U28: SI | V28: SI | W28: SI | X28: SI | Y28: SI | Z28: SI | AB28: SI | AC28: SI | AD28: SI | AE28: SI | AF28: SI | AG28: SI | AI28: NO | AJ28: SI | AM28: =IF(COUNTIF(G28:AK28,"SI")=0,"",COUNTIF(G28:AK28,"SI")) -> 18 | AO28: =IF(COUNTIF(G28:AK28,"NO")=0,"",COUNTIF(G28:AK28,"NO")) -> 1 | AQ28: =IF(COUNTIF(G28:AK28,"MED")=0,"",COUNTIF(G28:AK28,"MED")) | AS28: =IF(SUM(AM28:AQ28)=0,"",SUM(AM28:AQ28)) -> 19
C29: CORDOVA ANGULO, JUAN | E29: =IFERROR(VLOOKUP(C29,'DATOS GRALES 1'!B7:E55,4,0),"") -> PEON | O29: SI | P29: SI | Q29: SI | R29: SI | S29: SI | U29: NO | V29: SI | W29: SI | X29: SI | Y29: SI | Z29: SI | AB29: SI | AC29: SI | AD29: SI | AE29: SI | AF29: SI | AG29: SI | AI29: SI | AJ29: SI | AM29: =IF(COUNTIF(G29:AK29,"SI")=0,"",COUNTIF(G29:AK29,"SI")) -> 18 | AO29: =IF(COUNTIF(G29:AK29,"NO")=0,"",COUNTIF(G29:AK29,"NO")) -> 1 | AQ29: =IF(COUNTIF(G29:AK29,"MED")=0,"",COUNTIF(G29:AK29,"MED")) | AS29: =IF(SUM(AM29:AQ29)=0,"",SUM(AM29:AQ29)) -> 19
C30: ROJAS SANDOVAL, JAVIER ELOY | E30: =IFERROR(VLOOKUP(C30,'DATOS GRALES 1'!B8:E56,4,0),"") -> OPERARIO/VOLQUETERO | O30: SI | P30: SI | Q30: SI | R30: SI | S30: SI | U30: SI | V30: SI | W30: SI | X30: SI | Y30: SI | Z30: SI | AB30: SI | AC30: SI | AD30: SI | AE30: SI | AF30: SI | AG30: SI | AI30: SI | AJ30: SI | AM30: =IF(COUNTIF(G30:AK30,"SI")=0,"",COUNTIF(G30:AK30,"SI")) -> 19 | AO30: =IF(COUNTIF(G30:AK30,"NO")=0,"",COUNTIF(G30:AK30,"NO")) | AQ30: =IF(COUNTIF(G30:AK30,"MED")=0,"",COUNTIF(G30:AK30,"MED")) | AS30: =IF(SUM(AM30:AQ30)=0,"",SUM(AM30:AQ30)) -> 19 | AU30: 29/09/2025 llego 9:00 am
C31: CHINO PILCO SIMON | E31: =IFERROR(VLOOKUP(C31,'DATOS GRALES 1'!B9:E57,4,0),"") -> PEON/CHOFER | O31: SI | AM31: =IF(COUNTIF(G31:AK31,"SI")=0,"",COUNTIF(G31:AK31,"SI")) -> 1 | AO31: =IF(COUNTIF(G31:AK31,"NO")=0,"",COUNTIF(G31:AK31,"NO")) | AQ31: =IF(COUNTIF(G31:AK31,"MED")=0,"",COUNTIF(G31:AK31,"MED")) | AS31: =IF(SUM(AM31:AQ31)=0,"",SUM(AM31:AQ31)) -> 1
C32: CHACON ORTIZ, JOSE ANTONIO | E32: =IFERROR(VLOOKUP(C32,'DATOS GRALES 1'!B10:E58,4,0),"") -> OPERARIO | U32: SI | V32: SI | W32: SI | X32: SI | Y32: SI | Z32: SI | AB32: SI | AC32: SI | AD32: SI | AE32: SI | AF32: SI | AG32: SI | AI32: SI | AJ32: SI | AM32: =IF(COUNTIF(G32:AK32,"SI")=0,"",COUNTIF(G32:AK32,"SI")) -> 14 | AO32: =IF(COUNTIF(G32:AK32,"NO")=0,"",COUNTIF(G32:AK32,"NO")) | AQ32: =IF(COUNTIF(G32:AK32,"MED")=0,"",COUNTIF(G32:AK32,"MED")) | AS32: =IF(SUM(AM32:AQ32)=0,"",SUM(AM32:AQ32)) -> 14
C33: ORDOÑEZ CONDORI, GILBERTO | E33: =IFERROR(VLOOKUP(C33,'DATOS GRALES 1'!B11:E59,4,0),"") -> PEON | U33: SI | V33: SI | W33: SI | X33: SI | Y33: SI | Z33: SI | AB33: SI | AC33: SI | AD33: SI | AE33: SI | AF33: SI | AG33: SI | AI33: SI | AJ33: SI | AM33: =IF(COUNTIF(G33:AK33,"SI")=0,"",COUNTIF(G33:AK33,"SI")) -> 14 | AO33: =IF(COUNTIF(G33:AK33,"NO")=0,"",COUNTIF(G33:AK33,"NO")) | AQ33: =IF(COUNTIF(G33:AK33,"MED")=0,"",COUNTIF(G33:AK33,"MED")) | AS33: =IF(SUM(AM33:AQ33)=0,"",SUM(AM33:AQ33)) -> 14
C34: GUTARATE SABINO, ADRIEL ANTONY | E34: =IFERROR(VLOOKUP(C34,'DATOS GRALES 1'!B12:E60,4,0),"") -> OPERARIO | AB34: SI | AC34: SI | AD34: SI | AE34: SI | AF34: SI | AG34: SI | AI34: NO | AJ34: SI | AM34: =IF(COUNTIF(G34:AK34,"SI")=0,"",COUNTIF(G34:AK34,"SI")) -> 7 | AO34: =IF(COUNTIF(G34:AK34,"NO")=0,"",COUNTIF(G34:AK34,"NO")) -> 1 | AQ34: =IF(COUNTIF(G34:AK34,"MED")=0,"",COUNTIF(G34:AK34,"MED")) | AS34: =IF(SUM(AM34:AQ34)=0,"",SUM(AM34:AQ34)) -> 8
C35: QUISPE LIMACHE, ROGELIO | E35: =IFERROR(VLOOKUP(C35,'DATOS GRALES 1'!B13:E61,4,0),"") -> OPERARIO | AB35: SI | AC35: SI | AD35: SI | AE35: SI | AF35: SI | AG35: SI | AI35: SI | AJ35: SI | AM35: =IF(COUNTIF(G35:AK35,"SI")=0,"",COUNTIF(G35:AK35,"SI")) -> 8 | AO35: =IF(COUNTIF(G35:AK35,"NO")=0,"",COUNTIF(G35:AK35,"NO")) | AQ35: =IF(COUNTIF(G35:AK35,"MED")=0,"",COUNTIF(G35:AK35,"MED")) | AS35: =IF(SUM(AM35:AQ35)=0,"",SUM(AM35:AQ35)) -> 8
C36: APASTEGUI GRANDEZ, LUIS ALFREDO | E36: =IFERROR(VLOOKUP(C36,'DATOS GRALES 1'!B14:E62,4,0),"") -> PEON | AB36: SI | AC36: SI | AD36: SI | AE36: SI | AF36: SI | AG36: SI | AI36: SI | AJ36: SI | AM36: =IF(COUNTIF(G36:AK36,"SI")=0,"",COUNTIF(G36:AK36,"SI")) -> 8 | AO36: =IF(COUNTIF(G36:AK36,"NO")=0,"",COUNTIF(G36:AK36,"NO")) | AQ36: =IF(COUNTIF(G36:AK36,"MED")=0,"",COUNTIF(G36:AK36,"MED")) | AS36: =IF(SUM(AM36:AQ36)=0,"",SUM(AM36:AQ36)) -> 8
C37: VILLEGAS, ROGER | E37: =IFERROR(VLOOKUP(C37,'DATOS GRALES 1'!B15:E63,4,0),"") -> OPERARIO MAQU. | Z37: SI | AB37: SI | AC37: SI | AD37: SI | AE37: SI | AF37: SI | AG37: SI | AI37: SI | AJ37: SI | AM37: =IF(COUNTIF(G37:AK37,"SI")=0,"",COUNTIF(G37:AK37,"SI")) -> 9 | AO37: =IF(COUNTIF(G37:AK37,"NO")=0,"",COUNTIF(G37:AK37,"NO")) | AQ37: =IF(COUNTIF(G37:AK37,"MED")=0,"",COUNTIF(G37:AK37,"MED")) | AS37: =IF(SUM(AM37:AQ37)=0,"",SUM(AM37:AQ37)) -> 9 | AU37: 22/09/2025 llego tarde | AV37: 29/09/2025 llego 9:00 am
C38: TUANAMA PILCO, CHRIS | E38: =IFERROR(VLOOKUP(C38,'DATOS GRALES 1'!B16:E64,4,0),"") -> PEON | AB38: NO | AC38: SI | AD38: SI | AE38: SI | AF38: SI | AG38: SI | AI38: SI | AJ38: SI | AM38: =IF(COUNTIF(G38:AK38,"SI")=0,"",COUNTIF(G38:AK38,"SI")) -> 7 | AO38: =IF(COUNTIF(G38:AK38,"NO")=0,"",COUNTIF(G38:AK38,"NO")) -> 1 | AQ38: =IF(COUNTIF(G38:AK38,"MED")=0,"",COUNTIF(G38:AK38,"MED")) | AS38: =IF(SUM(AM38:AQ38)=0,"",SUM(AM38:AQ38)) -> 8 | AU38: 22 09 2025 llego media dia
C39: CACERES CALACHUA, YEYSON JORGE | E39: =IFERROR(VLOOKUP(C39,'DATOS GRALES 1'!B17:E65,4,0),"") -> OPERARIO | AB39: si | AC39: SI | AD39: SI | AE39: SI | AF39: SI | AG39: SI | AI39: SI | AJ39: SI | AM39: =IF(COUNTIF(G39:AK39,"SI")=0,"",COUNTIF(G39:AK39,"SI")) -> 8 | AO39: =IF(COUNTIF(G39:AK39,"NO")=0,"",COUNTIF(G39:AK39,"NO")) | AQ39: =IF(COUNTIF(G39:AK39,"MED")=0,"",COUNTIF(G39:AK39,"MED")) | AS39: =IF(SUM(AM39:AQ39)=0,"",SUM(AM39:AQ39)) -> 8 | AU39: 29/09/25 LLEGO 7:12
C40: MAQUERA QUISPE, LEONIDAS EDWIN | E40: =IFERROR(VLOOKUP(C40,'DATOS GRALES 1'!B18:E66,4,0),"") -> OPERARIO | AI40: SI | AJ40: SI | AM40: =IF(COUNTIF(G40:AK40,"SI")=0,"",COUNTIF(G40:AK40,"SI")) -> 2 | AO40: =IF(COUNTIF(G40:AK40,"NO")=0,"",COUNTIF(G40:AK40,"NO")) | AQ40: =IF(COUNTIF(G40:AK40,"MED")=0,"",COUNTIF(G40:AK40,"MED")) | AS40: =IF(SUM(AM40:AQ40)=0,"",SUM(AM40:AQ40)) -> 2
E41: =IFERROR(VLOOKUP(C41,'DATOS GRALES 1'!B19:E67,4,0),"") | AM41: =IF(COUNTIF(G41:AK41,"SI")=0,"",COUNTIF(G41:AK41,"SI")) | AO41: =IF(COUNTIF(G41:AK41,"NO")=0,"",COUNTIF(G41:AK41,"NO")) | AQ41: =IF(COUNTIF(G41:AK41,"MED")=0,"",COUNTIF(G41:AK41,"MED")) | AS41: =IF(SUM(AM41:AQ41)=0,"",SUM(AM41:AQ41))
E42: =IFERROR(VLOOKUP(C42,'DATOS GRALES 1'!B20:E68,4,0),"") | AM42: =IF(COUNTIF(G42:AK42,"SI")=0,"",COUNTIF(G42:AK42,"SI")) | AO42: =IF(COUNTIF(G42:AK42,"NO")=0,"",COUNTIF(G42:AK42,"NO")) | AQ42: =IF(COUNTIF(G42:AK42,"MED")=0,"",COUNTIF(G42:AK42,"MED")) | AS42: =IF(SUM(AM42:AQ42)=0,"",SUM(AM42:AQ42))
E43: =IFERROR(VLOOKUP(C43,'DATOS GRALES 1'!B21:E69,4,0),"") | AM43: =IF(COUNTIF(G43:AK43,"SI")=0,"",COUNTIF(G43:AK43,"SI")) | AO43: =IF(COUNTIF(G43:AK43,"NO")=0,"",COUNTIF(G43:AK43,"NO")) | AQ43: =IF(COUNTIF(G43:AK43,"MED")=0,"",COUNTIF(G43:AK43,"MED")) | AS43: =IF(SUM(AM43:AQ43)=0,"",SUM(AM43:AQ43))
...

Sheet ASISTENCIA OCTUBRE
C1: Registro y Control de Asistencia
C4: Escoja Mes: | E4: Octubre | H4: ← Item Lista Desplegable | N4: Empresa: | Q4: FSA Constructora | V4: El Periodo Comprende | AD4: Mes: | AG4: Año: | AM4: Horas Extras: | AO4: NO
N5: Obra: | Q5: Ticapampa | V5: ="Desde: "&TEXT(DATE(E6,MONTH(E4&1),1),"mmm-dd-yy")&" Hasta "&TEXT(EOMONTH(DATE(E6,MONTH(E4&1),1),0),"mmm-dd-yy") -> Desde: Oct-01-25 Hasta Oct-31-25 | AD5: =E4 -> Octubre | AG5: =E6 -> 2025
C6: Escoja Año: | E6: 2025 | H6: ← Introduzca manualmente | N6: Encargado: | Q6: Ernesto Acuachi | AM6: Por Encima de: | AO6: 8
G8: =DATE(E6,MONTH(E4&1),1) -> 45931 | H8: =G8+1 -> 45932 | I8: =H8+1 -> 45933 | J8: =I8+1 -> 45934 | K8: =J8+1 -> 45935 | L8: =K8+1 -> 45936 | M8: =L8+1 -> 45937 | N8: =M8+1 -> 45938 | O8: =N8+1 -> 45939 | ... AK8: =AJ8+1 -> 45961
AT9: Festivos
AT10: 45658
AT11: 45866
AT12: 45867
C13: Apellido y Nombres | E13: Cargo | G13: =PROPER(LEFT(TEXT(G8,"dddd"),3)) -> Mié | H13: =PROPER(LEFT(TEXT(H8,"dddd"),3)) -> Jue | I13: =PROPER(LEFT(TEXT(I8,"dddd"),3)) -> Vie | J13: =PROPER(LEFT(TEXT(J8,"dddd"),3)) -> Sáb | K13: =PROPER(LEFT(TEXT(K8,"dddd"),3)) -> Dom | L13: =PROPER(LEFT(TEXT(L8,"dddd"),3)) -> Lun | M13: =PROPER(LEFT(TEXT(M8,"dddd"),3)) -> Mar | N13: =PROPER(LEFT(TEXT(N8,"dddd"),3)) -> Mié | ... AK13: =PROPER(LEFT(TEXT(AK8,"dddd"),3)) -> Vie | AM13: ASISTIO(SI) | AO13: FALTA(NO) | AQ13: MEDIO DIA(MED) | AS13: TOTAL | AT13: 45962
AT14: 46016
C15: SALAZAR BAZAN, ROCÍO DALILA | E15: =IFERROR(VLOOKUP(C15,'DATOS GRALES 1'!$B$2:$E$52,4,0),"") -> RESIDENTE | G15: SI | H15: SI | I15: SI | L15: Si | M15: SI | N15: SI | O15: SI | P15: SI | S15: SI | T15: SI | U15: SI | V15: SI | W15: NO | X15: NO | Z15: NO | AA15: SI | AB15: SI | AC15: SI | AD15: SI | AG15: SI | AH15: SI | AI15: SI | AJ15: SI | AK15: SI | AM15: =IF(COUNTIF(G15:AK15,"SI")=0,"",COUNTIF(G15:AK15,"SI")) -> 21 | AO15: =IF(COUNTIF(G15:AK15,"NO")=0,"",COUNTIF(G15:AK15,"NO")) -> 3 | AQ15: =IF(COUNTIF(G15:AK15,"MED")=0,"",COUNTIF(G15:AK15,"MED")) | AS15: =IF(SUM(AM15:AQ15)=0,"",SUM(AM15:AQ15)) -> 24 | AT15: 46022
C16: ALEJO CHARCA, DENNYS MIRIAM | E16: =IFERROR(VLOOKUP(C16,'DATOS GRALES 1'!$B$2:$E$52,4,0),"") -> ING. CALIDAD | G16: SI | H16: SI | I16: SI | L16: Si | M16: SI | N16: SI | O16: SI | P16: NO | S16: SI | T16: SI | U16: SI | V16: SI | W16: SI | X16: NO | Z16: SI | AA16: SI | AB16: SI | AC16: SI | AD16: SI | AG16: SI | AH16: SI | AI16: SI | AJ16: SI | AK16: SI | AM16: =IF(COUNTIF(G16:AK16,"SI")=0,"",COUNTIF(G16:AK16,"SI")) -> 22 | AO16: =IF(COUNTIF(G16:AK16,"NO")=0,"",COUNTIF(G16:AK16,"NO")) -> 2 | AQ16: =IF(COUNTIF(G16:AK16,"MED")=0,"",COUNTIF(G16:AK16,"MED")) | AS16: =IF(SUM(AM16:AQ16)=0,"",SUM(AM16:AQ16)) -> 24
C17: SILVA BORDA, ARLETTE NINOSKA | E17: =IFERROR(VLOOKUP(C17,'DATOS GRALES 1'!$B$2:$E$52,4,0),"") -> ASIS. ING. | G17: SI | H17: SI | I17: SI | L17: SI | M17: SI | N17: SI | O17: SI | P17: SI | S17: SI | T17: SI | U17: SI | V17: SI | W17: SI | X17: SI | Z17: SI | AA17: SI | AB17: SI | AC17: SI | AD17: SI | AG17: SI | AH17: SI | AI17: SI | AJ17: SI | AK17: SI | AM17: =IF(COUNTIF(G17:AK17,"SI")=0,"",COUNTIF(G17:AK17,"SI")) -> 24 | AO17: =IF(COUNTIF(G17:AK17,"NO")=0,"",COUNTIF(G17:AK17,"NO")) | AQ17: =IF(COUNTIF(G17:AK17,"MED")=0,"",COUNTIF(G17:AK17,"MED")) | AS17: =IF(SUM(AM17:AQ17)=0,"",SUM(AM17:AQ17)) -> 24
